Workbook

Sheet DATA
A1: IMO_NOMBRE | B1: IMO_PILA | C1: IMO_EQUIPO | D1: IMO_TEL | E1: PX_NOMBRE | F1: PX_EQUIPO | G1: ESTADO | H1: FECHA_RESP | I1: OBSERVACIONES
A2: Nunez Tapia Mayra Alexandra | B2: Mayra | C2: EQUIPO 104 | D2: 0984946974 | E2: Jorge Jeyner Uceda Agapito | F2: EQUIPO 21 | G2: PENDIENTE
A3: Micolta Gracia Briana Kimberli | B3: Briana | C3: EQUIPO 105 | D3: 0983476990 | E3: Mary Laura Donayre Navarrete | F3: EQUIPO 22 | G3: PENDIENTE
A4: Esposito Farfan Daniela De La Trinidad | B4: Daniela | C4: EQUIPO 108 | D4: 0981188999 | E4: Yoneglis May-Ling Conde Garcia | F4: EQUIPO 23 | G4: PENDIENTE
A5: Cubillo Vera Liliana Lilibeth | B5: Liliana | C5: EQUIPO 109 | D5: 0996521133 | E5: Twiggy Carmen Aguirre Sanchez | F5: EQUIPO 23 | G5: PENDIENTE
A6: Rodriguez Gallegos Adrian Andre | B6: Adrian | C6: EQUIPO 109 | D6: 0981523455 | E6: Camila Celena Machaca Pacompia | F6: EQUIPO 24 | G6: PENDIENTE
A7: Lopez Chahua Sandra Marlene | B7: Sandra | C7: EQUIPO 14 | D7: 970870801 | E7: Moises Mancisidor Dominguez | F7: EQUIPO 17 | G7: PENDIENTE
A8: Lopez Chahua Sandra Marlene | B8: Sandra | C8: EQUIPO 14 | D8: 970870801 | E8: Lida Mancisidor Lopez | F8: EQUIPO 17 | G8: PENDIENTE
A9: Borjas Ormeno Roxana Florentina | B9: Roxana | C9: EQUIPO 14 | D9: 961718880 | E9: Belén María Gutiérrez Vásquez | F9: EQUIPO 17 | G9: PENDIENTE
A10: Borjas Ormeno Roxana Florentina | B10: Roxana | C10: EQUIPO 14 | D10: 961718880 | E10: Yessenia Brillith Robles Zamora | F10: EQUIPO 24 | G10: PENDIENTE
A11: Anaya Espinoza Nora | B11: Nora | C11: EQUIPO 14 | D11: 966103120 | E11: Anyeli Suney Prado Gómez | F11: EQUIPO 17 | G11: PENDIENTE
A12: Jaramillo Pinedo Reyna | B12: Reyna | C12: EQUIPO 14 | D12: 954821488 | E12: Magaly Yenny Jaramillo Pinedo | F12: EQUIPO 17 | G12: PENDIENTE
A13: Tello Sarmiento Flor De Cantuta | B13: Flor | C13: EQUIPO 14 | D13: 995864425 | E13: Silvia Cecilia Tello Rojas | F13: EQUIPO 17 | G13: PENDIENTE
... A747: Rivera Toyama Manuel Yakima | B747: Manuel | C747: EQUIPO 25 | D747: 996612880 | E747: Pedro Eder Espinoza Alva | F747: EQUIPO 19 | G747: PENDIENTE

Sheet MENSAJES_IMO
A1: 📨 CAMPAÑA REZAGADOS C1 E27 | Comunicaciones Crear Poder Sin Límites Perú | 1-3 mayo 2026
A2: ="IMOs: "&COUNTA(MENSAJES_IMO!B5:B9999)&" | Px campaña: "&COUNTA(DATA!E2:E9999)&" | Confirmados: "&COUNTIF(DATA!G:G,"CONFIRMADO")&" | Pendientes: "&COUNTIF(DATA!G:G,"PENDIENTE") -> IMOs: 282 | Px campaña: 746 | Confirmados: 0 | Pendientes: 746
A3: N° | B3: NOMBRE IMO | C3: EQUIPO IMO | D3: TEL. IMO | E3: PX TOTAL | F3: CONFIRMADOS | G3: ESTADO | H3: MENSAJE WA
A5: 1 | B5: Nunez Tapia Mayra Alexandra | C5: EQUIPO 104 | D5: 0984946974 | E5: =COUNTIF(DATA!A:A,B5) -> 1 | F5: =COUNTIFS(DATA!A:A,B5,DATA!G:G,"CONFIRMADO") -> 0 | G5: =IF(E5=0,"SIN DATA",IF(F5=E5,"✅ COMPLETO",IF(F5>0,"🔄 PARCIAL",IF(COUNTIFS(DATA!A:A,B5,DATA!G:G,"PENDIENTE")=E5,"⏳ PENDIENTE","⚠ MIXTO")))) -> ⏳ PENDIENTE | H5: ="Hola "&IFERROR(LEFT(TRIM(MID(B5,FIND(" ",B5,FIND(" ",B5)+1)+1,100)),IFERROR(FIND(" ",TRIM(MID(B5,FIND(" ",B5,FIND(" ",B5)+1)+1,100)))-1,100)),TRIM(MID(B5,FIND(" ",B5&" ")+1,100)))&", buen día."&CHAR(10)&CHAR(10)&"Te escribo porque una persona de tu equipo aún no se ha sentado en el Capítulo 1:"&CHAR(10)&CHAR(10)&"1. Jorge Jeyner Uceda Agapito"&CHAR(10)&CHAR(10)&"El próximo C1 es el 1, 2 y 3 de mayo. Necesito saber el estatus real de esta persona: si tiene la intención de sentarse, qué está pasando con su proceso y si cuenta con tu acompañamiento para llegar."&CHAR(10)&CHAR(10)&"Por favor respóndenos a este mismo número con el estatus de esta persona antes del viernes."&CHAR(10)&CHAR(10)&"Comunicaciones Crear Poder Sin Límites Perú" -> Hola Mayra, buen día. Te escribo porque una persona de tu equipo aún no se ha sentado en el Capítulo 1: 1. Jorge Jeyner Uceda Agapito El próximo C1 es el 1, 2 y 3 de mayo. Necesito saber el estatus real de esta persona: si tiene la intención de sentarse, qué está pasando con su proceso y si cuenta con tu acompañamiento para llegar. Por favor respóndenos a este mismo número con el estatus de esta persona antes del viernes. Comunicaciones Crear Poder Sin Límites Perú
A6: 2 | B6: Micolta Gracia Briana Kimberli | C6: EQUIPO 105 | D6: 0983476990 | E6: =COUNTIF(DATA!A:A,B6) -> 1 | F6: =COUNTIFS(DATA!A:A,B6,DATA!G:G,"CONFIRMADO") -> 0 | G6: =IF(E6=0,"SIN DATA",IF(F6=E6,"✅ COMPLETO",IF(F6>0,"🔄 PARCIAL",IF(COUNTIFS(DATA!A:A,B6,DATA!G:G,"PENDIENTE")=E6,"⏳ PENDIENTE","⚠ MIXTO")))) -> ⏳ PENDIENTE | H6: ="Hola "&IFERROR(LEFT(TRIM(MID(B6,FIND(" ",B6,FIND(" ",B6)+1)+1,100)),IFERROR(FIND(" ",TRIM(MID(B6,FIND(" ",B6,FIND(" ",B6)+1)+1,100)))-1,100)),TRIM(MID(B6,FIND(" ",B6&" ")+1,100)))&", buen día."&CHAR(10)&CHAR(10)&"Te escribo porque una persona de tu equipo aún no se ha sentado en el Capítulo 1:"&CHAR(10)&CHAR(10)&"1. Mary Laura Donayre Navarrete"&CHAR(10)&CHAR(10)&"El próximo C1 es el 1, 2 y 3 de mayo. Necesito saber el estatus real de esta persona: si tiene la intención de sentarse, qué está pasando con su proceso y si cuenta con tu acompañamiento para llegar."&CHAR(10)&CHAR(10)&"Por favor respóndenos a este mismo número con el estatus de esta persona antes del viernes."&CHAR(10)&CHAR(10)&"Comunicaciones Crear Poder Sin Límites Perú" -> Hola Briana, buen día. Te escribo porque una persona de tu equipo aún no se ha sentado en el Capítulo 1: 1. Mary Laura Donayre Navarrete El próximo C1 es el 1, 2 y 3 de mayo. Necesito saber el estatus real de esta persona: si tiene la intención de sentarse, qué está pasando con su proceso y si cuenta con tu acompañamiento para llegar. Por favor respóndenos a este mismo número con el estatus de esta persona antes del viernes. Comunicaciones Crear Poder Sin Límites Perú
A7: 3 | B7: Esposito Farfan Daniela De La Trinidad | C7: EQUIPO 108 | D7: 0981188999 | E7: =COUNTIF(DATA!A:A,B7) -> 1 | F7: =COUNTIFS(DATA!A:A,B7,DATA!G:G,"CONFIRMADO") -> 0 | G7: =IF(E7=0,"SIN DATA",IF(F7=E7,"✅ COMPLETO",IF(F7>0,"🔄 PARCIAL",IF(COUNTIFS(DATA!A:A,B7,DATA!G:G,"PENDIENTE")=E7,"⏳ PENDIENTE","⚠ MIXTO")))) -> ⏳ PENDIENTE | H7: ="Hola "&IFERROR(LEFT(TRIM(MID(B7,FIND(" ",B7,FIND(" ",B7)+1)+1,100)),IFERROR(FIND(" ",TRIM(MID(B7,FIND(" ",B7,FIND(" ",B7)+1)+1,100)))-1,100)),TRIM(MID(B7,FIND(" ",B7&" ")+1,100)))&", buen día."&CHAR(10)&CHAR(10)&"Te escribo porque una persona de tu equipo aún no se ha sentado en el Capítulo 1:"&CHAR(10)&CHAR(10)&"1. Yoneglis May-Ling Conde Garcia"&CHAR(10)&CHAR(10)&"El próximo C1 es el 1, 2 y 3 de mayo. Necesito saber el estatus real de esta persona: si tiene la intención de sentarse, qué está pasando con su proceso y si cuenta con tu acompañamiento para llegar."&CHAR(10)&CHAR(10)&"Por favor respóndenos a este mismo número con el estatus de esta persona antes del viernes."&CHAR(10)&CHAR(10)&"Comunicaciones Crear Poder Sin Límites Perú" -> Hola Daniela, buen día. Te escribo porque una persona de tu equipo aún no se ha sentado en el Capítulo 1: 1. Yoneglis May-Ling Conde Garcia El próximo C1 es el 1, 2 y 3 de mayo. Necesito saber el estatus real de esta persona: si tiene la intención de sentarse, qué está pasando con su proceso y si cuenta con tu acompañamiento para llegar. Por favor respóndenos a este mismo número con el estatus de esta persona antes del viernes. Comunicaciones Crear Poder Sin Límites Perú
A8: 4 | B8: Cubillo Vera Liliana Lilibeth | C8: EQUIPO 109 | D8: 0996521133 | E8: =COUNTIF(DATA!A:A,B8) -> 1 | F8: =COUNTIFS(DATA!A:A,B8,DATA!G:G,"CONFIRMADO") -> 0 | G8: =IF(E8=0,"SIN DATA",IF(F8=E8,"✅ COMPLETO",IF(F8>0,"🔄 PARCIAL",IF(COUNTIFS(DATA!A:A,B8,DATA!G:G,"PENDIENTE")=E8,"⏳ PENDIENTE","⚠ MIXTO")))) -> ⏳ PENDIENTE | H8: ="Hola "&IFERROR(LEFT(TRIM(MID(B8,FIND(" ",B8,FIND(" ",B8)+1)+1,100)),IFERROR(FIND(" ",TRIM(MID(B8,FIND(" ",B8,FIND(" ",B8)+1)+1,100)))-1,100)),TRIM(MID(B8,FIND(" ",B8&" ")+1,100)))&", buen día."&CHAR(10)&CHAR(10)&"Te escribo porque una persona de tu equipo aún no se ha sentado en el Capítulo 1:"&CHAR(10)&CHAR(10)&"1. Twiggy Carmen Aguirre Sanchez"&CHAR(10)&CHAR(10)&"El próximo C1 es el 1, 2 y 3 de mayo. Necesito saber el estatus real de esta persona: si tiene la intención de sentarse, qué está pasando con su proceso y si cuenta con tu acompañamiento para llegar."&CHAR(10)&CHAR(10)&"Por favor respóndenos a este mismo número con el estatus de esta persona antes del viernes."&CHAR(10)&CHAR(10)&"Comunicaciones Crear Poder Sin Límites Perú" -> Hola Liliana, buen día. Te escribo porque una persona de tu equipo aún no se ha sentado en el Capítulo 1: 1. Twiggy Carmen Aguirre Sanchez El próximo C1 es el 1, 2 y 3 de mayo. Necesito saber el estatus real de esta persona: si tiene la intención de sentarse, qué está pasando con su proceso y si cuenta con tu acompañamiento para llegar. Por favor respóndenos a este mismo número con el estatus de esta persona antes del viernes. Comunicaciones Crear Poder Sin Límites Perú
A9: 5 | B9: Rodriguez Gallegos Adrian Andre | C9: EQUIPO 109 | D9: 0981523455 | E9: =COUNTIF(DATA!A:A,B9) -> 1 | F9: =COUNTIFS(DATA!A:A,B9,DATA!G:G,"CONFIRMADO") -> 0 | G9: =IF(E9=0,"SIN DATA",IF(F9=E9,"✅ COMPLETO",IF(F9>0,"🔄 PARCIAL",IF(COUNTIFS(DATA!A:A,B9,DATA!G:G,"PENDIENTE")=E9,"⏳ PENDIENTE","⚠ MIXTO")))) -> ⏳ PENDIENTE | H9: ="Hola "&IFERROR(LEFT(TRIM(MID(B9,FIND(" ",B9,FIND(" ",B9)+1)+1,100)),IFERROR(FIND(" ",TRIM(MID(B9,FIND(" ",B9,FIND(" ",B9)+1)+1,100)))-1,100)),TRIM(MID(B9,FIND(" ",B9&" ")+1,100)))&", buen día."&CHAR(10)&CHAR(10)&"Te escribo porque una persona de tu equipo aún no se ha sentado en el Capítulo 1:"&CHAR(10)&CHAR(10)&"1. Camila Celena Machaca Pacompia"&CHAR(10)&CHAR(10)&"El próximo C1 es el 1, 2 y 3 de mayo. Necesito saber el estatus real de esta persona: si tiene la intención de sentarse, qué está pasando con su proceso y si cuenta con tu acompañamiento para llegar."&CHAR(10)&CHAR(10)&"Por favor respóndenos a este mismo número con el estatus de esta persona antes del viernes."&CHAR(10)&CHAR(10)&"Comunicaciones Crear Poder Sin Límites Perú" -> Hola Adrian, buen día. Te escribo porque una persona de tu equipo aún no se ha sentado en el Capítulo 1: 1. Camila Celena Machaca Pacompia El próximo C1 es el 1, 2 y 3 de mayo. Necesito saber el estatus real de esta persona: si tiene la intención de sentarse, qué está pasando con su proceso y si cuenta con tu acompañamiento para llegar. Por favor respóndenos a este mismo número con el estatus de esta persona antes del viernes. Comunicaciones Crear Poder Sin Límites Perú
A10: 6 | B10: Lopez Chahua Sandra Marlene | C10: EQUIPO 14 | D10: 970870801 | E10: =COUNTIF(DATA!A:A,B10) -> 2 | F10: =COUNTIFS(DATA!A:A,B10,DATA!G:G,"CONFIRMADO") -> 0 | G10: =IF(E10=0,"SIN DATA",IF(F10=E10,"✅ COMPLETO",IF(F10>0,"🔄 PARCIAL",IF(COUNTIFS(DATA!A:A,B10,DATA!G:G,"PENDIENTE")=E10,"⏳ PENDIENTE","⚠ MIXTO")))) -> ⏳ PENDIENTE | H10: ="Hola "&IFERROR(LEFT(TRIM(MID(B10,FIND(" ",B10,FIND(" ",B10)+1)+1,100)),IFERROR(FIND(" ",TRIM(MID(B10,FIND(" ",B10,FIND(" ",B10)+1)+1,100)))-1,100)),TRIM(MID(B10,FIND(" ",B10&" ")+1,100)))&", buen día."&CHAR(10)&CHAR(10)&"Te escribo porque "&E10&" personas de tu equipo aún no se han sentado en el Capítulo 1:"&CHAR(10)&CHAR(10)&"1. Moises Mancisidor Dominguez 2. Lida Mancisidor Lopez"&CHAR(10)&CHAR(10)&"El próximo C1 es el 1, 2 y 3 de mayo. Necesito saber el estatus real de cada uno: si tienen la intención de sentarse, qué está pasando con su proceso y si cuentan con tu acompañamiento para llegar."&CHAR(10)&CHAR(10)&"Por favor respóndenos a este mismo número con el estatus de cada uno antes del viernes."&CHAR(10)&CHAR(10)&"Comunicaciones Crear Poder Sin Límites Perú" -> Hola Sandra, buen día. Te escribo porque 2 personas de tu equipo aún no se han sentado en el Capítulo 1: 1. Moises Mancisidor Dominguez 2. Lida Mancisidor Lopez El próximo C1 es el 1, 2 y 3 de mayo. Necesito saber el estatus real de cada uno: si tienen la intención de sentarse, qué está pasando con su proceso y si cuentan con tu acompañamiento para llegar. Por favor respóndenos a este mismo número con el estatus de cada uno antes del viernes. Comunicaciones Crear Poder Sin Límites Perú
A11: 7 | B11: Borjas Ormeno Roxana Florentina | C11: EQUIPO 14 | D11: 961718880 | E11: =COUNTIF(DATA!A:A,B11) -> 2 | F11: =COUNTIFS(DATA!A:A,B11,DATA!G:G,"CONFIRMADO") -> 0 | G11: =IF(E11=0,"SIN DATA",IF(F11=E11,"✅ COMPLETO",IF(F11>0,"🔄 PARCIAL",IF(COUNTIFS(DATA!A:A,B11,DATA!G:G,"PENDIENTE")=E11,"⏳ PENDIENTE","⚠ MIXTO")))) -> ⏳ PENDIENTE | H11: ="Hola "&IFERROR(LEFT(TRIM(MID(B11,FIND(" ",B11,FIND(" ",B11)+1)+1,100)),IFERROR(FIND(" ",TRIM(MID(B11,FIND(" ",B11,FIND(" ",B11)+1)+1,100)))-1,100)),TRIM(MID(B11,FIND(" ",B11&" ")+1,100)))&", buen día."&CHAR(10)&CHAR(10)&"Te escribo porque "&E11&" personas de tu equipo aún no se han sentado en el Capítulo 1:"&CHAR(10)&CHAR(10)&"1. Belén María Gutiérrez Vásquez 2. Yessenia Brillith Robles Zamora"&CHAR(10)&CHAR(10)&"El próximo C1 es el 1, 2 y 3 de mayo. Necesito saber el estatus real de cada uno: si tienen la intención de sentarse, qué está pasando con su proceso y si cuentan con tu acompañamiento para llegar."&CHAR(10)&CHAR(10)&"Por favor respóndenos a este mismo número con el estatus de cada uno antes del viernes."&CHAR(10)&CHAR(10)&"Comunicaciones Crear Poder Sin Límites Perú" -> Hola Roxana, buen día. Te escribo porque 2 personas de tu equipo aún no se han sentado en el Capítulo 1: 1. Belén María Gutiérrez Vásquez 2. Yessenia Brillith Robles Zamora El próximo C1 es el 1, 2 y 3 de mayo. Necesito saber el estatus real de cada uno: si tienen la intención de sentarse, qué está pasando con su proceso y si cuentan con tu acompañamiento para llegar. Por favor respóndenos a este mismo número con el estatus de cada uno antes del viernes. Comunicaciones Crear Poder Sin Límites Perú
A12: 8 | B12: Anaya Espinoza Nora | C12: EQUIPO 14 | D12: 966103120 | E12: =COUNTIF(DATA!A:A,B12) -> 1 | F12: =COUNTIFS(DATA!A:A,B12,DATA!G:G,"CONFIRMADO") -> 0 | G12: =IF(E12=0,"SIN DATA",IF(F12=E12,"✅ COMPLETO",IF(F12>0,"🔄 PARCIAL",IF(COUNTIFS(DATA!A:A,B12,DATA!G:G,"PENDIENTE")=E12,"⏳ PENDIENTE","⚠ MIXTO")))) -> ⏳ PENDIENTE | H12: ="Hola "&IFERROR(LEFT(TRIM(MID(B12,FIND(" ",B12,FIND(" ",B12)+1)+1,100)),IFERROR(FIND(" ",TRIM(MID(B12,FIND(" ",B12,FIND(" ",B12)+1)+1,100)))-1,100)),TRIM(MID(B12,FIND(" ",B12&" ")+1,100)))&", buen día."&CHAR(10)&CHAR(10)&"Te escribo porque una persona de tu equipo aún no se ha sentado en el Capítulo 1:"&CHAR(10)&CHAR(10)&"1. Anyeli Suney Prado Gómez"&CHAR(10)&CHAR(10)&"El próximo C1 es el 1, 2 y 3 de mayo. Necesito saber el estatus real de esta persona: si tiene la intención de sentarse, qué está pasando con su proceso y si cuenta con tu acompañamiento para llegar."&CHAR(10)&CHAR(10)&"Por favor respóndenos a este mismo número con el estatus de esta persona antes del viernes."&CHAR(10)&CHAR(10)&"Comunicaciones Crear Poder Sin Límites Perú" -> Hola Nora, buen día. Te escribo porque una persona de tu equipo aún no se ha sentado en el Capítulo 1: 1. Anyeli Suney Prado Gómez El próximo C1 es el 1, 2 y 3 de mayo. Necesito saber el estatus real de esta persona: si tiene la intención de sentarse, qué está pasando con su proceso y si cuenta con tu acompañamiento para llegar. Por favor respóndenos a este mismo número con el estatus de esta persona antes del viernes. Comunicaciones Crear Poder Sin Límites Perú
A13: 9 | B13: Jaramillo Pinedo Reyna | C13: EQUIPO 14 | D13: 954821488 | E13: =COUNTIF(DATA!A:A,B13) -> 1 | F13: =COUNTIFS(DATA!A:A,B13,DATA!G:G,"CONFIRMADO") -> 0 | G13: =IF(E13=0,"SIN DATA",IF(F13=E13,"✅ COMPLETO",IF(F13>0,"🔄 PARCIAL",IF(COUNTIFS(DATA!A:A,B13,DATA!G:G,"PENDIENTE")=E13,"⏳ PENDIENTE","⚠ MIXTO")))) -> ⏳ PENDIENTE | H13: ="Hola "&IFERROR(LEFT(TRIM(MID(B13,FIND(" ",B13,FIND(" ",B13)+1)+1,100)),IFERROR(FIND(" ",TRIM(MID(B13,FIND(" ",B13,FIND(" ",B13)+1)+1,100)))-1,100)),TRIM(MID(B13,FIND(" ",B13&" ")+1,100)))&", buen día."&CHAR(10)&CHAR(10)&"Te escribo porque una persona de tu equipo aún no se ha sentado en el Capítulo 1:"&CHAR(10)&CHAR(10)&"1. Magaly Yenny Jaramillo Pinedo"&CHAR(10)&CHAR(10)&"El próximo C1 es el 1, 2 y 3 de mayo. Necesito saber el estatus real de esta persona: si tiene la intención de sentarse, qué está pasando con su proceso y si cuenta con tu acompañamiento para llegar."&CHAR(10)&CHAR(10)&"Por favor respóndenos a este mismo número con el estatus de esta persona antes del viernes."&CHAR(10)&CHAR(10)&"Comunicaciones Crear Poder Sin Límites Perú" -> Hola Reyna, buen día. Te escribo porque una persona de tu equipo aún no se ha sentado en el Capítulo 1: 1. Magaly Yenny Jaramillo Pinedo El próximo C1 es el 1, 2 y 3 de mayo. Necesito saber el estatus real de esta persona: si tiene la intención de sentarse, qué está pasando con su proceso y si cuenta con tu acompañamiento para llegar. Por favor respóndenos a este mismo número con el estatus de esta persona antes del viernes. Comunicaciones Crear Poder Sin Límites Perú
A14: 10 | B14: Tello Sarmiento Flor De Cantuta | C14: EQUIPO 14 | D14: 995864425 | E14: =COUNTIF(DATA!A:A,B14) -> 3 | F14: =COUNTIFS(DATA!A:A,B14,DATA!G:G,"CONFIRMADO") -> 0 | G14: =IF(E14=0,"SIN DATA",IF(F14=E14,"✅ COMPLETO",IF(F14>0,"🔄 PARCIAL",IF(COUNTIFS(DATA!A:A,B14,DATA!G:G,"PENDIENTE")=E14,"⏳ PENDIENTE","⚠ MIXTO")))) -> ⏳ PENDIENTE | H14: ="Hola "&IFERROR(LEFT(TRIM(MID(B14,FIND(" ",B14,FIND(" ",B14)+1)+1,100)),IFERROR(FIND(" ",TRIM(MID(B14,FIND(" ",B14,FIND(" ",B14)+1)+1,100)))-1,100)),TRIM(MID(B14,FIND(" ",B14&" ")+1,100)))&", buen día."&CHAR(10)&CHAR(10)&"Te escribo porque "&E14&" personas de tu equipo aún no se han sentado en el Capítulo 1:"&CHAR(10)&CHAR(10)&"1. Silvia Cecilia Tello Rojas 2. Julio Cesar Tello Rojas 3. Hermelinda Delgado Heredia"&CHAR(10)&CHAR(10)&"El próximo C1 es el 1, 2 y 3 de mayo. Necesito saber el estatus real de cada uno: si tienen la intención de sentarse, qué está pasando con su proceso y si cuentan con tu acompañamiento para llegar."&CHAR(10)&CHAR(10)&"Por favor respóndenos a este mismo número con el estatus de cada uno antes del viernes."&CHAR(10)&CHAR(10)&"Comunicaciones Crear Poder Sin Límites Perú" -> Hola Flor, buen día. Te escribo porque 3 personas de tu equipo aún no se han sentado en el Capítulo 1: 1. Silvia Cecilia Tello Rojas 2. Julio Cesar Tello Rojas 3. Hermelinda Delgado Heredia El próximo C1 es el 1, 2 y 3 de mayo. Necesito saber el estatus real de cada uno: si tienen la intención de sentarse, qué está pasando con su proceso y si cuentan con tu acompañamiento para llegar. Por favor respóndenos a este mismo número con el estatus de cada uno antes del viernes. Comunicaciones Crear Poder Sin Límites Perú
A15: 11 | B15: Conga Huarcaya Jessica | C15: EQUIPO 14 | D15: 974632398 | E15: =COUNTIF(DATA!A:A,B15) -> 1 | F15: =COUNTIFS(DATA!A:A,B15,DATA!G:G,"CONFIRMADO") -> 0 | G15: =IF(E15=0,"SIN DATA",IF(F15=E15,"✅ COMPLETO",IF(F15>0,"🔄 PARCIAL",IF(COUNTIFS(DATA!A:A,B15,DATA!G:G,"PENDIENTE")=E15,"⏳ PENDIENTE","⚠ MIXTO")))) -> ⏳ PENDIENTE | H15: ="Hola "&IFERROR(LEFT(TRIM(MID(B15,FIND(" ",B15,FIND(" ",B15)+1)+1,100)),IFERROR(FIND(" ",TRIM(MID(B15,FIND(" ",B15,FIND(" ",B15)+1)+1,100)))-1,100)),TRIM(MID(B15,FIND(" ",B15&" ")+1,100)))&", buen día."&CHAR(10)&CHAR(10)&"Te escribo porque una persona de tu equipo aún no se ha sentado en el Capítulo 1:"&CHAR(10)&CHAR(10)&"1. Carolina Floresmila Montoro Acosta"&CHAR(10)&CHAR(10)&"El próximo C1 es el 1, 2 y 3 de mayo. Necesito saber el estatus real de esta persona: si tiene la intención de sentarse, qué está pasando con su proceso y si cuenta con tu acompañamiento para llegar."&CHAR(10)&CHAR(10)&"Por favor respóndenos a este mismo número con el estatus de esta persona antes del viernes."&CHAR(10)&CHAR(10)&"Comunicaciones Crear Poder Sin Límites Perú" -> Hola Jessica, buen día. Te escribo porque una persona de tu equipo aún no se ha sentado en el Capítulo 1: 1. Carolina Floresmila Montoro Acosta El próximo C1 es el 1, 2 y 3 de mayo. Necesito saber el estatus real de esta persona: si tiene la intención de sentarse, qué está pasando con su proceso y si cuenta con tu acompañamiento para llegar. Por favor respóndenos a este mismo número con el estatus de esta persona antes del viernes. Comunicaciones Crear Poder Sin Límites Perú
A16: 12 | B16: Minchola Valdivia Gian Carlo Duval | C16: EQUIPO 14 | D16: 970784090 | E16: =COUNTIF(DATA!A:A,B16) -> 1 | F16: =COUNTIFS(DATA!A:A,B16,DATA!G:G,"CONFIRMADO") -> 0 | G16: =IF(E16=0,"SIN DATA",IF(F16=E16,"✅ COMPLETO",IF(F16>0,"🔄 PARCIAL",IF(COUNTIFS(DATA!A:A,B16,DATA!G:G,"PENDIENTE")=E16,"⏳ PENDIENTE","⚠ MIXTO")))) -> ⏳ PENDIENTE | H16: ="Hola "&IFERROR(LEFT(TRIM(MID(B16,FIND(" ",B16,FIND(" ",B16)+1)+1,100)),IFERROR(FIND(" ",TRIM(MID(B16,FIND(" ",B16,FIND(" ",B16)+1)+1,100)))-1,100)),TRIM(MID(B16,FIND(" ",B16&" ")+1,100)))&", buen día."&CHAR(10)&CHAR(10)&"Te escribo porque una persona de tu equipo aún no se ha sentado en el Capítulo 1:"&CHAR(10)&CHAR(10)&"1. Jose Luis Montoya Garcia"&CHAR(10)&CHAR(10)&"El próximo C1 es el 1, 2 y 3 de mayo. Necesito saber el estatus real de esta persona: si tiene la intención de sentarse, qué está pasando con su proceso y si cuenta con tu acompañamiento para llegar."&CHAR(10)&CHAR(10)&"Por favor respóndenos a este mismo número con el estatus de esta persona antes del viernes."&CHAR(10)&CHAR(10)&"Comunicaciones Crear Poder Sin Límites Perú" -> Hola Gian, buen día. Te escribo porque una persona de tu equipo aún no se ha sentado en el Capítulo 1: 1. Jose Luis Montoya Garcia El próximo C1 es el 1, 2 y 3 de mayo. Necesito saber el estatus real de esta persona: si tiene la intención de sentarse, qué está pasando con su proceso y si cuenta con tu acompañamiento para llegar. Por favor respóndenos a este mismo número con el estatus de esta persona antes del viernes. Comunicaciones Crear Poder Sin Límites Perú
A17: 13 | B17: Chavez Romero Marilin Leslie | C17: EQUIPO 14 | D17: 964212086 | E17: =COUNTIF(DATA!A:A,B17) -> 1 | F17: =COUNTIFS(DATA!A:A,B17,DATA!G:G,"CONFIRMADO") -> 0 | G17: =IF(E17=0,"SIN DATA",IF(F17=E17,"✅ COMPLETO",IF(F17>0,"🔄 PARCIAL",IF(COUNTIFS(DATA!A:A,B17,DATA!G:G,"PENDIENTE")=E17,"⏳ PENDIENTE","⚠ MIXTO")))) -> ⏳ PENDIENTE | H17: ="Hola "&IFERROR(LEFT(TRIM(MID(B17,FIND(" ",B17,FIND(" ",B17)+1)+1,100)),IFERROR(FIND(" ",TRIM(MID(B17,FIND(" ",B17,FIND(" ",B17)+1)+1,100)))-1,100)),TRIM(MID(B17,FIND(" ",B17&" ")+1,100)))&", buen día."&CHAR(10)&CHAR(10)&"Te escribo porque una persona de tu equipo aún no se ha sentado en el Capítulo 1:"&CHAR(10)&CHAR(10)&"1. Ruth Milagros Morán Morán"&CHAR(10)&CHAR(10)&"El próximo C1 es el 1, 2 y 3 de mayo. Necesito saber el estatus real de esta persona: si tiene la intención de sentarse, qué está pasando con su proceso y si cuenta con tu acompañamiento para llegar."&CHAR(10)&CHAR(10)&"Por favor respóndenos a este mismo número con el estatus de esta persona antes del viernes."&CHAR(10)&CHAR(10)&"Comunicaciones Crear Poder Sin Límites Perú" -> Hola Marilin, buen día. Te escribo porque una persona de tu equipo aún no se ha sentado en el Capítulo 1: 1. Ruth Milagros Morán Morán El próximo C1 es el 1, 2 y 3 de mayo. Necesito saber el estatus real de esta persona: si tiene la intención de sentarse, qué está pasando con su proceso y si cuenta con tu acompañamiento para llegar. Por favor respóndenos a este mismo número con el estatus de esta persona antes del viernes. Comunicaciones Crear Poder Sin Límites Perú
A18: 14 | B18: Perez Chinchay Carmen Gricelda | C18: EQUIPO 14 | D18: 936558835 | E18: =COUNTIF(DATA!A:A,B18) -> 1 | F18: =COUNTIFS(DATA!A:A,B18,DATA!G:G,"CONFIRMADO") -> 0 | G18: =IF(E18=0,"SIN DATA",IF(F18=E18,"✅ COMPLETO",IF(F18>0,"🔄 PARCIAL",IF(COUNTIFS(DATA!A:A,B18,DATA!G:G,"PENDIENTE")=E18,"⏳ PENDIENTE","⚠ MIXTO")))) -> ⏳ PENDIENTE | H18: ="Hola "&IFERROR(LEFT(TRIM(MID(B18,FIND(" ",B18,FIND(" ",B18)+1)+1,100)),IFERROR(FIND(" ",TRIM(MID(B18,FIND(" ",B18,FIND(" ",B18)+1)+1,100)))-1,100)),TRIM(MID(B18,FIND(" ",B18&" ")+1,100)))&", buen día."&CHAR(10)&CHAR(10)&"Te escribo porque una persona de tu equipo aún no se ha sentado en el Capítulo 1:"&CHAR(10)&CHAR(10)&"1. Mercedes Niquin Dominguez"&CHAR(10)&CHAR(10)&"El próximo C1 es el 1, 2 y 3 de mayo. Necesito saber el estatus real de esta persona: si tiene la intención de sentarse, qué está pasando con su proceso y si cuenta con tu acompañamiento para llegar."&CHAR(10)&CHAR(10)&"Por favor respóndenos a este mismo número con el estatus de esta persona antes del viernes."&CHAR(10)&CHAR(10)&"Comunicaciones Crear Poder Sin Límites Perú" -> Hola Carmen, buen día. Te escribo porque una persona de tu equipo aún no se ha sentado en el Capítulo 1: 1. Mercedes Niquin Dominguez El próximo C1 es el 1, 2 y 3 de mayo. Necesito saber el estatus real de esta persona: si tiene la intención de sentarse, qué está pasando con su proceso y si cuenta con tu acompañamiento para llegar. Por favor respóndenos a este mismo número con el estatus de esta persona antes del viernes. Comunicaciones Crear Poder Sin Límites Perú
A19: 15 | B19: Antaurco Perez Jesus Julio | C19: EQUIPO 14 | D19: 977473283 | E19: =COUNTIF(DATA!A:A,B19) -> 1 | F19: =COUNTIFS(DATA!A:A,B19,DATA!G:G,"CONFIRMADO") -> 0 | G19: =IF(E19=0,"SIN DATA",IF(F19=E19,"✅ COMPLETO",IF(F19>0,"🔄 PARCIAL",IF(COUNTIFS(DATA!A:A,B19,DATA!G:G,"PENDIENTE")=E19,"⏳ PENDIENTE","⚠ MIXTO")))) -> ⏳ PENDIENTE | H19: ="Hola "&IFERROR(LEFT(TRIM(MID(B19,FIND(" ",B19,FIND(" ",B19)+1)+1,100)),IFERROR(FIND(" ",TRIM(MID(B19,FIND(" ",B19,FIND(" ",B19)+1)+1,100)))-1,100)),TRIM(MID(B19,FIND(" ",B19&" ")+1,100)))&", buen día."&CHAR(10)&CHAR(10)&"Te escribo porque una persona de tu equipo aún no se ha sentado en el Capítulo 1:"&CHAR(10)&CHAR(10)&"1. Lessly Ossorio C."&CHAR(10)&CHAR(10)&"El próximo C1 es el 1, 2 y 3 de mayo. Necesito saber el estatus real de esta persona: si tiene la intención de sentarse, qué está pasando con su proceso y si cuenta con tu acompañamiento para llegar."&CHAR(10)&CHAR(10)&"Por favor respóndenos a este mismo número con el estatus de esta persona antes del viernes."&CHAR(10)&CHAR(10)&"Comunicaciones Crear Poder Sin Límites Perú" -> Hola Jesus, buen día. Te escribo porque una persona de tu equipo aún no se ha sentado en el Capítulo 1: 1. Lessly Ossorio C. El próximo C1 es el 1, 2 y 3 de mayo. Necesito saber el estatus real de esta persona: si tiene la intención de sentarse, qué está pasando con su proceso y si cuenta con tu acompañamiento para llegar. Por favor respóndenos a este mismo número con el estatus de esta persona antes del viernes. Comunicaciones Crear Poder Sin Límites Perú
A20: 16 | B20: Valencia Lazo Diego Marcelo | C20: EQUIPO 14 | D20: 940135875 | E20: =COUNTIF(DATA!A:A,B20) -> 2 | F20: =COUNTIFS(DATA!A:A,B20,DATA!G:G,"CONFIRMADO") -> 0 | G20: =IF(E20=0,"SIN DATA",IF(F20=E20,"✅ COMPLETO",IF(F20>0,"🔄 PARCIAL",IF(COUNTIFS(DATA!A:A,B20,DATA!G:G,"PENDIENTE")=E20,"⏳ PENDIENTE","⚠ MIXTO")))) -> ⏳ PENDIENTE | H20: ="Hola "&IFERROR(LEFT(TRIM(MID(B20,FIND(" ",B20,FIND(" ",B20)+1)+1,100)),IFERROR(FIND(" ",TRIM(MID(B20,FIND(" ",B20,FIND(" ",B20)+1)+1,100)))-1,100)),TRIM(MID(B20,FIND(" ",B20&" ")+1,100)))&", buen día."&CHAR(10)&CHAR(10)&"Te escribo porque "&E20&" personas de tu equipo aún no se han sentado en el Capítulo 1:"&CHAR(10)&CHAR(10)&"1. Kevin Pedro Perez Garcia 2. Jossymar Alberto Leon Alba"&CHAR(10)&CHAR(10)&"El próximo C1 es el 1, 2 y 3 de mayo. Necesito saber el estatus real de cada uno: si tienen la intención de sentarse, qué está pasando con su proceso y si cuentan con tu acompañamiento para llegar."&CHAR(10)&CHAR(10)&"Por favor respóndenos a este mismo número con el estatus de cada uno antes del viernes."&CHAR(10)&CHAR(10)&"Comunicaciones Crear Poder Sin Límites Perú" -> Hola Diego, buen día. Te escribo porque 2 personas de tu equipo aún no se han sentado en el Capítulo 1: 1. Kevin Pedro Perez Garcia 2. Jossymar Alberto Leon Alba El próximo C1 es el 1, 2 y 3 de mayo. Necesito saber el estatus real de cada uno: si tienen la intención de sentarse, qué está pasando con su proceso y si cuentan con tu acompañamiento para llegar. Por favor respóndenos a este mismo número con el estatus de cada uno antes del viernes. Comunicaciones Crear Poder Sin Límites Perú
A21: 17 | B21: Lopez Hanco Bryan Rodney | C21: EQUIPO 14 | D21: 907730431 | E21: =COUNTIF(DATA!A:A,B21) -> 3 | F21: =COUNTIFS(DATA!A:A,B21,DATA!G:G,"CONFIRMADO") -> 0 | G21: =IF(E21=0,"SIN DATA",IF(F21=E21,"✅ COMPLETO",IF(F21>0,"🔄 PARCIAL",IF(COUNTIFS(DATA!A:A,B21,DATA!G:G,"PENDIENTE")=E21,"⏳ PENDIENTE","⚠ MIXTO")))) -> ⏳ PENDIENTE | H21: ="Hola "&IFERROR(LEFT(TRIM(MID(B21,FIND(" ",B21,FIND(" ",B21)+1)+1,100)),IFERROR(FIND(" ",TRIM(MID(B21,FIND(" ",B21,FIND(" ",B21)+1)+1,100)))-1,100)),TRIM(MID(B21,FIND(" ",B21&" ")+1,100)))&", buen día."&CHAR(10)&CHAR(10)&"Te escribo porque "&E21&" personas de tu equipo aún no se han sentado en el Capítulo 1:"&CHAR(10)&CHAR(10)&"1. Gianella Brissete Gutierrez Narvaez 2. Zadid Días 3. Rosa Marysabell Romero Cárdenas"&CHAR(10)&CHAR(10)&"El próximo C1 es el 1, 2 y 3 de mayo. Necesito saber el estatus real de cada uno: si tienen la intención de sentarse, qué está pasando con su proceso y si cuentan con tu acompañamiento para llegar."&CHAR(10)&CHAR(10)&"Por favor respóndenos a este mismo número con el estatus de cada uno antes del viernes."&CHAR(10)&CHAR(10)&"Comunicaciones Crear Poder Sin Límites Perú" -> Hola Bryan, buen día. Te escribo porque 3 personas de tu equipo aún no se han sentado en el Capítulo 1: 1. Gianella Brissete Gutierrez Narvaez 2. Zadid Días 3. Rosa Marysabell Romero Cárdenas El próximo C1 es el 1, 2 y 3 de mayo. Necesito saber el estatus real de cada uno: si tienen la intención de sentarse, qué está pasando con su proceso y si cuentan con tu acompañamiento para llegar. Por favor respóndenos a este mismo número con el estatus de cada uno antes del viernes. Comunicaciones Crear Poder Sin Límites Perú
A22: 18 | B22: Landa Ochoa Nathaly | C22: EQUIPO 15 | D22: 918147583 | E22: =COUNTIF(DATA!A:A,B22) -> 1 | F22: =COUNTIFS(DATA!A:A,B22,DATA!G:G,"CONFIRMADO") -> 0 | G22: =IF(E22=0,"SIN DATA",IF(F22=E22,"✅ COMPLETO",IF(F22>0,"🔄 PARCIAL",IF(COUNTIFS(DATA!A:A,B22,DATA!G:G,"PENDIENTE")=E22,"⏳ PENDIENTE","⚠ MIXTO")))) -> ⏳ PENDIENTE | H22: ="Hola "&IFERROR(LEFT(TRIM(MID(B22,FIND(" ",B22,FIND(" ",B22)+1)+1,100)),IFERROR(FIND(" ",TRIM(MID(B22,FIND(" ",B22,FIND(" ",B22)+1)+1,100)))-1,100)),TRIM(MID(B22,FIND(" ",B22&" ")+1,100)))&", buen día."&CHAR(10)&CHAR(10)&"Te escribo porque una persona de tu equipo aún no se ha sentado en el Capítulo 1:"&CHAR(10)&CHAR(10)&"1. Thalia Giorgina Gamboa Valdivia"&CHAR(10)&CHAR(10)&"El próximo C1 es el 1, 2 y 3 de mayo. Necesito saber el estatus real de esta persona: si tiene la intención de sentarse, qué está pasando con su proceso y si cuenta con tu acompañamiento para llegar."&CHAR(10)&CHAR(10)&"Por favor respóndenos a este mismo número con el estatus de esta persona antes del viernes."&CHAR(10)&CHAR(10)&"Comunicaciones Crear Poder Sin Límites Perú" -> Hola Nathaly, buen día. Te escribo porque una persona de tu equipo aún no se ha sentado en el Capítulo 1: 1. Thalia Giorgina Gamboa Valdivia El próximo C1 es el 1, 2 y 3 de mayo. Necesito saber el estatus real de esta persona: si tiene la intención de sentarse, qué está pasando con su proceso y si cuenta con tu acompañamiento para llegar. Por favor respóndenos a este mismo número con el estatus de esta persona antes del viernes. Comunicaciones Crear Poder Sin Límites Perú
A23: 19 | B23: Tolentino Angulo Roberto Carlos | C23: EQUIPO 15 | D23: 944343392 | E23: =COUNTIF(DATA!A:A,B23) -> 1 | F23: =COUNTIFS(DATA!A:A,B23,DATA!G:G,"CONFIRMADO") -> 0 | G23: =IF(E23=0,"SIN DATA",IF(F23=E23,"✅ COMPLETO",IF(F23>0,"🔄 PARCIAL",IF(COUNTIFS(DATA!A:A,B23,DATA!G:G,"PENDIENTE")=E23,"⏳ PENDIENTE","⚠ MIXTO")))) -> ⏳ PENDIENTE | H23: ="Hola "&IFERROR(LEFT(TRIM(MID(B23,FIND(" ",B23,FIND(" ",B23)+1)+1,100)),IFERROR(FIND(" ",TRIM(MID(B23,FIND(" ",B23,FIND(" ",B23)+1)+1,100)))-1,100)),TRIM(MID(B23,FIND(" ",B23&" ")+1,100)))&", buen día."&CHAR(10)&CHAR(10)&"Te escribo porque una persona de tu equipo aún no se ha sentado en el Capítulo 1:"&CHAR(10)&CHAR(10)&"1. Richard Elvis Tolentino Angulo"&CHAR(10)&CHAR(10)&"El próximo C1 es el 1, 2 y 3 de mayo. Necesito saber el estatus real de esta persona: si tiene la intención de sentarse, qué está pasando con su proceso y si cuenta con tu acompañamiento para llegar."&CHAR(10)&CHAR(10)&"Por favor respóndenos a este mismo número con el estatus de esta persona antes del viernes."&CHAR(10)&CHAR(10)&"Comunicaciones Crear Poder Sin Límites Perú" -> Hola Roberto, buen día. Te escribo porque una persona de tu equipo aún no se ha sentado en el Capítulo 1: 1. Richard Elvis Tolentino Angulo El próximo C1 es el 1, 2 y 3 de mayo. Necesito saber el estatus real de esta persona: si tiene la intención de sentarse, qué está pasando con su proceso y si cuenta con tu acompañamiento para llegar. Por favor respóndenos a este mismo número con el estatus de esta persona antes del viernes. Comunicaciones Crear Poder Sin Límites Perú
A24: 20 | B24: Trujillo Mallqui Liz Carol | C24: EQUIPO 15 | D24: 980496819 | E24: =COUNTIF(DATA!A:A,B24) -> 1 | F24: =COUNTIFS(DATA!A:A,B24,DATA!G:G,"CONFIRMADO") -> 0 | G24: =IF(E24=0,"SIN DATA",IF(F24=E24,"✅ COMPLETO",IF(F24>0,"🔄 PARCIAL",IF(COUNTIFS(DATA!A:A,B24,DATA!G:G,"PENDIENTE")=E24,"⏳ PENDIENTE","⚠ MIXTO")))) -> ⏳ PENDIENTE | H24: ="Hola "&IFERROR(LEFT(TRIM(MID(B24,FIND(" ",B24,FIND(" ",B24)+1)+1,100)),IFERROR(FIND(" ",TRIM(MID(B24,FIND(" ",B24,FIND(" ",B24)+1)+1,100)))-1,100)),TRIM(MID(B24,FIND(" ",B24&" ")+1,100)))&", buen día."&CHAR(10)&CHAR(10)&"Te escribo porque una persona de tu equipo aún no se ha sentado en el Capítulo 1:"&CHAR(10)&CHAR(10)&"1. Vooictor Eugenio Rodolfo Guerrero Soto"&CHAR(10)&CHAR(10)&"El próximo C1 es el 1, 2 y 3 de mayo. Necesito saber el estatus real de esta persona: si tiene la intención de sentarse, qué está pasando con su proceso y si cuenta con tu acompañamiento para llegar."&CHAR(10)&CHAR(10)&"Por favor respóndenos a este mismo número con el estatus de esta persona antes del viernes."&CHAR(10)&CHAR(10)&"Comunicaciones Crear Poder Sin Límites Perú" -> Hola Liz, buen día. Te escribo porque una persona de tu equipo aún no se ha sentado en el Capítulo 1: 1. Vooictor Eugenio Rodolfo Guerrero Soto El próximo C1 es el 1, 2 y 3 de mayo. Necesito saber el estatus real de esta persona: si tiene la intención de sentarse, qué está pasando con su proceso y si cuenta con tu acompañamiento para llegar. Por favor respóndenos a este mismo número con el estatus de esta persona antes del viernes. Comunicaciones Crear Poder Sin Límites Perú
A25: 21 | B25: Trujillo Montoya Rodrigo Elias Enrique | C25: EQUIPO 15 | D25: 937410103 | E25: =COUNTIF(DATA!A:A,B25) -> 3 | F25: =COUNTIFS(DATA!A:A,B25,DATA!G:G,"CONFIRMADO") -> 0 | G25: =IF(E25=0,"SIN DATA",IF(F25=E25,"✅ COMPLETO",IF(F25>0,"🔄 PARCIAL",IF(COUNTIFS(DATA!A:A,B25,DATA!G:G,"PENDIENTE")=E25,"⏳ PENDIENTE","⚠ MIXTO")))) -> ⏳ PENDIENTE | H25: ="Hola "&IFERROR(LEFT(TRIM(MID(B25,FIND(" ",B25,FIND(" ",B25)+1)+1,100)),IFERROR(FIND(" ",TRIM(MID(B25,FIND(" ",B25,FIND(" ",B25)+1)+1,100)))-1,100)),TRIM(MID(B25,FIND(" ",B25&" ")+1,100)))&", buen día."&CHAR(10)&CHAR(10)&"Te escribo porque "&E25&" personas de tu equipo aún no se han sentado en el Capítulo 1:"&CHAR(10)&CHAR(10)&"1. David Eduardo Luque Tejada 2. Flor De María Montoya Cruzado 3. Mercedes Margot Flores Ipanaqui"&CHAR(10)&CHAR(10)&"El próximo C1 es el 1, 2 y 3 de mayo. Necesito saber el estatus real de cada uno: si tienen la intención de sentarse, qué está pasando con su proceso y si cuentan con tu acompañamiento para llegar."&CHAR(10)&CHAR(10)&"Por favor respóndenos a este mismo número con el estatus de cada uno antes del viernes."&CHAR(10)&CHAR(10)&"Comunicaciones Crear Poder Sin Límites Perú" -> Hola Rodrigo, buen día. Te escribo porque 3 personas de tu equipo aún no se han sentado en el Capítulo 1: 1. David Eduardo Luque Tejada 2. Flor De María Montoya Cruzado 3. Mercedes Margot Flores Ipanaqui El próximo C1 es el 1, 2 y 3 de mayo. Necesito saber el estatus real de cada uno: si tienen la intención de sentarse, qué está pasando con su proceso y si cuentan con tu acompañamiento para llegar. Por favor respóndenos a este mismo número con el estatus de cada uno antes del viernes. Comunicaciones Crear Poder Sin Límites Perú
A26: 22 | B26: Palomino Anaya Sebastian Manuel | C26: EQUIPO 15 | D26: 907434050 | E26: =COUNTIF(DATA!A:A,B26) -> 1 | F26: =COUNTIFS(DATA!A:A,B26,DATA!G:G,"CONFIRMADO") -> 0 | G26: =IF(E26=0,"SIN DATA",IF(F26=E26,"✅ COMPLETO",IF(F26>0,"🔄 PARCIAL",IF(COUNTIFS(DATA!A:A,B26,DATA!G:G,"PENDIENTE")=E26,"⏳ PENDIENTE","⚠ MIXTO")))) -> ⏳ PENDIENTE | H26: ="Hola "&IFERROR(LEFT(TRIM(MID(B26,FIND(" ",B26,FIND(" ",B26)+1)+1,100)),IFERROR(FIND(" ",TRIM(MID(B26,FIND(" ",B26,FIND(" ",B26)+1)+1,100)))-1,100)),TRIM(MID(B26,FIND(" ",B26&" ")+1,100)))&", buen día."&CHAR(10)&CHAR(10)&"Te escribo porque una persona de tu equipo aún no se ha sentado en el Capítulo 1:"&CHAR(10)&CHAR(10)&"1. Julián Aquino Huaman"&CHAR(10)&CHAR(10)&"El próximo C1 es el 1, 2 y 3 de mayo. Necesito saber el estatus real de esta persona: si tiene la intención de sentarse, qué está pasando con su proceso y si cuenta con tu acompañamiento para llegar."&CHAR(10)&CHAR(10)&"Por favor respóndenos a este mismo número con el estatus de esta persona antes del viernes."&CHAR(10)&CHAR(10)&"Comunicaciones Crear Poder Sin Límites Perú" -> Hola Sebastian, buen día. Te escribo porque una persona de tu equipo aún no se ha sentado en el Capítulo 1: 1. Julián Aquino Huaman El próximo C1 es el 1, 2 y 3 de mayo. Necesito saber el estatus real de esta persona: si tiene la intención de sentarse, qué está pasando con su proceso y si cuenta con tu acompañamiento para llegar. Por favor respóndenos a este mismo número con el estatus de esta persona antes del viernes. Comunicaciones Crear Poder Sin Límites Perú
A27: 23 | B27: De La Cruz Huaytalla Sheila | C27: EQUIPO 15 | D27: 917479833 | E27: =COUNTIF(DATA!A:A,B27) -> 3 | F27: =COUNTIFS(DATA!A:A,B27,DATA!G:G,"CONFIRMADO") -> 0 | G27: =IF(E27=0,"SIN DATA",IF(F27=E27,"✅ COMPLETO",IF(F27>0,"🔄 PARCIAL",IF(COUNTIFS(DATA!A:A,B27,DATA!G:G,"PENDIENTE")=E27,"⏳ PENDIENTE","⚠ MIXTO")))) -> ⏳ PENDIENTE | H27: ="Hola "&IFERROR(LEFT(TRIM(MID(B27,FIND(" ",B27,FIND(" ",B27)+1)+1,100)),IFERROR(FIND(" ",TRIM(MID(B27,FIND(" ",B27,FIND(" ",B27)+1)+1,100)))-1,100)),TRIM(MID(B27,FIND(" ",B27&" ")+1,100)))&", buen día."&CHAR(10)&CHAR(10)&"Te escribo porque "&E27&" personas de tu equipo aún no se han sentado en el Capítulo 1:"&CHAR(10)&CHAR(10)&"1. Rosalin Carolina Pernia Bandera 2. Lizbeth Briceño Heredia 3. Veronica Delgado Rimarachin"&CHAR(10)&CHAR(10)&"El próximo C1 es el 1, 2 y 3 de mayo. Necesito saber el estatus real de cada uno: si tienen la intención de sentarse, qué está pasando con su proceso y si cuentan con tu acompañamiento para llegar."&CHAR(10)&CHAR(10)&"Por favor respóndenos a este mismo número con el estatus de cada uno antes del viernes."&CHAR(10)&CHAR(10)&"Comunicaciones Crear Poder Sin Límites Perú" -> Hola Cruz, buen día. Te escribo porque 3 personas de tu equipo aún no se han sentado en el Capítulo 1: 1. Rosalin Carolina Pernia Bandera 2. Lizbeth Briceño Heredia 3. Veronica Delgado Rimarachin El próximo C1 es el 1, 2 y 3 de mayo. Necesito saber el estatus real de cada uno: si tienen la intención de sentarse, qué está pasando con su proceso y si cuentan con tu acompañamiento para llegar. Por favor respóndenos a este mismo número con el estatus de cada uno antes del viernes. Comunicaciones Crear Poder Sin Límites Perú
A28: 24 | B28: Matta Morales Mauricio Andre | C28: EQUIPO 15 | D28: 971092525 | E28: =COUNTIF(DATA!A:A,B28) -> 1 | F28: =COUNTIFS(DATA!A:A,B28,DATA!G:G,"CONFIRMADO") -> 0 | G28: =IF(E28=0,"SIN DATA",IF(F28=E28,"✅ COMPLETO",IF(F28>0,"🔄 PARCIAL",IF(COUNTIFS(DATA!A:A,B28,DATA!G:G,"PENDIENTE")=E28,"⏳ PENDIENTE","⚠ MIXTO")))) -> ⏳ PENDIENTE | H28: ="Hola "&IFERROR(LEFT(TRIM(MID(B28,FIND(" ",B28,FIND(" ",B28)+1)+1,100)),IFERROR(FIND(" ",TRIM(MID(B28,FIND(" ",B28,FIND(" ",B28)+1)+1,100)))-1,100)),TRIM(MID(B28,FIND(" ",B28&" ")+1,100)))&", buen día."&CHAR(10)&CHAR(10)&"Te escribo porque una persona de tu equipo aún no se ha sentado en el Capítulo 1:"&CHAR(10)&CHAR(10)&"1. Rafael Gonzales Aranzaens"&CHAR(10)&CHAR(10)&"El próximo C1 es el 1, 2 y 3 de mayo. Necesito saber el estatus real de esta persona: si tiene la intención de sentarse, qué está pasando con su proceso y si cuenta con tu acompañamiento para llegar."&CHAR(10)&CHAR(10)&"Por favor respóndenos a este mismo número con el estatus de esta persona antes del viernes."&CHAR(10)&CHAR(10)&"Comunicaciones Crear Poder Sin Límites Perú" -> Hola Mauricio, buen día. Te escribo porque una persona de tu equipo aún no se ha sentado en el Capítulo 1: 1. Rafael Gonzales Aranzaens El próximo C1 es el 1, 2 y 3 de mayo. Necesito saber el estatus real de esta persona: si tiene la intención de sentarse, qué está pasando con su proceso y si cuenta con tu acompañamiento para llegar. Por favor respóndenos a este mismo número con el estatus de esta persona antes del viernes. Comunicaciones Crear Poder Sin Límites Perú
A29: 25 | B29: Castillo Tipismana Carlos Alberto | C29: EQUIPO 15 | D29: 982791484 | E29: =COUNTIF(DATA!A:A,B29) -> 1 | F29: =COUNTIFS(DATA!A:A,B29,DATA!G:G,"CONFIRMADO") -> 0 | G29: =IF(E29=0,"SIN DATA",IF(F29=E29,"✅ COMPLETO",IF(F29>0,"🔄 PARCIAL",IF(COUNTIFS(DATA!A:A,B29,DATA!G:G,"PENDIENTE")=E29,"⏳ PENDIENTE","⚠ MIXTO")))) -> ⏳ PENDIENTE | H29: ="Hola "&IFERROR(LEFT(TRIM(MID(B29,FIND(" ",B29,FIND(" ",B29)+1)+1,100)),IFERROR(FIND(" ",TRIM(MID(B29,FIND(" ",B29,FIND(" ",B29)+1)+1,100)))-1,100)),TRIM(MID(B29,FIND(" ",B29&" ")+1,100)))&", buen día."&CHAR(10)&CHAR(10)&"Te escribo porque una persona de tu equipo aún no se ha sentado en el Capítulo 1:"&CHAR(10)&CHAR(10)&"1. Jhanet De La Cruz Bautista"&CHAR(10)&CHAR(10)&"El próximo C1 es el 1, 2 y 3 de mayo. Necesito saber el estatus real de esta persona: si tiene la intención de sentarse, qué está pasando con su proceso y si cuenta con tu acompañamiento para llegar."&CHAR(10)&CHAR(10)&"Por favor respóndenos a este mismo número con el estatus de esta persona antes del viernes."&CHAR(10)&CHAR(10)&"Comunicaciones Crear Poder Sin Límites Perú" -> Hola Carlos, buen día. Te escribo porque una persona de tu equipo aún no se ha sentado en el Capítulo 1: 1. Jhanet De La Cruz Bautista El próximo C1 es el 1, 2 y 3 de mayo. Necesito saber el estatus real de esta persona: si tiene la intención de sentarse, qué está pasando con su proceso y si cuenta con tu acompañamiento para llegar. Por favor respóndenos a este mismo número con el estatus de esta persona antes del viernes. Comunicaciones Crear Poder Sin Límites Perú
A30: 26 | B30: Quispe Choque Jorge Armando | C30: EQUIPO 15 | D30: 980502144 | E30: =COUNTIF(DATA!A:A,B30) -> 1 | F30: =COUNTIFS(DATA!A:A,B30,DATA!G:G,"CONFIRMADO") -> 0 | G30: =IF(E30=0,"SIN DATA",IF(F30=E30,"✅ COMPLETO",IF(F30>0,"🔄 PARCIAL",IF(COUNTIFS(DATA!A:A,B30,DATA!G:G,"PENDIENTE")=E30,"⏳ PENDIENTE","⚠ MIXTO")))) -> ⏳ PENDIENTE | H30: ="Hola "&IFERROR(LEFT(TRIM(MID(B30,FIND(" ",B30,FIND(" ",B30)+1)+1,100)),IFERROR(FIND(" ",TRIM(MID(B30,FIND(" ",B30,FIND(" ",B30)+1)+1,100)))-1,100)),TRIM(MID(B30,FIND(" ",B30&" ")+1,100)))&", buen día."&CHAR(10)&CHAR(10)&"Te escribo porque una persona de tu equipo aún no se ha sentado en el Capítulo 1:"&CHAR(10)&CHAR(10)&"1. Willy Adrian Quispe"&CHAR(10)&CHAR(10)&"El próximo C1 es el 1, 2 y 3 de mayo. Necesito saber el estatus real de esta persona: si tiene la intención de sentarse, qué está pasando con su proceso y si cuenta con tu acompañamiento para llegar."&CHAR(10)&CHAR(10)&"Por favor respóndenos a este mismo número con el estatus de esta persona antes del viernes."&CHAR(10)&CHAR(10)&"Comunicaciones Crear Poder Sin Límites Perú" -> Hola Jorge, buen día. Te escribo porque una persona de tu equipo aún no se ha sentado en el Capítulo 1: 1. Willy Adrian Quispe El próximo C1 es el 1, 2 y 3 de mayo. Necesito saber el estatus real de esta persona: si tiene la intención de sentarse, qué está pasando con su proceso y si cuenta con tu acompañamiento para llegar. Por favor respóndenos a este mismo número con el estatus de esta persona antes del viernes. Comunicaciones Crear Poder Sin Límites Perú
A31: 27 | B31: Matias Uriol Kresly Stefanny | C31: EQUIPO 15 | D31: 940280000 | E31: =COUNTIF(DATA!A:A,B31) -> 1 | F31: =COUNTIFS(DATA!A:A,B31,DATA!G:G,"CONFIRMADO") -> 0 | G31: =IF(E31=0,"SIN DATA",IF(F31=E31,"✅ COMPLETO",IF(F31>0,"🔄 PARCIAL",IF(COUNTIFS(DATA!A:A,B31,DATA!G:G,"PENDIENTE")=E31,"⏳ PENDIENTE","⚠ MIXTO")))) -> ⏳ PENDIENTE | H31: ="Hola "&IFERROR(LEFT(TRIM(MID(B31,FIND(" ",B31,FIND(" ",B31)+1)+1,100)),IFERROR(FIND(" ",TRIM(MID(B31,FIND(" ",B31,FIND(" ",B31)+1)+1,100)))-1,100)),TRIM(MID(B31,FIND(" ",B31&" ")+1,100)))&", buen día."&CHAR(10)&CHAR(10)&"Te escribo porque una persona de tu equipo aún no se ha sentado en el Capítulo 1:"&CHAR(10)&CHAR(10)&"1. Giannina Giselle Espiritu Palomino"&CHAR(10)&CHAR(10)&"El próximo C1 es el 1, 2 y 3 de mayo. Necesito saber el estatus real de esta persona: si tiene la intención de sentarse, qué está pasando con su proceso y si cuenta con tu acompañamiento para llegar."&CHAR(10)&CHAR(10)&"Por favor respóndenos a este mismo número con el estatus de esta persona antes del viernes."&CHAR(10)&CHAR(10)&"Comunicaciones Crear Poder Sin Límites Perú" -> Hola Kresly, buen día. Te escribo porque una persona de tu equipo aún no se ha sentado en el Capítulo 1: 1. Giannina Giselle Espiritu Palomino El próximo C1 es el 1, 2 y 3 de mayo. Necesito saber el estatus real de esta persona: si tiene la intención de sentarse, qué está pasando con su proceso y si cuenta con tu acompañamiento para llegar. Por favor respóndenos a este mismo número con el estatus de esta persona antes del viernes. Comunicaciones Crear Poder Sin Límites Perú
A32: 28 | B32: Medrano De Meza Luz Angelica | C32: EQUIPO 15 | D32: 955619099 | E32: =COUNTIF(DATA!A:A,B32) -> 1 | F32: =COUNTIFS(DATA!A:A,B32,DATA!G:G,"CONFIRMADO") -> 0 | G32: =IF(E32=0,"SIN DATA",IF(F32=E32,"✅ COMPLETO",IF(F32>0,"🔄 PARCIAL",IF(COUNTIFS(DATA!A:A,B32,DATA!G:G,"PENDIENTE")=E32,"⏳ PENDIENTE","⚠ MIXTO")))) -> ⏳ PENDIENTE | H32: ="Hola "&IFERROR(LEFT(TRIM(MID(B32,FIND(" ",B32,FIND(" ",B32)+1)+1,100)),IFERROR(FIND(" ",TRIM(MID(B32,FIND(" ",B32,FIND(" ",B32)+1)+1,100)))-1,100)),TRIM(MID(B32,FIND(" ",B32&" ")+1,100)))&", buen día."&CHAR(10)&CHAR(10)&"Te escribo porque una persona de tu equipo aún no se ha sentado en el Capítulo 1:"&CHAR(10)&CHAR(10)&"1. Vanesa Otrera"&CHAR(10)&CHAR(10)&"El próximo C1 es el 1, 2 y 3 de mayo. Necesito saber el estatus real de esta persona: si tiene la intención de sentarse, qué está pasando con su proceso y si cuenta con tu acompañamiento para llegar."&CHAR(10)&CHAR(10)&"Por favor respóndenos a este mismo número con el estatus de esta persona antes del viernes."&CHAR(10)&CHAR(10)&"Comunicaciones Crear Poder Sin Límites Perú" -> Hola Meza, buen día. Te escribo porque una persona de tu equipo aún no se ha sentado en el Capítulo 1: 1. Vanesa Otrera El próximo C1 es el 1, 2 y 3 de mayo. Necesito saber el estatus real de esta persona: si tiene la intención de sentarse, qué está pasando con su proceso y si cuenta con tu acompañamiento para llegar. Por favor respóndenos a este mismo número con el estatus de esta persona antes del viernes. Comunicaciones Crear Poder Sin Límites Perú
A33: 29 | B33: Malpartida Flores Nancy | C33: EQUIPO 15 | D33: 993577714 | E33: =COUNTIF(DATA!A:A,B33) -> 1 | F33: =COUNTIFS(DATA!A:A,B33,DATA!G:G,"CONFIRMADO") -> 0 | G33: =IF(E33=0,"SIN DATA",IF(F33=E33,"✅ COMPLETO",IF(F33>0,"🔄 PARCIAL",IF(COUNTIFS(DATA!A:A,B33,DATA!G:G,"PENDIENTE")=E33,"⏳ PENDIENTE","⚠ MIXTO")))) -> ⏳ PENDIENTE | H33: ="Hola "&IFERROR(LEFT(TRIM(MID(B33,FIND(" ",B33,FIND(" ",B33)+1)+1,100)),IFERROR(FIND(" ",TRIM(MID(B33,FIND(" ",B33,FIND(" ",B33)+1)+1,100)))-1,100)),TRIM(MID(B33,FIND(" ",B33&" ")+1,100)))&", buen día."&CHAR(10)&CHAR(10)&"Te escribo porque una persona de tu equipo aún no se ha sentado en el Capítulo 1:"&CHAR(10)&CHAR(10)&"1. Enrique Marco Navarro"&CHAR(10)&CHAR(10)&"El próximo C1 es el 1, 2 y 3 de mayo. Necesito saber el estatus real de esta persona: si tiene la intención de sentarse, qué está pasando con su proceso y si cuenta con tu acompañamiento para llegar."&CHAR(10)&CHAR(10)&"Por favor respóndenos a este mismo número con el estatus de esta persona antes del viernes."&CHAR(10)&CHAR(10)&"Comunicaciones Crear Poder Sin Límites Perú" -> Hola Nancy, buen día. Te escribo porque una persona de tu equipo aún no se ha sentado en el Capítulo 1: 1. Enrique Marco Navarro El próximo C1 es el 1, 2 y 3 de mayo. Necesito saber el estatus real de esta persona: si tiene la intención de sentarse, qué está pasando con su proceso y si cuenta con tu acompañamiento para llegar. Por favor respóndenos a este mismo número con el estatus de esta persona antes del viernes. Comunicaciones Crear Poder Sin Límites Perú
A34: 30 | B34: Alcantata Maurtua Mayra Alejandra | C34: EQUIPO 15 | D34: 977477566 | E34: =COUNTIF(DATA!A:A,B34) -> 2 | F34: =COUNTIFS(DATA!A:A,B34,DATA!G:G,"CONFIRMADO") -> 0 | G34: =IF(E34=0,"SIN DATA",IF(F34=E34,"✅ COMPLETO",IF(F34>0,"🔄 PARCIAL",IF(COUNTIFS(DATA!A:A,B34,DATA!G:G,"PENDIENTE")=E34,"⏳ PENDIENTE","⚠ MIXTO")))) -> ⏳ PENDIENTE | H34: ="Hola "&IFERROR(LEFT(TRIM(MID(B34,FIND(" ",B34,FIND(" ",B34)+1)+1,100)),IFERROR(FIND(" ",TRIM(MID(B34,FIND(" ",B34,FIND(" ",B34)+1)+1,100)))-1,100)),TRIM(MID(B34,FIND(" ",B34&" ")+1,100)))&", buen día."&CHAR(10)&CHAR(10)&"Te escribo porque "&E34&" personas de tu equipo aún no se han sentado en el Capítulo 1:"&CHAR(10)&CHAR(10)&"1. Héctor Wiliam Torres Choquez 2. Angella Marianne Hernandez Salvatierra"&CHAR(10)&CHAR(10)&"El próximo C1 es el 1, 2 y 3 de mayo. Necesito saber el estatus real de cada uno: si tienen la intención de sentarse, qué está pasando con su proceso y si cuentan con tu acompañamiento para llegar."&CHAR(10)&CHAR(10)&"Por favor respóndenos a este mismo número con el estatus de cada uno antes del viernes."&CHAR(10)&CHAR(10)&"Comunicaciones Crear Poder Sin Límites Perú" -> Hola Mayra, buen día. Te escribo porque 2 personas de tu equipo aún no se han sentado en el Capítulo 1: 1. Héctor Wiliam Torres Choquez 2. Angella Marianne Hernandez Salvatierra El próximo C1 es el 1, 2 y 3 de mayo. Necesito saber el estatus real de cada uno: si tienen la intención de sentarse, qué está pasando con su proceso y si cuentan con tu acompañamiento para llegar. Por favor respóndenos a este mismo número con el estatus de cada uno antes del viernes. Comunicaciones Crear Poder Sin Límites Perú
A35: 31 | B35: Antaurco Perez Joel | C35: EQUIPO 15 | D35: 933969837 | E35: =COUNTIF(DATA!A:A,B35) -> 1 | F35: =COUNTIFS(DATA!A:A,B35,DATA!G:G,"CONFIRMADO") -> 0 | G35: =IF(E35=0,"SIN DATA",IF(F35=E35,"✅ COMPLETO",IF(F35>0,"🔄 PARCIAL",IF(COUNTIFS(DATA!A:A,B35,DATA!G:G,"PENDIENTE")=E35,"⏳ PENDIENTE","⚠ MIXTO")))) -> ⏳ PENDIENTE | H35: ="Hola "&IFERROR(LEFT(TRIM(MID(B35,FIND(" ",B35,FIND(" ",B35)+1)+1,100)),IFERROR(FIND(" ",TRIM(MID(B35,FIND(" ",B35,FIND(" ",B35)+1)+1,100)))-1,100)),TRIM(MID(B35,FIND(" ",B35&" ")+1,100)))&", buen día."&CHAR(10)&CHAR(10)&"Te escribo porque una persona de tu equipo aún no se ha sentado en el Capítulo 1:"&CHAR(10)&CHAR(10)&"1. Alisson Yuviri Simón Cabello"&CHAR(10)&CHAR(10)&"El próximo C1 es el 1, 2 y 3 de mayo. Necesito saber el estatus real de esta persona: si tiene la intención de sentarse, qué está pasando con su proceso y si cuenta con tu acompañamiento para llegar."&CHAR(10)&CHAR(10)&"Por favor respóndenos a este mismo número con el estatus de esta persona antes del viernes."&CHAR(10)&CHAR(10)&"Comunicaciones Crear Poder Sin Límites Perú" -> Hola Joel, buen día. Te escribo porque una persona de tu equipo aún no se ha sentado en el Capítulo 1: 1. Alisson Yuviri Simón Cabello El próximo C1 es el 1, 2 y 3 de mayo. Necesito saber el estatus real de esta persona: si tiene la intención de sentarse, qué está pasando con su proceso y si cuenta con tu acompañamiento para llegar. Por favor respóndenos a este mismo número con el estatus de esta persona antes del viernes. Comunicaciones Crear Poder Sin Límites Perú
A36: 32 | B36: Arone Chachayma Cristian Jonathan | C36: EQUIPO 15 | D36: 961496514 | E36: =COUNTIF(DATA!A:A,B36) -> 2 | F36: =COUNTIFS(DATA!A:A,B36,DATA!G:G,"CONFIRMADO") -> 0 | G36: =IF(E36=0,"SIN DATA",IF(F36=E36,"✅ COMPLETO",IF(F36>0,"🔄 PARCIAL",IF(COUNTIFS(DATA!A:A,B36,DATA!G:G,"PENDIENTE")=E36,"⏳ PENDIENTE","⚠ MIXTO")))) -> ⏳ PENDIENTE | H36: ="Hola "&IFERROR(LEFT(TRIM(MID(B36,FIND(" ",B36,FIND(" ",B36)+1)+1,100)),IFERROR(FIND(" ",TRIM(MID(B36,FIND(" ",B36,FIND(" ",B36)+1)+1,100)))-1,100)),TRIM(MID(B36,FIND(" ",B36&" ")+1,100)))&", buen día."&CHAR(10)&CHAR(10)&"Te escribo porque "&E36&" personas de tu equipo aún no se han sentado en el Capítulo 1:"&CHAR(10)&CHAR(10)&"1. Diana Edith Sánchez Correa 2. Prudencio Arone Robles"&CHAR(10)&CHAR(10)&"El próximo C1 es el 1, 2 y 3 de mayo. Necesito saber el estatus real de cada uno: si tienen la intención de sentarse, qué está pasando con su proceso y si cuentan con tu acompañamiento para llegar."&CHAR(10)&CHAR(10)&"Por favor respóndenos a este mismo número con el estatus de cada uno antes del viernes."&CHAR(10)&CHAR(10)&"Comunicaciones Crear Poder Sin Límites Perú" -> Hola Cristian, buen día. Te escribo porque 2 personas de tu equipo aún no se han sentado en el Capítulo 1: 1. Diana Edith Sánchez Correa 2. Prudencio Arone Robles El próximo C1 es el 1, 2 y 3 de mayo. Necesito saber el estatus real de cada uno: si tienen la intención de sentarse, qué está pasando con su proceso y si cuentan con tu acompañamiento para llegar. Por favor respóndenos a este mismo número con el estatus de cada uno antes del viernes. Comunicaciones Crear Poder Sin Límites Perú
A37: 33 | B37: Ore Bendezu Silvia Raquel | C37: EQUIPO 15 | D37: 925530813 | E37: =COUNTIF(DATA!A:A,B37) -> 2 | F37: =COUNTIFS(DATA!A:A,B37,DATA!G:G,"CONFIRMADO") -> 0 | G37: =IF(E37=0,"SIN DATA",IF(F37=E37,"✅ COMPLETO",IF(F37>0,"🔄 PARCIAL",IF(COUNTIFS(DATA!A:A,B37,DATA!G:G,"PENDIENTE")=E37,"⏳ PENDIENTE","⚠ MIXTO")))) -> ⏳ PENDIENTE | H37: ="Hola "&IFERROR(LEFT(TRIM(MID(B37,FIND(" ",B37,FIND(" ",B37)+1)+1,100)),IFERROR(FIND(" ",TRIM(MID(B37,FIND(" ",B37,FIND(" ",B37)+1)+1,100)))-1,100)),TRIM(MID(B37,FIND(" ",B37&" ")+1,100)))&", buen día."&CHAR(10)&CHAR(10)&"Te escribo porque "&E37&" personas de tu equipo aún no se han sentado en el Capítulo 1:"&CHAR(10)&CHAR(10)&"1. Eugenia Karla Huamanin Leon 2. Lidia Sefora Vela Rodríguez De Rengifo Vela Rodriguez"&CHAR(10)&CHAR(10)&"El próximo C1 es el 1, 2 y 3 de mayo. Necesito saber el estatus real de cada uno: si tienen la intención de sentarse, qué está pasando con su proceso y si cuentan con tu acompañamiento para llegar."&CHAR(10)&CHAR(10)&"Por favor respóndenos a este mismo número con el estatus de cada uno antes del viernes."&CHAR(10)&CHAR(10)&"Comunicaciones Crear Poder Sin Límites Perú" -> Hola Silvia, buen día. Te escribo porque 2 personas de tu equipo aún no se han sentado en el Capítulo 1: 1. Eugenia Karla Huamanin Leon 2. Lidia Sefora Vela Rodríguez De Rengifo Vela Rodriguez El próximo C1 es el 1, 2 y 3 de mayo. Necesito saber el estatus real de cada uno: si tienen la intención de sentarse, qué está pasando con su proceso y si cuentan con tu acompañamiento para llegar. Por favor respóndenos a este mismo número con el estatus de cada uno antes del viernes. Comunicaciones Crear Poder Sin Límites Perú
A38: 34 | B38: Riano Zubieta Noris | C38: EQUIPO 15 | D38: 989577877 | E38: =COUNTIF(DATA!A:A,B38) -> 1 | F38: =COUNTIFS(DATA!A:A,B38,DATA!G:G,"CONFIRMADO") -> 0 | G38: =IF(E38=0,"SIN DATA",IF(F38=E38,"✅ COMPLETO",IF(F38>0,"🔄 PARCIAL",IF(COUNTIFS(DATA!A:A,B38,DATA!G:G,"PENDIENTE")=E38,"⏳ PENDIENTE","⚠ MIXTO")))) -> ⏳ PENDIENTE | H38: ="Hola "&IFERROR(LEFT(TRIM(MID(B38,FIND(" ",B38,FIND(" ",B38)+1)+1,100)),IFERROR(FIND(" ",TRIM(MID(B38,FIND(" ",B38,FIND(" ",B38)+1)+1,100)))-1,100)),TRIM(MID(B38,FIND(" ",B38&" ")+1,100)))&", buen día."&CHAR(10)&CHAR(10)&"Te escribo porque una persona de tu equipo aún no se ha sentado en el Capítulo 1:"&CHAR(10)&CHAR(10)&"1. Victor Filomon Espinal Chuquillanqui"&CHAR(10)&CHAR(10)&"El próximo C1 es el 1, 2 y 3 de mayo. Necesito saber el estatus real de esta persona: si tiene la intención de sentarse, qué está pasando con su proceso y si cuenta con tu acompañamiento para llegar."&CHAR(10)&CHAR(10)&"Por favor respóndenos a este mismo número con el estatus de esta persona antes del viernes."&CHAR(10)&CHAR(10)&"Comunicaciones Crear Poder Sin Límites Perú" -> Hola Noris, buen día. Te escribo porque una persona de tu equipo aún no se ha sentado en el Capítulo 1: 1. Victor Filomon Espinal Chuquillanqui El próximo C1 es el 1, 2 y 3 de mayo. Necesito saber el estatus real de esta persona: si tiene la intención de sentarse, qué está pasando con su proceso y si cuenta con tu acompañamiento para llegar. Por favor respóndenos a este mismo número con el estatus de esta persona antes del viernes. Comunicaciones Crear Poder Sin Límites Perú
A39: 35 | B39: Roca De La Cruz Maria Purina | C39: EQUIPO 15 | D39: 978095350 | E39: =COUNTIF(DATA!A:A,B39) -> 1 | F39: =COUNTIFS(DATA!A:A,B39,DATA!G:G,"CONFIRMADO") -> 0 | G39: =IF(E39=0,"SIN DATA",IF(F39=E39,"✅ COMPLETO",IF(F39>0,"🔄 PARCIAL",IF(COUNTIFS(DATA!A:A,B39,DATA!G:G,"PENDIENTE")=E39,"⏳ PENDIENTE","⚠ MIXTO")))) -> ⏳ PENDIENTE | H39: ="Hola "&IFERROR(LEFT(TRIM(MID(B39,FIND(" ",B39,FIND(" ",B39)+1)+1,100)),IFERROR(FIND(" ",TRIM(MID(B39,FIND(" ",B39,FIND(" ",B39)+1)+1,100)))-1,100)),TRIM(MID(B39,FIND(" ",B39&" ")+1,100)))&", buen día."&CHAR(10)&CHAR(10)&"Te escribo porque una persona de tu equipo aún no se ha sentado en el Capítulo 1:"&CHAR(10)&CHAR(10)&"1. Leydi Estefany Ochoa Vega"&CHAR(10)&CHAR(10)&"El próximo C1 es el 1, 2 y 3 de mayo. Necesito saber el estatus real de esta persona: si tiene la intención de sentarse, qué está pasando con su proceso y si cuenta con tu acompañamiento para llegar."&CHAR(10)&CHAR(10)&"Por favor respóndenos a este mismo número con el estatus de esta persona antes del viernes."&CHAR(10)&CHAR(10)&"Comunicaciones Crear Poder Sin Límites Perú" -> Hola La, buen día. Te escribo porque una persona de tu equipo aún no se ha sentado en el Capítulo 1: 1. Leydi Estefany Ochoa Vega El próximo C1 es el 1, 2 y 3 de mayo. Necesito saber el estatus real de esta persona: si tiene la intención de sentarse, qué está pasando con su proceso y si cuenta con tu acompañamiento para llegar. Por favor respóndenos a este mismo número con el estatus de esta persona antes del viernes. Comunicaciones Crear Poder Sin Límites Perú
A40: 36 | B40: Morales Carcelen Elizabeth Milagros | C40: EQUIPO 15 | D40: 998450224 | E40: =COUNTIF(DATA!A:A,B40) -> 2 | F40: =COUNTIFS(DATA!A:A,B40,DATA!G:G,"CONFIRMADO") -> 0 | G40: =IF(E40=0,"SIN DATA",IF(F40=E40,"✅ COMPLETO",IF(F40>0,"🔄 PARCIAL",IF(COUNTIFS(DATA!A:A,B40,DATA!G:G,"PENDIENTE")=E40,"⏳ PENDIENTE","⚠ MIXTO")))) -> ⏳ PENDIENTE | H40: ="Hola "&IFERROR(LEFT(TRIM(MID(B40,FIND(" ",B40,FIND(" ",B40)+1)+1,100)),IFERROR(FIND(" ",TRIM(MID(B40,FIND(" ",B40,FIND(" ",B40)+1)+1,100)))-1,100)),TRIM(MID(B40,FIND(" ",B40&" ")+1,100)))&", buen día."&CHAR(10)&CHAR(10)&"Te escribo porque "&E40&" personas de tu equipo aún no se han sentado en el Capítulo 1:"&CHAR(10)&CHAR(10)&"1. Jaqueline Roman Contreras 2. Marco Morales Carcelen"&CHAR(10)&CHAR(10)&"El próximo C1 es el 1, 2 y 3 de mayo. Necesito saber el estatus real de cada uno: si tienen la intención de sentarse, qué está pasando con su proceso y si cuentan con tu acompañamiento para llegar."&CHAR(10)&CHAR(10)&"Por favor respóndenos a este mismo número con el estatus de cada uno antes del viernes."&CHAR(10)&CHAR(10)&"Comunicaciones Crear Poder Sin Límites Perú" -> Hola Elizabeth, buen día. Te escribo porque 2 personas de tu equipo aún no se han sentado en el Capítulo 1: 1. Jaqueline Roman Contreras 2. Marco Morales Carcelen El próximo C1 es el 1, 2 y 3 de mayo. Necesito saber el estatus real de cada uno: si tienen la intención de sentarse, qué está pasando con su proceso y si cuentan con tu acompañamiento para llegar. Por favor respóndenos a este mismo número con el estatus de cada uno antes del viernes. Comunicaciones Crear Poder Sin Límites Perú
