Workbook

Sheet ALIADOS C1 E25
A1: CAPITAN | B1: MANUEL YAKIMA RIVERA
A2: CREADOR CUANTICO | B2: EQUIPO | C2: RESPONSABLE | D2: ESTADO | E2: OBSERVACIONES | F2: QT | G2: reto1 | H2: Grounding | I2: video | J2: forms
A3: CRISTIAN ARONE | B3: 15 | C3: JOYCE | D3: NO | E3: CONFIRMA YAKIMA | H3: OK
A4: AVRIL ESTEPHANIA GARCIA MEDINA | B4: 16 | C4: JOYCE | D4: NO | E4: SER LIDER EN SU CARRERA | H4: OK
A5: CARMEN PÉREZ PÉREZ | B5: 5 | C5: KRISCIA | D5: OK | E5: SER LIDER EN ALTO RENDIMIENTO | H5: OK
A6: TONNY GUTIERREZ | B6: 8 | C6: GARETH | D6: NC
A7: ELVIS CUELLAR | B7: 8 | C7: JOYCE | D7: NC
A8: JHEN PONCE | B8: 7 | C8: GARETH | D8: OK | E8: CONFIRMA YAKIMA | H8: OK | J8: 41
A9: JUANA MARIA FALCON ROJAS | B9: 10 | C9: GARETH | D9: NP
A10: GERALDINE VANESSA SOTOMAYOR BAZAN | B10: 10 | C10: JOYCE | D10: NC
A11: YUSMELY DESIREE GARCIA LLOVERA | B11: 10 | C11: JOYCE | D11: NP
A12: JEANNET LEON LEDESMA | B12: 10 | C12: KRISCIA | D12: NC
A13: JOSÉ BLADIMER RAMOS SIQUEROS | B13: 10 | C13: KRISCIA | D13: NP | E13: TRABAJO
A14: MARIA CELLI HUAYANCA DIAZ | B14: 11 | C14: GARETH | D14: XC
A15: MARCO ANTONIO VILLARREAL VALDIVIEZO | B15: 7 | C15: JOYCE | D15: OK | E15: REENTRENARME A SER LIDER | H15: OK
A16: ALEXANDRA TAPULLIMA CORDOVA | B16: 11 | C16: JOYCE | D16: XC
A17: HERMÓGENES UNTIVEROA CISNEROS | B17: 11 | C17: JOYCE | D17: XC | E17: LLAMAR 17H00
A18: ANAMELVA QUIÑONES BELTRÁN | B18: 11 | C18: KRISCIA | D18: NC
A19: JANET DURAND YARASQUI | B19: 11 | C19: KRISCIA | D19: NP | E19: TRABAJO
A20: ROBERTO CONDEZO | B20: 8 | C20: JOYCE | D20: OK | E20: SER COMPROMISO INQUEBRANTABLE | H20: OK
A21: FUEL DURAND HUAYNATE | B21: 12 | C21: GARETH | D21: NP
A22: SHIRLEY RIVERA HUAMAN | B22: 12 | C22: GARETH | D22: SIG | E22: E26
A23: JOHNNY EDUARDO HUÁNUCO ARELLANO | B23: 12 | C23: JOYCE | D23: XC | E23: LLAMAR 20H30
A24: LUISA PÉREZ CHINCHAY | B24: 12 | C24: JOYCE | D24: NC
A25: PAMELA MELISA MORALES VEGA | B25: 12 | C25: JOYCE | D25: NP | E25: TRABAJO
A26: DIEGO HECTOR BARBIERI GALECIO | B26: 11 | C26: KRISCIA | D26: OK | E26: SER LIDER EN ALTO RENDIMIENTO, CONECTAR | H26: OK | J26: =44+1+5 -> 50
A27: JEAN CARLOS RIOS | B27: 13 | C27: GARETH | D27: NP
A28: YANINA ESTEFANIA MEJIA ROMERO | B28: 13 | C28: GARETH | D28: NC
A29: MARÍA JESÚS CARRASCO LLATAS | B29: 13 | C29: GARETH | D29: NP
A30: PILAR DE LA CRUZ | B30: 13 | C30: GARETH | D30: XC | E30: Confirma Lunes - Llama Joyce
A31: ANGELLA BOLLET | B31: 13 | C31: JOYCE | D31: NP | E31: SERVICIO
A32: RAQUEL RIVEROS RAMOS | B32: 13 | C32: JOYCE | D32: XC
A33: RAÚL CHÁVEZ INCHE | B33: 13 | C33: JOYCE | E33: COMPROMISO INQUEBRANTABLE
A34: MARIA ELENA ROMERO | B34: 13 | C34: KRISCIA | D34: NP | E34: FUERA DE LIMA
A35: PATRICIA RIOS | B35: 13 | C35: KRISCIA | D35: NP
A36: LIZ CAROL TRUJILLO MALLQUI | B36: 11 | C36: JOYCE | D36: OK | E36: ENTRENARSE EN RELACION | H36: OK
A37: FLOR DE CANTUTA TELLO SARMIENTO | B37: 14 | C37: GARETH | D37: NP
A38: JESSICA CONGA HUARCAYA | B38: 14 | C38: JOYCE | D38: XC
A39: ALLYZON LEON SUAREZ | B39: 12 | C39: KRISCIA | D39: OK | E39: SER RELACION, MAS ESCUCHA. - Confirma Joyce | H39: OK
A40: SONIA POLANCO CABEZA | B40: 14 | C40: JOYCE | D40: SIG | E40: ALIADO E26
...

Sheet GRADUADOS 
A1: CREAR CUANTICO | B1: EQUIPO ORIGINAL | C1: E5 | D1: E6 | E1: E7 | F1: E8 | G1: E9 | H1: E10 | I1: E11 | J1: E12 | K1: E13 | L1: E14 | M1: E15 | N1: E16 | O1: E17 | P1: E18 | Q1: E19 | R1: E20 | S1: E21 | T1: E22 | U1: E23 | V1: E24 | W1: E25 | X1: E26 | Y1: E27 | Z1: E28
A2: CARLOS RAMIREZ | B2: 4 | C2: - | D2: - | E2: - | F2: M | G2: - | H2: - | I2: - | J2: - | K2: - | L2: - | M2: - | N2: - | O2: -
A3: LUCY OSTOA | B3: 4 | C3: - | D3: - | E3: - | F3: M | G3: - | H3: - | I3: - | J3: - | K3: - | L3: A | M3: - | N3: - | O3: -
A4: LUSY DIAZ | B4: 4 | C4: - | D4: - | E4: - | F4: M | G4: - | H4: - | I4: - | J4: - | K4: - | L4: - | M4: - | N4: - | O4: -
A5: MANUEL VIVANCO | B5: 4 | C5: - | D5: - | E5: - | F5: C | G5: - | H5: - | I5: - | J5: Q | K5: Q | L5: Q | M5: Q | N5: Q | O5: Q | S5: Q | T5: Q | U5: Q
A6: NANCY HUALLIPE | B6: 4 | C6: - | D6: - | E6: - | F6: A | G6: M | H6: - | I6: - | J6: - | K6: - | L6: - | M6: - | N6: - | O6: -
A7: ROCIO DE LA CRUZ | B7: 4 | C7: - | D7: - | E7: - | F7: - | G7: Q | H7: Q | I7: Q | J7: - | K7: Q | L7: Q | M7: Q | N7: Q | O7: C
A8: SARITA RAMOS | B8: 4 | C8: - | D8: - | E8: - | F8: - | G8: - | H8: - | I8: - | J8: - | K8: M | L8: - | M8: - | N8: - | O8: -
A9: VIVIANA ELIZABETH ALCANTARA MAURTUA | B9: 4 | C9: - | D9: - | E9: - | F9: M | G9: - | H9: - | I9: - | J9: M | K9: - | L9: - | M9: - | N9: - | O9: - | P9: A | Q9: A
A10: CARMEN GRICELDA PEREZ CHINCHAY | B10: 5 | C10: - | D10: - | E10: - | F10: - | G10: M | H10: - | I10: - | J10: - | K10: - | L10: C | M10: - | N10: - | O10: - | W10: A
A11: HILDA UCHASARA | B11: 5 | C11: - | D11: - | E11: - | F11: A | G11: NI | H11: - | I11: - | J11: - | K11: - | L11: - | M11: - | N11: - | O11: -
A12: JOSE COELLO | B12: 5 | C12: C | D12: - | E12: - | G12: - | H12: - | I12: - | J12: NI | K12: - | L12: - | M12: - | N12: - | O12: -
A13: MARIA CELLI HUAYANCA DIAZ | B13: 5 | C13: - | D13: - | E13: - | F13: A | G13: - | H13: - | I13: - | J13: M | K13: - | L13: - | M13: - | N13: A | O13: -
A14: NATHALY CHUCO | B14: 5 | C14: - | D14: - | E14: - | G14: - | H14: - | I14: - | J14: - | K14: - | L14: - | M14: - | N14: - | O14: NI
A15: ANEL ORIHUELA | B15: 6 | C15: - | D15: C | E15: C | F15: - | G15: - | H15: - | I15: - | J15: - | K15: - | L15: - | M15: - | N15: - | O15: - | T15: A | U15: Q | V15: Q | W15: Q | X15: Q
A16: LEYLA KELLY PASQUEL ALFARO | B16: 6 | C16: - | D16: M | E16: M | F16: - | G16: - | H16: - | I16: C | J16: - | K16: - | L16: - | M16: Q | N16: Q | O16: Q | Q16: Q | R16: Q | S16: Q | T16: Q | U16: Q | V16: Q | W16: Q
A17: GARETH SAID RAMOS PEREZ | B17: 7 | C17: - | D17: - | E17: - | F17: - | G17: - | H17: - | I17: A | J17: A | L17: M | M17: - | N17: - | O17: - | P17: A | U17: M
A18: GREGORIA ALHUAY ROJAS | B18: 7 | C18: - | D18: - | E18: - | F18: - | G18: - | H18: - | I18: - | J18: - | K18: - | L18: M | M18: - | N18: - | O18: -
A19: HUMBERTO CARRASCO LLATAS | B19: 7 | C19: - | D19: - | E19: - | F19: - | G19: - | H19: - | I19: - | J19: - | K19: - | L19: - | M19: - | N19: - | O19: NI
A20: JHEN JEZMIN PONCE ESPINOZA | B20: 7 | C20: - | D20: - | E20: - | F20: - | G20: - | H20: - | I20: A | J20: A | K20: - | L20: - | M20: - | N20: - | O20: A | S20: A | W20: A
A21: JHONATAN DANIEL ALCÁNTARA MAURTUA | B21: 7 | C21: - | D21: - | E21: - | F21: - | G21: - | H21: - | I21: - | J21: - | K21: - | L21: - | M21: - | N21: - | O21: NI
A22: LUZ BLANCA VASQUEZ SALES | B22: 7 | C22: - | D22: - | E22: - | F22: - | G22: - | H22: - | I22: A | J22: A | K22: - | L22: - | M22: - | N22: - | O22: -
A23: MANUEL YAKIMA RIVERA TOYAMA | B23: 7 | C23: - | D23: - | E23: - | F23: - | G23: - | H23: - | I23: - | J23: M | K23: - | L23: - | M23: - | N23: M | O23: - | R23: Q | S23: Q | T23: Q | U23: Q | V23: Q
A24: MARCO ANTONIO VILLARREAL VALDIVIEZO | B24: 7 | C24: - | D24: - | E24: - | F24: - | G24: - | H24: - | I24: M | J24: - | K24: A | L24: - | M24: M | N24: - | O24: - | Q24: Q | W24: A
A25: ALEXANDER TORIBIO CURI AGUADO | B25: 8 | C25: - | D25: - | E25: - | F25: - | G25: - | H25: - | I25: - | J25: - | K25: - | L25: - | M25: - | N25: - | O25: NI
A26: ARIANA MERCEDES GUEVARA MELENDEZ | B26: 8 | C26: - | D26: - | E26: - | F26: - | G26: - | H26: - | I26: - | J26: - | K26: - | L26: - | M26: - | N26: - | O26: -
A27: ELVIS CUELLAR | B27: 8 | C27: - | D27: - | E27: - | F27: - | G27: - | H27: - | I27: - | J27: - | K27: - | L27: - | M27: - | N27: - | O27: - | P27: M
A28: JULIO MOSCOSO | B28: 8 | C28: - | D28: - | E28: - | F28: - | G28: - | H28: - | I28: - | J28: - | K28: - | L28: - | M28: - | N28: - | O28: -
A29: KATHERINE CHUCO VASQUEZ | B29: 8 | C29: - | D29: - | E29: - | F29: - | G29: - | H29: - | I29: - | J29: - | K29: - | L29: - | M29: - | N29: - | O29: NI
A30: KRISCIA LISZET RODAS QUISPE | B30: 8 | C30: - | D30: - | E30: - | F30: - | G30: - | H30: - | I30: - | J30: M | K30: - | L30: - | M30: - | N30: - | O30: -
A31: MARLLORY ULLOA USQUIANO | B31: 8 | C31: - | D31: - | E31: - | F31: - | G31: - | H31: - | I31: - | J31: - | K31: - | L31: - | M31: - | N31: - | O31: -
A32: ROBERTO CONDEZO | B32: 8 | C32: - | D32: - | E32: - | F32: M | G32: - | H32: - | I32: - | J32: C | K32: - | L32: - | M32: - | N32: - | O32: - | P32: A | Q32: Q | W32: A
A33: TONNY GUTIERREZ | B33: 8 | C33: - | D33: - | E33: - | F33: M | G33: - | H33: - | I33: - | J33: - | K33: - | L33: - | M33: - | N33: A | O33: - | P33: C
A34: GABY DEL PILAR DE LA PAZ MONTIVEROD | B34: 9 | C34: - | D34: - | E34: - | F34: - | G34: - | H34: - | I34: - | J34: - | K34: - | L34: A | M34: - | N34: A | O34: -
A35: JOEL ROBERTO CONDEZO RAMIREZ | B35: 9 | C35: - | D35: - | E35: - | F35: - | G35: - | H35: - | I35: - | J35: - | K35: - | L35: NI | M35: - | N35: - | O35: -
A36: NURY LUISA DEL CARMEN MARCA | B36: 9 | C36: - | D36: - | E36: - | F36: - | G36: - | H36: - | I36: - | J36: - | K36: - | L36: A | M36: - | N36: - | O36: NI
A37: ROSEMARY DE PAZ | B37: 9 | C37: - | D37: - | E37: - | F37: - | G37: C | H37: - | I37: - | J37: - | K37: - | L37: Q | M37: 0 | N37: Q | O37: Q
A38: SANDRA MARLENE LOPEZ CHAHUA | B38: 9 | C38: - | D38: - | E38: - | F38: - | G38: - | H38: - | I38: - | J38: - | K38: - | L38: M | M38: - | N38: - | O38: -
A39: DAYSI REQUEJO LINARES | B39: 10 | C39: - | D39: - | E39: - | F39: - | G39: - | H39: - | I39: - | J39: - | K39: - | L39: - | M39: M | N39: - | O39: -
A40: DIEGO AREVALO SILVA | B40: 10 | C40: - | D40: - | E40: - | F40: - | G40: - | H40: - | I40: - | J40: - | K40: NI | L40: - | M40: - | N40: - | O40: -
...

Sheet ALIADOS C1E27
A2: CREADOR CUANTICO | B2: EQUIPO | C2: RESPONSABLE | D2: ESTADO | E2: OBSERVACIONES | F2: QT | G2: reto1 | H2: Grounding | I2: video | J2: forms
A3: VIVIANA ELIZABETH ALCANTARA MAURTUA | B3: 4 | C3: DIANA
A4: CARMEN GRICELDA PEREZ CHINCHAY | B4: 5 | C4: JOYCE | D4: NP
A5: ELVIS CUELLAR | B5: 8 | C5: OTTY | D5: NI | E5: POR AHORA NO, QUIZÁ MÁS ADELANTE
A6: TONNY GUTIERREZ | B6: 8 | C6: OTTY | D6: NP | E6: MAS ADELANTE
A7: SANDRA MARLENE LOPEZ CHAHUA | B7: 9 | C7: JOYCE | D7: OK | E7: SER DISFRUTE Y EN TENERLO TODO
A8: YUSMELY DESIREE GARCIA LLOVERA | B8: 10 | C8: DIANA
A9: GERALDINE VANESSA SOTOMAYOR BAZAN | B9: 10 | C9: OTTY
A10: JOSÉ BLADIMER RAMOS SIQUEROS | B10: 10 | C10: OTTY | D10: SIG | E10: EQUIPO 28 - ENTRENARSE EN MOSTRARSE PARA COMUNICARSE ASERTIVAMENTE
A11: JEANNET LEON LEDESMA | B11: 10 | C11: DIANA | D11: NC
A12: JUANA MARIA FALCON ROJAS | B12: 10 | C12: DIANA | D12: NP | E12: INDICA ALREDEDOR DE JUNIO GESTIONAR TIEMPOS
A13: ALEXANDRA TAPULLIMA CORDOVA | B13: 11 | C13: JOYCE | D13: NP
A14: HERMÓGENES UNTIVEROA CISNEROS | B14: 11 | C14: DIANA | E14: POSIBILIDAD E27
A15: ANAMELVA QUIÑONES BELTRÁN | B15: 11 | C15: JOYCE | D15: XC
A16: MARIA CELLI HUAYANCA DIAZ | B16: 11 | C16: OTTY | D16: NO
A17: ELIZABETH MORALES CARCELEN | B17: 11 | C17: OTTY | D17: NP
A18: JANET DURAND YARASQUI | B18: 11 | C18: DIANA | D18: NC | E18: TRABAJO
A19: LUISA PÉREZ CHINCHAY | B19: 12 | C19: OTTY | D19: NP
A20: PAMELA MELISA MORALES VEGA | B20: 12 | C20: JOYCE | D20: NP | E20: TRABAJO
A21: JOHNNY EDUARDO HUÁNUCO ARELLANO | B21: 12 | C21: JOYCE | D21: NC | E21: LLAMAR 20H30
A22: FUEL DURAND HUAYNATE | B22: 12 | C22: OTTY | D22: NA
A23: SHIRLEY RIVERA HUAMAN | B23: 12 | C23: OTTY | D23: NI
A24: ANGELLA BOLLET | B24: 13 | C24: JOYCE | D24: OK | E24: ENTRENARSE EN MANERAS
A25: RAQUEL RIVEROS RAMOS | B25: 13 | C25: JOYCE | D25: NP
A26: PATRICIA RIOS | B26: 13 | C26: DIANA
A27: MARÍA JESÚS CARRASCO LLATAS | B27: 13 | C27: OTTY | D27: NP
A28: MARIA VERONICA JIMENEZ VASQUEZ | B28: 13 | C28: JOYCE | D28: OK | E28: SER SU PALABRA
A29: MARIA ELENA ROMERO | B29: 13 | C29: OTTY | D29: NP
A30: JEAN CARLOS RIOS | B30: 13 | C30: DIANA | D30: NC
A31: PILAR DE LA CRUZ | B31: 13 | C31: DIANA | D31: NC | E31: Confirma Lunes - Llama Joyce
A32: YANINA ESTEFANIA MEJIA ROMERO | B32: 13 | C32: DIANA | D32: NC
A33: JESSICA CONGA HUARCAYA | B33: 14 | C33: OTTY
A34: ROXANA FLORENTINA BORJAS ORMEÑO | B34: 14 | C34: DIANA | E34: COMPROMISO INQUEBRANTABLE
A35: SONIA POLANCO CABEZA | B35: 14 | C35: OTTY | E35: ALIADO E26
A36: FLOR DE CANTUTA TELLO SARMIENTO | B36: 14 | C36: JOYCE | D36: NC
A37: RONY LANDEO | B37: 14 | C37: DIANA | D37: NC
A38: HELAR MUGURUZA | B38: 14 | C38: JOYCE | D38: OK
A39: ZELMY ALCANTARA | B39: 15 | C39: DIANA
A40: MARIBEL ROBERTA ESPAÑA ZAMBRANO | B40: 15 | C40: JOYCE | D40: NI
A41: ANTONY LEO ALTAMIRANO LLACCHUAS | B41: 15 | C41: OTTY | E41: LLAMARLOS
...

Sheet ALIADOS C2E26
A2: CREADOR CUANTICO | B2: EQUIPO | C2: ESTADO | D2: OBSERVACIONES | E2: reto1 | F2: Grounding | G2: video | H2: forms
A3: ANITA ESPERANZA FLORES TIPISMANA | B3: 19 | C3: OK | D3: CONFIRMA CAPI
A4: BRIAN STEVE SANGAY SALVATIERRA | B4: 22 | C4: OK | D4: SER LIDER - CONFIRMA JOYCE
A5: BRYAN RODNEY LÓPEZ | B5: 14 | C5: OK
A6: CAMILA ALEGRIA VERASTEGUI DURAN | B6: 19 | C6: OK | D6: NO LO TIENE CLARO -
A7: DARNER ISZAT DIAZ ZAPANA | B7: 18 | C7: OK | D7: RELACION - Confirma Joyce LLAMARLOS
A8: FABIO ALESSANDRO CANQUY LLOYD | B8: 19 | C8: OK | D8: SER PARTICIPACION TOTAL
A9: GREZIA MARÍA JOLLY VERA | B9: 15 | C9: OK
A10: JOLBER VARGAS ENRIQUEZ | B10: 22 | C10: OK | D10: ENTRENARSE EN SER ESCUCHA - FILTROS
A11: JOSE GUILLERMO CURI SALVADOR | B11: 17 | C11: OK | D11: SER ENTRENADOR
A12: KARIN PORTOCARRERO PEREA | B12: 22 | C12: NO | D12: CONFIRMO CAPITAN - POR CONFIRMAR
A13: LIZ CAROL TRUJILLO MALLQUI | B13: 11 | C13: NO
A14: LUZ ELVIRA RAMiREZ | B14: 20 | C14: NO
A15: MARIA OLARTE BARRIENTOS | B15: 22 | C15: OK | D15: SER LIDER Y COMPROMETIDA CON LA SER INSPIRACIÓN
A16: PAUL GAMARRA | B16: LQ | C16: OK | D16: SIGUIENTE E26
A17: PIERO ALESSANDRO PORTAL PASQUEL | B17: 14 | C17: OK
A18: RHANIA SHADEN UNTIVEROS REQUEJO | B18: 14 | C18: NO | D18: CONFIRMA CAPI
A28: Confirmados | C28: =+COUNTIF(C3:C26,"OK") -> 12

Sheet ALIADOS C2 E25
A1: CAPITAN | B1: MANUEL YAKIMA RIVERA
A2: CREADOR CUANTICO | B2: EQUIPO | C2: RESPONSABLE | D2: ESTADO | E2: OBSERVACIONES | F2: QT | G2: reto1 | H2: Grounding | I2: video | J2: forms
A3: CARMEN PÉREZ PÉREZ | B3: 5 | C3: KRISCIA | D3: NO | E3: SER LIDER EN ALTO RENDIMIENTO | H3: OK
A4: JHEN PONCE | B4: 7 | C4: GARETH | D4: OK | E4: MANAGER | H4: OK
A5: MARCO ANTONIO VILLARREAL VALDIVIEZO | B5: 7 | C5: JOYCE | D5: OK | E5: MANAGER | H5: OK
A6: MANUEL YAKIMA RIVERA TOYAMA | B6: 7 | C6: CAPITAN | D6: OK | E6: CAPITAN
A7: ROBERTO CONDEZO | B7: 8 | C7: JOYCE | D7: NO | E7: SER COMPROMISO INQUEBRANTABLE | H7: OK
A8: DIEGO HECTOR BARBIERI GALECIO | B8: 11 | C8: KRISCIA | D8: NO | E8: SER LIDER EN ALTO RENDIMIENTO, CONECTAR | H8: OK
A9: LIZ CAROL TRUJILLO MALLQUI | B9: 11 | C9: JOYCE | D9: OK | H9: OK
A10: ALLYZON LEON SUAREZ | B10: 12 | C10: KRISCIA | D10: NO | E10: SER RELACION, MAS ESCUCHA. - Confirma Joyce | H10: OK
A11: BRITNEY SAFIRO OLENKA DELGADO QUIÑONES | B11: 13 | C11: KRISCIA | D11: NO | E11: CONFIRMA JOYCE - SER Líder y disciplinada en profesión | H11: OK
A12: NORA ANAYA ESPINOZA | B12: 14 | C12: JOYCE | D12: NO | E12: Confirmo con Kriscia -llamar | H12: OK
A13: LUZ MABEL CHIPANA VEGA | B13: 14 | C13: KRISCIA | D13: NO | E13: HABITAR EN SU CONTRATO: LIDER PODEROSA AUTENTICA Y CREADORA | H13: OK
A14: LIMBER ELOY QUISPE | B14: 14 | C14: JOYCE | D14: OK
A15: HELAR MUGURUZA | B15: 14 | C15: LINID | D15: OK | E15: MANAGER | H15: OK
A16: JOEL JULIO ANTAURCO PEREZ | B16: 15 | C16: JOYCE | D16: NO | H16: OK | I16: =104-I15 -> 104
A17: LUCAS ALBERTO SANCHEZ SILVA | B17: 15 | C17: JOYCE | D17: NO | E17: SER LIDER | H17: OK
A18: HECTOR ENRIQUE CANQUI VALLADARES | B18: 15 | C18: KRISCIA | D18: NO | E18: SER SU PALABRA | H18: OK
A19: ERIKA LIZETH NORENA DURAND | B19: 17 | C19: JOYCE | D19: NO | E19: SER LIDER EN ALTO RENDIMIENTO | H19: OK
A20: NADIA ZEGARRA TOLENTINO | B20: 18 | C20: JOYCE | D20: NO | E20: SER ARRIESGADA | H20: OK
A21: CAMILA VERASTEGUI | B21: 19 | C21: GARETH | D21: NO | E21: CONFIRMA YAKIMA / Abrir su consultoria | H21: OK
A22: ANITA FLORES TIPISMANA | B22: 19 | C22: KRISCIA | D22: NO | E22: SER FUENTE Y RELACIONS | H22: OK
A23: FABIO ALESSANDRO CANQUY LLOYD | B23: 19 | C23: JOYCE | D23: OK | H23: OK
A24: FELIPE ALEJANDRO MALLQUI TRUJILLO | B24: 20 | C24: JOYCE | D24: OK | E24: DESERTOR | H24: OK
A25: HIPOLITA SaNCHEZ MEDINA | B25: 20 | C25: JOYCE | D25: OK | E25: MANAGER | H25: OK
A26: RICHARD PILCO CALIZAYA | B26: 20 | C26: JOYCE | D26: OK | H26: OK
A27: LEONARDO QUISPE TRUJILLO | B27: 20 | C27: JOYCE | D27: OK | H27: OK
A28: CAROLINA VICTORIA MANRIQUE HUARANCA | B28: 20 | C28: JOYCE | D28: OK | H28: OK
A29: JAVIER LEVANO MAGALLANES | B29: 20 | C29: LINID | D29: OK | H29: OK
A30: ROXANA MURILLO BONETT | B30: 21 | C30: JOYCE | D30: NO | H30: OK
A31: PAULINA PALOMINO RAMOS | B31: 21 | C31: LINID | D31: NO | H31: OK
A32: ALEJANDRINA PATRICIA TIPISMANA PASACHE | B32: 21 | C32: JOSE | D32: NO | H32: OK
A33: PERCY ANTONIO MURO GAYOSO | B33: 21 | C33: JOSE | D33: NO | E33: VIAJAR A AREQUIPA CON SUN LINDA ESPOSA | H33: OK
A34: YISSEL HUAMaN ALVAREZ | B34: 21 | C34: JOYCE | D34: NO | E34: COMPROMISO INQUEBRANTABLE | H34: OK
A35: MARiA ELENA ALVINO LoPEZ | B35: 21 | C35: KRISCIA | D35: OK | H35: OK
A36: JUAN ALVARO RAMIREZ HUALPA | B36: 21 | C36: GARETH | D36: OK | H36: OK
A37: DAVID JESUS RODRIGUEZ LA RIVA | B37: 21 | C37: JOYCE | D37: OK | E37: MANAGER | H37: OK
A38: EVER DAVID CARDENAS TELLO | B38: 21 | C38: LINID | D38: OK | H38: OK
A39: TANIA AURORA SaNCHEZ CASTRO | B39: 21 | C39: KRISCIA | D39: OK | H39: OK
A40: CÉSAR AUGUSTO NIEBUHR PRADO | B40: INGENIA | C40: JOSE | D40: OK | H40: OK
...

Sheet ALIADOS C1 E21
A1: CAPITAN | B1: CAMILA LEON
A2: CREADOR CUANTICO | B2: EQUIPO | C2: RESPONSABLE | D2: ESTADO | E2: OBSERVACIONES | F2: QT | G2: STATUS
A3: ROCIO DE LA CRUZ HUAYTALLA | B3: 4 | C3: KRISCIA | D3: NP | E3: (corta llamada)
A4: MANUEL YAKIMA RIVERA TOYAMA | B4: 7 | C4: KRISCIA | D4: NP | E4: QT
A5: MARLLORY ULLOA USQUIANO | B5: 8 | C5: KRISCIA | D5: NC
A6: ARIANA MERCEDES GUEVARA MELENDEZ | B6: 8 | C6: DIANA | D6: NP
A7: ARISKELA MONTANO MIRANDA | B7: 17 | C7: DIANA | D7: OK | E7: ENTRENARSE COMPROMISO - MANAGER
A8: BRITNEY SAFIRO OLENKA DELGADO QUINONES | B8: 13 | C8: KRISCIA | D8: NO
A9: JEANNET LEON LEDESMA | B9: 10 | C9: KRISCIA | D9: NP
A10: JUANA MARIA FALCON ROJAS | B10: 10 | C10: KRISCIA | D10: NP | E10: CAPITANA DE SERVICIO GRADUACION E18
A11: CARLOS ALBERTO CASTILLO TIPISMANA | B11: 16 | C11: DIANA | D11: NO
A12: VANESSA SAAVEDRA ORBE | B12: 11 | C12: PAMELA | D12: NP | E12: FUERA DE LIMA
A13: JANET DURAND YARASQUI | B13: 11 | C13: PAMELA | D13: NP | E13: ESTA TRABAJANDO EN LA SELVA NO TIENE SALIDA
A14: CRISTINA CUBA RIOS | B14: 11 | C14: DIANA | D14: NP | E14: Temas laborales
A15: HERMÓGENES UNTIVEROA CISNEROS | B15: 11 | C15: DIANA | D15: NP | E15: TRABAJO
A16: ANAMELVA QUINONES BELTRAN | B16: 11 | C16: PAMELA | D16: NP
A17: XIOMARA NICOLE QUIJANDRIA MEZA | B17: 12 | C17: KRISCIA | D17: NP | E17: CLASES
A18: JOHNNY EDUARDO HUÁNUCO ARELLANO | B18: 12 | C18: PAMELA | D18: NP | E18: POR AHORA NO PODRA PARTICIPAR
A19: JUANA ZARELA RODRIGUEZ GUERRERO | B19: 12 | C19: PAMELA | D19: NP | E19: INICIO CLASES DE BIOQUIMIVA Y FARMACIA
A20: CARMEN JOSELINA VALENCIA GUZMAN | B20: 12 | C20: PAMELA | D20: NP | E20: POR AHORA NO VENDRA A LIMA
A21: SHIRLEY RIVERA HUAMAN | B21: 12 | C21: DIANA | D21: rep | E21: ENTRENARSE PARA TENER RESULTADO - MANAGER
A22: CHARO YANETH APONTE PEREZ | B22: 17 | C22: PAMELA | D22: OK | E22: CONFIRMÓ CAMILA - Entrenarse en ser autentica
A23: FUEL DURAND HUAYNATE | B23: 12 | C23: KRISCIA | D23: NP
A24: D'YANIRA ALLYZON LEON SUAREZ | B24: 12 | C24: DIANA | D24: OK
A25: PAMELA MELISA MORALES VEGA | B25: 12 | C25: DIANA | D25: NC
A26: LIANA ELSA CASTRO PIETRO GONZALES | B26: 13 | C26: KRISCIA | D26: NP
A27: SADITH KRY LÓPEZ HERRERA | B27: 13 | C27: PAMELA | D27: NC
A28: PATRICIA RIOS ROSSELL | B28: 13 | C28: PAMELA | D28: NP | E28: POR SALUD
A29: JUDY DIANA ARQUISE ESPINOZA | B29: 13 | C29: KRISCIA | D29: NP
A30: LIBBY FIORELA HUAYTALLA SANCHEZ | B30: 13 | C30: GARETH | D30: NC
A31: YANINA ESTEFANIA MEJIA ROMERO | B31: 13 | C31: KRISCIA | D31: NC
A32: MARÍA JESÚS CARRASCO LLATAS | B32: 13 | C32: GARETH | D32: NP | E32: COMPROMISO FAMILIAR
A33: EUFEMIA ISABEL CORREA OLAYA | B33: 12 | C33: DIANA | D33: OK | E33: ENTRENARSE EN COMPROMISO
A34: JEAN CARLOS RIOS ZEA | B34: 13 | C34: PAMELA | D34: NP | E34: QUE SE TOMARA UN TIEMPO FUERA DEL ENTRENAMIENTO
A35: GABRIELA NAUPARI VASQUEZ | B35: 17 | C35: KRISCIA | D35: OK | E35: SER SU PALABRA - AMOROSA (RELACION HERMANOS)
A36: REYNA JARAMILLO | B36: 14 | C36: KRISCIA | D36: NP
A37: FLOR DE CANTUTA TELLO SARMIENTO | B37: 14 | C37: KRISCIA | D37: NP | E37: FUERA DE LIMA
A38: NORA ANAYA ESPINOZA | B38: 14 | C38: KRISCIA | D38: NP | E38: FUERA DE LIMA
A39: LIMBER ELOY QUISPE | B39: 14 | C39: KRISCIA | D39: NC | E39: E21
A40: SONIA POLANCO CABEZA | B40: 14 | C40: KRISCIA | D40: NP | E40: TRABAJO
...

Sheet ALIADOS C1 E24
A1: CAPITAN
A2: CREADOR CUANTICO | B2: EQUIPO | C2: RESPONSABLE | D2: ESTADO | E2: OBSERVACIONES | F2: QT | G2: reto1 | H2: Grounding
A3: LUIS HERNANDEZ | B3: 9 | C3: JOYCE | D3: OK | E3: CONFIRMÓ ISABEL- Entrenar en gratitud con todo | G3: ok | H3: ok
A4: ALEXANDRA TAPULLIMA CORDOVA | B4: 11 | C4: JOYCE | D4: NC
A5: ALLYZON LEON SUAREZ | B5: 12 | C5: KRISCIA | D5: NP | E5: CONFIRMÓ ISABEL - Confirma el jueves / INTERVENCION QUIRURGICA | H5: ok
A6: DIANA MOSCOSO | B6: 12 | C6: KRISCIA | D6: OK | E6: SER AUTENTICA - QUE LAS PERSONAS SE ENAMOREN DE ELLOS MISMOS Y SUS SUEÑOS | G6: ok | H6: ok
A7: ANAMELVA QUIÑONES BELTRÁN | B7: 11 | C7: KRISCIA | D7: NO | E7: CONFIRMÓ ISABEL - Se quiere entrenar en divertirse sin mucho analisis | G7: ok | H7: ok
A8: HELAR MUGURUZA | B8: 12 | C8: KRISCIA | D8: OK | E8: CONFIRMÓ ISABEL - PARTICIPAR EN GRATITUD (MUDANZA FAMILIA A LIMA) | G8: ok | H8: ok
A9: ANGELLA BOLLET | B9: 13 | C9: JOYCE | D9: NP | E9: CONFIRMÓ ISABEL - Alterar mis relaciones a que sean extraordinarias, requiero conectar con las personas. (Llamar a Linid)
A10: ANGELLO GERONIMO PANTA MORALES | B10: 17 | C10: GARETH | D10: NP | E10: SALUD
A11: ANITA FLORES TIPISMANA | B11: 19 | C11: KRISCIA | D11: NP | E11: VIAJE ENERO HIJA - BRASIL
A12: ANTHONY WILLIAMS VARGAS ZAMBRANO | B12: 19 | C12: GARETH | D12: NC
A13: BRITNEY SAFIRO OLENKA DELGADO QUIÑONES | B13: 13 | C13: KRISCIA | D13: NP
A14: CAMILA VERASTEGUI | B14: 19 | C14: GARETH | D14: NP
A15: CARMEN PÉREZ PÉREZ | B15: 14 | C15: KRISCIA | E15: PRUEBA QT
A16: RAUL CHAVEZ INCHE | B16: 13 | C16: JOYCE | D16: OK | E16: CONFIRMÓ ISABEL - Entrenar en tenerlo todo y ser entrenador de potencial humano | G16: ok | H16: ok
A17: CLAUDIA GALVEZ | B17: 17 | C17: GARETH | D17: NR | E17: CONFIRMÓ ISABEL / | G17: ok
A18: CONSUELO LAURA BALTAZAR ROSALES | B18: 19 | C18: JOYCE | D18: NC | E18: NO CONTESTA LLAMADA
A19: CRISTIAN ARONE | B19: 15 | C19: JOYCE | D19: NO | E19: CONFIRMÓ ISABEL
A20: CRISTIAN SANCHEZ TRINIDAD | B20: 20 | C20: GARETH | D20: NC | E20: mensaje | H20: ok
A21: DARNER ISZAT DIAZ ZAPANA | B21: 18 | C21: GARETH | D21: NC
A22: DIANA CAROLINA CCOSCCO GUTIéRREZ | B22: 18 | C22: GARETH | D22: NP
A23: RHANIA UNTIVEROS | B23: 14 | C23: GARETH | D23: OK | E23: CONFIRMÓ ISABEL / Ser una mujer abundante | G23: ok | H23: ok
A24: DIANA REYNA RAMOS OROSCO | B24: 19 | C24: GARETH | D24: SIG | E24: E25 - MANAGER
A25: DIEGO HECTOR BARBIERI GALECIO | B25: 11 | C25: KRISCIA | D25: XC | E25: LIDERAZGO
A26: ROCIO AYVAR VEGA | B26: 14 | C26: GARETH | D26: OK | E26: SER IMPACTO | G26: ok | H26: ok
A27: ELIZABETH MORALES | B27: 15 | C27: JOYCE | D27: NO | E27: CONFIRMÓ ISABEL - | G27: no | H27: ok
A28: ELVIS CUELLAR | B28: 8 | C28: JOYCE | D28: NP | E28: MESA DE ENROLLAMIENTO
A29: ERIKA LIZETH NORENA DURAND | B29: 17 | C29: JOYCE | D29: NO | E29: CONFIRMÓ ISABEL - Entrenarse en dejar de procastinar y tener mas liderazgo en mis proyectos | G29: ok | H29: ok
A30: FABIO ALESSANDRO CANQUY LLOYD | B30: 19 | C30: JOYCE | D30: NC | E30: VOLVER A LLAMAR
A31: FABRICIO JAIR, CARDENAS ALTA MIRANO | B31: 19 | C31: JOYCE | D31: NP | E31: E26
A32: FELIPE ALEJANDRO MALLQUI TRUJILLO | B32: 20 | C32: JOYCE | D32: NO | E32: Ser fuente de inspiración para otros como aliado desde la evidencia que ha creado.
A33: FERNANDO ABEL LOPEZ LOPEZ | B33: 18 | C33: GARETH | D33: NO | E33: MANAGER E23
A34: ROXANA FLORENTINA BORJAS ORMEÑO | B34: 14 | C34: KRISCIA | D34: OK | E34: SER SU PALABRA | G34: ok | H34: ok
A35: FIORELA GUTIERREZ SAAVEDRA | B35: 19 | C35: GARETH | D35: NC
A36: FLOR DE CANTUTA TELLO SARMIENTO | B36: 14 | C36: GARETH | D36: SIG | E36: E25 | H36: ok
A37: FUEL DURAND HUAYNATE | B37: 12 | C37: GARETH | D37: NP
A38: GABRIELA KATERINNE JARA NARCISO | B38: 18 | C38: KRISCIA | D38: NC
A39: GABRIELA ÑAUPARI | B39: 15 | C39: KRISCIA | D39: OK | E39: CONFIRMÓ ISABEL - PARARSE EN COMPROMISO Y EN CREAR RELACIONES EXTRAORDINARIAS | G39: ok | H39: ok
A40: GERALDINE STEPHANIE OTRERA CACÑAHUARAY | B40: 15 | C40: GARETH | D40: OK | E40: CONFIRMÓ ISABEL / MANAGER / generar 3k de ganancia en venta de accesorios | G40: ok | H40: ok
...

Sheet ALIADOS C1 E23
A1: CAPITAN
A2: CREADOR CUANTICO | B2: EQUIPO | C2: RESPONSABLE | D2: ESTADO | E2: OBSERVACIONES | F2: QT | G2: reto1 | H2: Grounding
A3: ROCIO DE LA CRUZ HUAYTALLA | B3: 4 | C3: GARETH | D3: NC | E3: (corta llamada)
A4: ELVIS CUELLAR | B4: 8 | C4: GARETH | D4: NC
A5: LUZ MABEL CHIPANA VEGA | B5: 8 | C5: GARETH | H5: ok
A6: TONNY GUTIERREZ | B6: 8 | C6: KRISCIA | D6: NP | E6: TRABAJO
A7: JEANNET LEON LEDESMA | B7: 10 | C7: JOYCE | D7: NP | E7: E24
A8: JUANA MARIA FALCON ROJAS | B8: 10 | C8: GARETH | D8: NP | E8: TRABAJO
A9: YUSMELY DESIREE GARCIA LLOVERA | B9: 10 | C9: JOYCE | E9: TRABAJO
A10: JOSÉ BLADIMER RAMOS SIQUEROS | B10: 10 | C10: GARETH | E10: MANAGER | H10: ok
A11: MARIA CELLI HUAYANCA DIAZ | B11: 11 | C11: GARETH
A12: HERMÓGENES UNTIVEROA CISNEROS | B12: 11 | C12: JOYCE | E12: apagado
A13: JANET DURAND YARASQUI | B13: 11 | C13: KRISCIA | D13: NP | E13: TRABAJO FUERA DE LIMA
A14: JUANA ZARELA RODRIGUEZ GUERRERO | B14: 12 | C14: KRISCIA | D14: NP
A15: PAMELA MELISA MORALES VEGA | B15: 12 | C15: JOYCE | D15: NP | E15: APOYARA EN MESA VIERNES Y SABADO CAP1
A16: CARMEN JOSELINA VALENCIA GUZMAN | B16: 12 | C16: JOYCE | D16: NP
A17: SHIRLEY RIVERA HUAMAN | B17: 12 | C17: KRISCIA | D17: NP | E17: temas de salud
A18: JOHNNY EDUARDO HUÁNUCO ARELLANO | B18: 12 | C18: JOYCE | E18: XC
A19: XIOMARA NICOLE QUIJANDRIA MEZA | B19: 12 | C19: GARETH | D19: NC | E19: CLASES
A20: FUEL DURAND HUAYNATE | B20: 12 | C20: KRISCIA | D20: NP | E20: VIAJE
A21: LUISA PÉREZ CHINCHAY | B21: 12 | C21: GARETH | E21: MANAGER | H21: ok
A22: YANINA ESTEFANIA MEJIA ROMERO | B22: 13 | C22: KRISCIA | D22: NC
A23: JIMENA PLASENCIA | B23: 13 | C23: GARETH
A24: MARIA ELENA ROMERO | B24: 13 | C24: KRISCIA | D24: NP | E24: FUERA DE LIMA / SALUD FAMILIAR
A25: PILAR DE LA CRUZ | B25: 13 | C25: KRISCIA | D25: NP | E25: MESA DOMINGO
A26: RAQUEL RIVEROS RAMOS | B26: 13 | C26: JOYCE | D26: OK | E26: E23 | H26: ok
A27: LIBBY FIORELA HUAYTALLA SANCHEZ | B27: 13 | C27: KRISCIA | D27: NP | E27: A partir de Enero
A28: MARÍA JESÚS CARRASCO LLATAS | B28: 13 | C28: GARETH | D28: NC | E28: cuelga
B29: 13 | C29: JOYCE | E29: VIAJE COLOMBIA FI
A30: RAUL CAHVEZ INCHE | B30: 13 | C30: GARETH | D30: NP
A31: BRITNEY SAFIRO OLENKA DELGADO QUIÑONES | B31: 13 | C31: GARETH | H31: ok
A32: JEAN CARLOS RIOS | B32: 13 | C32: KRISCIA
A33: ROCIO AYVAR VEGA | B33: 14 | C33: JOYCE | H33: ok
A34: JESSICA CONGA HUARCAYA | B34: 14 | C34: GARETH | D34: NC
A35: CARMEN PÉREZ PÉREZ | B35: 14 | C35: GARETH | D35: NP | E35: VIAJA A CONVENCION POR SU EMPRENDIMIENTO
A36: FLOR DE CANTUTA TELLO SARMIENTO | B36: 14 | C36: KRISCIA | D36: NP | E36: FUERA DE LIMA
A37: NORA ANAYA ESPINOZA | B37: 14 | C37: KRISCIA | D37: NP | E37: FUERA DE LIMA
A38: RONY LANDEO | B38: 14 | C38: JOYCE | D38: NP | E38: Para el siguiente - quiere ser entrenador E24
A39: PILAR CUADRAO CARRUITERO | B39: 14 | C39: GARETH | D39: NP | E39: trabajo, no la escucho queriendo participar
A40: SONIA POLANCO CABEZA | B40: 14 | C40: GARETH | D40: NC
...

Sheet ALIADOS C1 E20
A1: CAPITAN | B1: Joselyn Alexandra Tapullima Cordova
A2: CREADOR CUANTICO | B2: EQUIPO | C2: RESPONSABLE | D2: ESTADO | E2: OBSERVACIONES | F2: QT | G2: STATUS
A3: ALEXANDRA TAPULLIMA CORDOVA | B3: 11 | C3: LINID | D3: OK
A4: ARIANA MERCEDES GUEVARA MELENDEZ | B4: 8 | C4: LINID
A5: AVRIL ESTEPHANIA GARCIA MEDINA | B5: 16 | C5: CAPITANA | D5: OK
A6: BETTY YANETH QUIÑONES BELTRAN | B6: 13 | C6: LINID | D6: OK
A7: BLANCA LUZ CHACHAYMA MARCOS | B7: 16 | C7: CAPITANA | D7: OK
A8: BRYAN RODNEY LÓPEZ | B8: 14 | C8: PAMELA | D8: SIG | E8: CONFIRMÓ A JUANMA
A9: CARLOS HUMBERTO MENDOZA PICOAGA | B9: 16 | C9: CAPITANA | D9: SIG | E9: SE LE CRUZA CON VIAJES
A10: CARMEN JOSELINA VALENCIA GUZMAN | B10: 12 | C10: LINID | E10: Estudio- Cap 18
A11: CARMEN PÉREZ PÉREZ | B11: 14 | C11: PAMELA | D11: NC
A12: CRISTINA CUBA RIOS | B12: 11 | C12: LINID | D12: NO
A13: DAINA AYELEN MARTINEZ FLORES | B13: 16 | C13: KRISCIA | D13: NC
A14: DIEGO HECTOR BARBIERI GALECIO | B14: 11 | C14: CAPITANA | D14: OK
A15: ELIZABETH MORALES CARCELEN | B15: 11 | C15: CAPITANA | D15: OK
A16: DORA LUISA BALTODANO SANDOVAL | B16: 14 | C16: KRISCIA | D16: NP | E16: TEMAS LABORALES
A17: GIOVANA ELIZABETH PALOMINO MARCOS | B17: 16 | C17: CAPITANA | D17: OK
A18: JEAN NUÑEZ | B18: EXTERNO | C18: PAMELA | D18: OK
A19: JENNY BETSABET ESPINAL BALTAZAR | B19: 16 | C19: CAPITANA | D19: OK
A20: FLOR DE CANTUTA TELLO SARMIENTO | B20: 14 | C20: KRISCIA | D20: NP | E20: FUERA DE LIMA
A21: JIMENA MARIBEL PLASENCIA AGUILAR | B21: 16 | C21: KRISCIA | E21: SER COMPROMISO
A22: GERALDINE STEPHANIE OTRERA CACÑAHUARAY | B22: 15 | C22: PAMELA
A23: GIAN CARLO MINCHOLA VALDIVIA | B23: 14 | C23: PAMELA | D23: NC
A24: JOEL JULIO ANTAURCO PEREZ | B24: 15 | C24: CAPITANA
A25: JORGE EDUARDO CHALCO CCASA | B25: 16 | C25: JOSE | D25: OK
A26: GLADYS CONDE QUISPE | B26: 16 | C26: KRISCIA | D26: SIG | E26: CUSCO
A27: JOSE ALONSO GALVEZ LOPEZ | B27: 16 | C27: KRISCIA | E27: SER PALABRA, CREADOR
A28: HELAR MUGURUZA | B28: 14 | C28: PAMELA | D28: NC
A29: JUTSU EUGENIO JARAMILLO PINEDO | B29: 15 | C29: KRISCIA | E29: PODER
A30: JANET DURAND YARASQUI | B30: 11 | C30: PAMELA | D30: XC
A31: KATHERINE LILIBET QUISPE ARENAS | B31: 16 | C31: JOSE | D31: OK | E31: PARA QUE …
A32: JEANNET LEON LEDESMA | B32: 10 | C32: LINID
A33: KATIA MELVA DE PAZ FIGUEROA | B33: 16 | C33: KRISCIA | D33: OK | E33: SER ENERGIA
A34: JESSICA CONGA HUARCAYA | B34: 14 | C34: PAMELA | D34: NC
A35: JESSICA PILAR LOPEZ LOPEZ | B35: 16 | C35: JOSE | D35: SIG | E35: DUALIADAD ENTRE EL ENTRENAMIENTO EN ECU Y EL ENTRENAMIENTO COMO ALIADOS
A36: JESUS JULIO ANTAURCO PEREZ | B36: 14 | C36: PAMELA | D36: NP
A37: LUIS ALBERTO HERNÁNDEZ MENDOZA | B37: 11 | C37: CAPITANA | D37: OK
A38: LUZ MABEL CHIPANA VEGA | B38: 15 | C38: CAPITANA | D38: OK
A39: JOHAN JENRRY LOZANO PONCE | B39: 16 | C39: PAMELA
A40: JOHNNY EDUARDO HUÁNUCO ARELLANO | B40: 12 | C40: PAMELA | D40: NC
...

Sheet ALIADOS C1 E19
A1: CAPITAN
A2: CREADOR CUANTICO | B2: EQUIPO | C2: RESPONSABLE | D2: ESTADO | E2: OBSERVACIONES | F2: QT | G2: STATUS
A3: CARMEN PÉREZ PÉREZ | B3: 14 | C3: PAMELA | D3: NC
A4: GIAN CARLO MINCHOLA VALDIVIA | B4: 14 | C4: PAMELA | D4: NC
A5: HELAR MUGURUZA | B5: 14 | C5: PAMELA | D5: NC
A6: JESSICA CONGA HUARCAYA | B6: 14 | C6: PAMELA | D6: NC
A7: JOHNNY EDUARDO HUÁNUCO ARELLANO | B7: 12 | C7: PAMELA | D7: NC
A8: JUDY DIANA ARQUISE ESPINOZA | B8: 13 | C8: LINID | D8: NC
A9: LIBBY FIORELA HUAYTALLA SANCHEZ | B9: 13 | C9: LINID | D9: NC
A10: LIMBER ELOY QUISPE | B10: 14 | C10: KRISCIA | D10: NC
A11: PILAR CUADRAO CARRUITERO | B11: 14 | C11: PAMELA | D11: NC
A12: RONY LANDEO | B12: 14 | C12: PAMELA | D12: NC
A13: SADITH KRY LÓPEZ HERRERA | B13: 13 | C13: PAMELA | D13: NC
A14: CRISTINA CUBA RIOS | B14: 11 | C14: LINID | D14: NO
A15: FUEL DURAND HUAYNATE | B15: 12 | C15: LINID | D15: NO | E15: Viaje
A16: JUANA ZARELA RODRIGUEZ GUERRERO | B16: 12 | C16: LINID | D16: NO | E16: Clases - Cap 18
A17: JUTSU EUGENIO JARAMILLO PINEDO | B17: 15 | C17: KRISCIA | D17: NO
A18: LIANA ELSA CASTRO PIETRO GONZALES | B18: 13 | C18: KRISCIA | D18: NO
A19: YANINA ESTEFANIA MEJIA ROMERO | B19: 13 | C19: LINID | D19: NO
A20: JESUS JULIO ANTAURCO PEREZ | B20: 14 | C20: PAMELA | D20: NP
A21: PATRICIA RIOS ROSSELL | B21: 13 | C21: PAMELA | D21: NP | E21: CONFIRMÓ A JUANMA
A22: RHANIA SHADEN UNTIVEROS REQUEJO | B22: 14 | C22: PAMELA | D22: NP | E22: UNIVERSIDAD
A23: VANESSA SAAVEDRA ORBE | B23: 11 | C23: PAMELA | D23: NP | E23: RETOS LABORALES
A24: ANTONY LEO ALTAMIRANO LLACCHUAS | B24: 15 | C24: KRISCIA | D24: OK | E24: LIDERAZGO | F24: LEYLA
A25: CARLOS ALBERTO CASTILLO TIPISMANA | B25: 15 | C25: PAMELA | D25: OK | E25: CONFIRMÓ A JUANMA | F25: LEYLA
A26: FANNY SUSAN ROJAS GALINDO | B26: 15 | C26: PAMELA | D26: OK | F26: LEYLA
A27: JUAN MANUEL NAVARRO GRANDA | B27: 7 | C27: CAPITAN | D27: OK | F27: LEYLA
A28: LUIS HERNANDEZ MENDOZA | B28: 11 | C28: KRISCIA | D28: OK | E28: CONFIRMÓ A JUANMA | F28: LEYLA
A29: MARÍA ELENA ROMERO RAMIREZ | B29: 13 | C29: LINID | D29: OK | E29: CONFIRMÓ A JUANMA | F29: LEYLA
A30: PIERO PORTAL | B30: 14 | C30: KRISCIA | D30: OK | F30: LEYLA
A31: ANGELLA BOLLET GOMEZ | B31: 13 | C31: KRISCIA | D31: OK | E31: CONFIRMÓ A JUANMA | F31: LEYLA
A32: CAMILA LEON MORE | B32: 14 | C32: KRISCIA | D32: OK | E32: CONFIRMÓ A JUANMA | F32: MARCO
A33: DIEGO BARBIERI | B33: 11 | C33: KRISCIA | D33: OK | F33: MARCO
A34: HECTOR ENRIQUE CANQUI VALLADARES | B34: 15 | C34: KRISCIA | D34: OK | E34: CONFIRMÓ A JUANMA | F34: MARCO
A35: LUCAS ALBERTO SANCHEZ SILVA | B35: 15 | C35: PAMELA | D35: OK | E35: CONFIRMÓ A JUANMA | F35: MARCO
A36: MARIA CARRASCO LLATAS | B36: 13 | C36: KRISCIA | D36: OK | E36: CONFIRMÓ A JUANMA | F36: MARCO
A37: NANCY MALPARTIDA FLORES | B37: 15 | C37: KRISCIA | D37: OK | F37: MARCO
A38: ZELMY ALCANTARA GUERRERO | B38: 15 | C38: KRISCIA | D38: OK | E38: CONFIRMÓ A JUANMA | F38: MARCO
A39: BETTY YANETH QUIÑONES BELTRAN | B39: 13 | C39: PAMELA | D39: OK | E39: CONFIRMÓ A JUANMA | F39: ROBERTO
A40: CRISTIAN JONATHAN ARONE CHACHAYMA | B40: 15 | C40: PAMELA | D40: OK | E40: DICE WUE LE CONFIRMO A JUANMA EN VUELOS | F40: ROBERTO
...

Sheet APOYOS C2 E17
A1: APOYOS | B1: EQUIPO | C1: JUEVES 11 am a 230 pm | D1: VIERNES 8:30 am a 2 pm | E1: RESPONSABLE
A2: JOSÉ BLADIMER RAMOS SIQUEROS | B2: 10 | C2: NP | D2: NP | E2: PAMELA
A3: MILAGROS CASTAÑEDA ORBE | B3: 10 | C3: NP | D3: NP | E3: KRISCIA
A4: HERMÓGENES UNTIVEROA CISNEROS | B4: 11 | C4: NP | D4: NP | E4: KRISCIA
A5: JANET DURAND YARASQUI | B5: 11 | C5: NP | D5: NP | E5: PAMELA
A6: SEFORA NOEMI OÑATE GUZMAN | B6: 11 | C6: NP | D6: NP | E6: KRISCIA
A7: ELÍ AMERICO CALZADA ESPINOZA | B7: 12 | C7: NP | D7: NP | E7: KRISCIA
A8: GISELA MORALES VALLADARES | B8: 12 | C8: NP | D8: NP | E8: KRISCIA
A9: JOHNNY EDUARDO HUÁNUCO ARELLANO | B9: 12 | C9: NC | D9: NC | E9: PAMELA
A10: BETTY YANETH QUIÑONES BELTRAN | B10: 13 | C10: NC | D10: NC | E10: PAMELA
A11: HELVER ROLANDO LLANOS VÁSQUEZ | B11: 13 | C11: NC | D11: NC | E11: KRISCIA
A12: JOSE VALENCIA FERNANDEZ | B12: 13 | C12: NC | D12: NC | E12: KRISCIA
A13: JUDY DIANA ARQUISE ESPINOZA | B13: 13 | C13: NC | D13: NC | E13: PAMELA
... A48: FIDEL TANGO | B48: 16 | C48: NP | D48: OK | E48: PAMELA
A49: DENVER | C49: NP | D49: OK | E49: PAMELA
A50: JENNY ESPINEL | C50: OK | D50: NP | E50: PAMELA
A54: Confirmados | C54: =+COUNTIF(C2:C50,"ok") -> 3 | D54: =+COUNTIF(D2:D50,"ok") -> 4

Sheet ALIADOS C1 E18
A1: CAPITAN | B1: TONNY GUTIERREZ
A2: CREADOR CUANTICO | B2: EQUIPO | C2: RESPONSABLE | D2: ESTADO | E2: OBSERVACIONES | F2: QT | G2: STATUS
A3: VIVIANA ALCANTARA MAURTUA | B3: 4 | C3: KRISCIA | D3: OK | F3: ROSE | G3: =+A3 -> VIVIANA ALCANTARA MAURTUA | H3: =+CONCATENATE(G3," & ", G4) -> VIVIANA ALCANTARA MAURTUA & TONNY GUTIERREZ
A4: TONNY GUTIERREZ | B4: 8 | C4: KRISCIA | D4: CAPITAN | F4: LEYLA | G4: =+A4 -> TONNY GUTIERREZ
A5: ELVIS CUELLAR | B5: 8 | C5: PAMELA | D5: OK | F5: ROSE | G5: =+A5 -> ELVIS CUELLAR | H5: =+CONCATENATE(G5," & ", G6) -> ELVIS CUELLAR & MARIA VERONICA JIMENEZ VASQUEZ
A6: MARIA VERONICA JIMENEZ VASQUEZ | B6: 13 | C6: PAMELA | D6: OK | E6: SITUACIÓN PERSONAL | F6: JORGE | G6: =+A6 -> MARIA VERONICA JIMENEZ VASQUEZ
A7: JOSÉ BLADIMER RAMOS SIQUEROS | B7: 10 | C7: PAMELA | D7: OK | F7: LEYLA | G7: =+A7 -> JOSÉ BLADIMER RAMOS SIQUEROS | H7: =+CONCATENATE(G7," & ", G8) -> JOSÉ BLADIMER RAMOS SIQUEROS & ZARA CASTILLO LEON
A8: ZARA CASTILLO LEON | B8: 12 | C8: KRISCIA | D8: OK | F8: JORGE | G8: =+A8 -> ZARA CASTILLO LEON
A9: LIDIA TRUJILLO GUTIERREZ | B9: 12 | C9: KRISCIA | D9: OK | F9: LEYLA | G9: =+A9 -> LIDIA TRUJILLO GUTIERREZ | H9: =+CONCATENATE(G9," & ", G10) -> LIDIA TRUJILLO GUTIERREZ & ROBERTO CONDEZO
A10: ROBERTO CONDEZO | B10: 12 | C10: KRISCIA | D10: OK | F10: MANUEL | G10: =+A10 -> ROBERTO CONDEZO
A11: LUISA PEREZ CHINCHAY | B11: 12 | C11: KRISCIA | D11: OK | F11: MANUEL | G11: =+A11 -> LUISA PEREZ CHINCHAY | H11: =+CONCATENATE(G11," & ", G12) -> LUISA PEREZ CHINCHAY & RAQUEL RIVEROS RAMOS
A12: RAQUEL RIVEROS RAMOS | B12: 13 | C12: KRISCIA | D12: OK | F12: ROSE | G12: =+A12 -> RAQUEL RIVEROS RAMOS
A13: GARETH SAID RAMOS PÉREZ | B13: 14 | C13: KRISCIA | D13: OK | F13: JORGE | G13: =+A13 -> GARETH SAID RAMOS PÉREZ | H13: =+CONCATENATE(G13," & ", G14) -> GARETH SAID RAMOS PÉREZ & ROCIO AYVAR VEGA
A14: ROCIO AYVAR VEGA | B14: 14 | C14: KRISCIA | D14: OK | F14: LEYLA | G14: =+A14 -> ROCIO AYVAR VEGA
A15: PIERO ALESSANDRO PORTAL PASQUEL | B15: 14 | C15: PAMELA | D15: OK | F15: MANUEL | G15: =+A15 -> PIERO ALESSANDRO PORTAL PASQUEL | H15: =+CONCATENATE(G15," & ", G16," & ",G17) -> PIERO ALESSANDRO PORTAL PASQUEL & CRISTINA MARTINEZ & JOYCE MARIN
A16: CRISTINA MARTINEZ | B16: 2019 CP | C16: PAMELA | D16: OK | F16: MANUEL | G16: =+A16 -> CRISTINA MARTINEZ
A17: JOYCE MARIN | B17: ECUADOR | C17: LINID | D17: OK | F17: JORGE | G17: =+A17 -> JOYCE MARIN
A18: ELÍ AMERICO CALZADA ESPINOZA | B18: 12 | C18: KRISCIA | D18: NC
A19: JOSE VALENCIA FERNANDEZ | B19: 13 | C19: KRISCIA | D19: NC | E19: Mayo | G19: JORGE | H19: =+CONCATENATE(G19," & ", G20) -> JORGE & MANUEL
A20: LIMBER ELOY QUISPE | B20: 14 | C20: KRISCIA | D20: NC | G20: MANUEL
A21: DORA LUISA BALTODANO SANDOVAL | B21: 14 | C21: KRISCIA | D21: NC | G21: LEYLA | H21: =+CONCATENATE(G21," & ", G22) -> LEYLA & ROSE
A22: NATHALY CHUCO | B22: 5 | C22: PAMELA | D22: NC | G22: ROSE
A23: ALEXANDER TORIBIO CURI AGUADO | B23: 8 | C23: PAMELA | D23: NC
A24: JULIO MOSCOSO | B24: 8 | C24: PAMELA | D24: NC
A25: JOEL ROBERTO CONDEZO RAMIREZ | B25: 9 | C25: PAMELA | D25: NC
A26: YRMA CECILIA ALCA BARRA | B26: 12 | C26: PAMELA | D26: NC
A27: JUDY DIANA ARQUISE ESPINOZA | B27: 13 | C27: PAMELA | D27: NC
A28: LIBBY FIORELA HUAYTALLA SANCHEZ | B28: 13 | C28: PAMELA | D28: NC
A29: SADITH KRY LÓPEZ HERRERA | B29: 13 | C29: PAMELA | D29: NC
A30: RONY LANDEO | B30: 14 | C30: PAMELA | D30: NC
A31: GIAN CARLO MINCHOLA VALDIVIA | B31: 14 | C31: PAMELA | D31: NC
A32: HELAR MUGURUZA | B32: 14 | C32: PAMELA | D32: NC
A33: PILAR CUADRAO CARRUITERO | B33: 14 | C33: PAMELA | D33: NC
A34: CARMEN PÉREZ PÉREZ | B34: 14 | C34: PAMELA | D34: NC
... A36: JOHNNY EDUARDO HUÁNUCO ARELLANO | B36: 12 | C36: PAMELA | D36: NI
A37: BRYAN RODNEY LÓPEZ | B37: 14 | C37: PAMELA | D37: NI | E37: POR AHORA ELIJE NO ENTRENARSE
A38: HUMBERTO CARRASCO LLATAS | B38: 7 | C38: LINID | D38: NO
A39: CRISTINA CUBA RIOS | B39: 11 | C39: LINID | D39: NO
A40: FUEL DURAND HUAYNATE | B40: 12 | C40: LINID | D40: NO | E40: Viaje
A41: JUANA ZARELA RODRIGUEZ GUERRERO | B41: 12 | C41: LINID | D41: NO | E41: Clases - Cap 18
...

Sheet ALIADOS C1 E22
A1: CAPITAN | B1: ROS
A2: CREADOR CUANTICO | B2: EQUIPO | C2: RESPONSABLE | D2: ESTADO | E2: OBSERVACIONES | F2: QT | G2: reto1
A3: VANESSA SAAVEDRA ORBE | B3: 11 | C3: DIANA | D3: NI
A4: JUANA ZARELA RODRIGUEZ GUERRERO | B4: 12 | C4: DIANA | D4: NC
A5: SADITH KRY LÓPEZ HERRERA | B5: 13 | C5: DIANA | D5: NI | E5: ENFOCADA EN SUS PROYECTOS PERSONALES
A6: RONY LANDEO | B6: 14 | C6: DIANA | D6: SIG | E6: Para el siguiente - quiere ser entrenador E23
A7: GIAN CARLO MINCHOLA VALDIVIA | B7: 14 | C7: DIANA | D7: NI
A8: BRYAN RODNEY LÓPEZ | B8: 14 | C8: DIANA | D8: NI
A9: MARIBEL ROBERTA ESPAÑA ZAMBRANO | B9: 15 | C9: DIANA | D9: NC
A10: CARLOS HUMBERTO MENDOZA PICOAGA | B10: 16 | C10: DIANA | D10: NI
A11: JESSICA PILAR LOPEZ LOPEZ | B11: 16 | C11: DIANA | D11: NC | E11: ALIADA EQUIPO 23
A12: ANGEL EDUARDO VELIZ YSLA | B12: 17 | C12: DIANA | D12: SIG | E12: Para el siguiente - viaja a Chimbote a la mina
A13: URSULA LAY GUILLEN | B13: 17 | C13: DIANA | D13: NP
A14: NADIA ZEGARRA TOLENTINO | B14: 18 | C14: DIANA | D14: NC
A15: ARIANA MERCEDES GUEVARA MELENDEZ | B15: 8 | C15: DIANA | D15: NI | E15: Trabajo
A16: CRISTINA CUBA RIOS | B16: 11 | C16: DIANA | D16: NC
A17: HERMÓGENES UNTIVEROA CISNEROS | B17: 11 | C17: DIANA | D17: NC | E17: apagado
A18: PAMELA MELISA MORALES VEGA | B18: 12 | C18: DIANA | D18: NC | E18: apagado
A19: SHIRLEY RIVERA HUAMAN | B19: 12 | C19: DIANA | D19: NP | E19: temas de salud
A20: RAQUEL RIVEROS RAMOS | B20: 13 | C20: DIANA | D20: SIG | E20: E23
A21: ODALIS RIVERA OSORES | B21: 16 | C21: DIANA | D21: NC
A22: AVRIL ESTEPHANIA GARCIA MEDINA | B22: 16 | C22: DIANA | D22: NC
A23: CARLOS ALBERTO CASTILLO TIPISMANA | B23: 16 | C23: DIANA | D23: NI
A24: JENNY BETZABET ESPINAL | B24: 16 | C24: DIANA | D24: SIG | E24: se encuentra cudiado a su papá hospitalziado - siguiente E23
A25: SARAI MESIAS TOLENTINO | B25: 17 | C25: DIANA | D25: NC | E25: númeto sin servicio
A26: CLAUDIA OLENKA GALVEZ LOPEZ | B26: 17 | C26: DIANA | D26: OK | E26: CONFIRMO A ROUS | G26: 1
A27: ANGELLO GERONIMO PANTA MORALES | B27: 17 | C27: DIANA | D27: NP | E27: Tema de salud - operación // siguiente
A28: LIZETH PATRICIA ACUÑA MATOS | B28: 17 | C28: DIANA | D28: NC
A29: GIOVANNI GIUSSEPPE MIRANDA MALPARTIDA | B29: 17 | C29: DIANA | D29: OK | F29: C2 | G29: 1
A30: FERNANDO ABEL LOPEZ LOPEZ | B30: 18 | C30: DIANA | D30: XC
A31: GABRIELA KATERINNE JARA NARCISO | B31: 18 | C31: DIANA | D31: NC | E31: apagado
A32: DARNER ISZAT DIAZ ZAPANA | B32: 18 | C32: DIANA | D32: NC
A33: JOYCE MARIN | B33: 18 | C33: DIANA | D33: SIG | E33: E23
A34: ELVIS CUELLAR | B34: 8 | C34: GARETH | D34: NC
A35: NURY LUISA DEL CARMEN MARCA | B35: 9 | C35: GARETH | D35: NI
A36: ANAMELVA QUINONES BELTRAN | B36: 11 | C36: GARETH | D36: OK | E36: CONFIRMO A ROUS | F36: C2
A37: JOHNNY EDUARDO HUÁNUCO ARELLANO | B37: 12 | C37: GARETH | D37: NP
A38: LIBBY FIORELA HUAYTALLA SANCHEZ | B38: 13 | C38: GARETH | D38: SIG | E38: A partir de Enero
A39: MARÍA JESÚS CARRASCO LLATAS | B39: 13 | C39: GARETH | D39: SIG | E39: A partir de diciembre
A40: RAUL CHAVEZ INCHE | B40: 13 | C40: GARETH | D40: OK | F40: C2
...

Sheet ALIADOS C1 E26
A2: CREADOR CUANTICO | B2: EQUIPO | C2: RESPONSABLE | D2: RESP2 | E2: ESTADO | F2: OBSERVACIONES | G2: QT | H2: reto1 | I2: Grounding | J2: video | K2: forms
A3: VIVIANA ELIZABETH ALCANTARA MAURTUA | B3: 4 | C3: JOYCE | D3: JOYCE | E3: NP | F3: CONFIRMA YAKIMA
A4: CARMEN GRICELDA PEREZ CHINCHAY | B4: 5 | C4: JOYCE | E4: NP | F4: CONFIRMA CAPI
A5: ELVIS CUELLAR | B5: 8 | C5: JOYCE | D5: DIANA
A6: TONNY GUTIERREZ | B6: 8 | C6: OTTY | E6: NP | F6: MAS ADELANTE
A7: SANDRA MARLENE LOPEZ CHAHUA | B7: 9 | C7: JOYCE | F7: SER DISFRUTE Y EN TENERLO TODO | I7: OK
A8: JUANA MARIA FALCON ROJAS | B8: 10 | C8: DIANA | D8: LEYLA | E8: NP
A9: GERALDINE VANESSA SOTOMAYOR BAZAN | B9: 10 | C9: JOYCE | D9: JOYCE
A10: YUSMELY DESIREE GARCIA LLOVERA | B10: 10 | C10: JOYCE | D10: ZULEY | E10: NP | F10: SIGUIENTE
A11: JEANNET LEON LEDESMA | B11: 10 | C11: DIANA | D11: DIANA | E11: NC
A12: JOSÉ BLADIMER RAMOS SIQUEROS | B12: 10 | C12: OTTY | D12: ZULEY | E12: XC | F12: LLAMAR 18:40
A13: ELIZABETH MORALES CARCELEN | B13: 11 | C13: OTTY | D13: ZULEY | E13: NP | F13: SIGUIENTE
A14: ALEXANDRA TAPULLIMA CORDOVA | B14: 11 | C14: JOYCE | D14: ZULEY | E14: NC
A15: HERMÓGENES UNTIVEROA CISNEROS | B15: 11 | C15: JOYCE | E15: NP | F15: POSIBILIDAD E27 | K15: =8-51 -> -43
A16: ANAMELVA QUIÑONES BELTRÁN | B16: 11 | C16: JOYCE | F16: CONFIRMA DIANA - ENTRENARSE EN DISFRUTAR | I16: OK
A17: JANET DURAND YARASQUI | B17: 11 | C17: DIANA | E17: NP | F17: TRABAJO
A18: MARIA CELLI HUAYANCA DIAZ | B18: 11 | C18: OTTY | D18: ZULEY | E18: NO | I18: NO
A19: LUISA PÉREZ CHINCHAY | B19: 12 | C19: JOYCE | D19: LEYLA | E19: NC
A20: PAMELA MELISA MORALES VEGA | B20: 12 | C20: JOYCE | D20: DIANA | E20: NC | F20: TRABAJO
A21: JOHNNY EDUARDO HUÁNUCO ARELLANO | B21: 12 | C21: JOYCE | D21: JOYCE | F21: LLAMAR 20H30
A22: FUEL DURAND HUAYNATE | B22: 12 | C22: OTTY | D22: LEYLA | E22: NA
A23: SHIRLEY RIVERA HUAMAN | B23: 12 | C23: OTTY | E23: NI
A24: YANINA ESTEFANIA MEJIA ROMERO | B24: 13 | C24: DIANA | D24: JOYCE | E24: NC
A25: JEAN CARLOS RIOS | B25: 13 | C25: DIANA | D25: ZULEY | E25: NP
A26: PILAR DE LA CRUZ | B26: 13 | C26: DIANA | D26: DIANA | F26: Confirma Lunes - Llama Joyce
A27: ANGELLA BOLLET | B27: 13 | C27: JOYCE | E27: NP | F27: SERVICIO
A28: RAQUEL RIVEROS RAMOS | B28: 13 | C28: JOYCE | D28: ZULEY | E28: NP | F28: SIGUIENTE
A29: LIZ CAROL TRUJILLO MALLQUI | B29: 11 | C29: JOYCE | E29: OK | I29: OK
A30: MARIA ELENA ROMERO | B30: 13 | C30: OTTY | D30: DIANA
A31: PATRICIA RIOS | B31: 13 | C31: JOYCE | D31: DIANA
A32: MARÍA JESÚS CARRASCO LLATAS | B32: 13 | C32: OTTY | E32: NP
A33: FLOR DE CANTUTA TELLO SARMIENTO | B33: 14 | C33: DIANA | E33: NP
A34: SONIA POLANCO CABEZA | B34: 14 | C34: JOYCE | D34: JOYCE | F34: ALIADO E26
A35: JESSICA CONGA HUARCAYA | B35: 14 | C35: JOYCE | D35: ZULEY | E35: NC
A36: ROXANA FLORENTINA BORJAS ORMEÑO | B36: 14 | C36: JOYCE | D36: LEYLA | E36: NP | F36: COMPROMISO INQUEBRANTABLE
A37: RONY LANDEO | B37: 14 | C37: DIANA | D37: LEYLA | E37: SIG
A38: RAÚL CHÁVEZ INCHE | B38: 13 | C38: JOYCE | D38: LEYLA | E38: OK | F38: COMPROMISO INQUEBRANTABLE | I38: OK
A39: RHANIA SHADEN UNTIVEROS REQUEJO | B39: 14 | E39: OK | F39: CONFIRMA CAPI | I39: OK
A40: ELIZABETH MORALES | B40: 15 | C40: JOYCE | D40: DIANA
A41: MARIBEL ROBERTA ESPAÑA ZAMBRANO | B41: 15 | C41: JOYCE | D41: JOYCE | F41: LLAMAR A LAS 17H00
...

Sheet SOMBRAS C1E26CREADOR CUANTICO 
A1: no | B1: CREADOR CUANTICO
A2: 10 | B2: PIERO | D2: PAUL GAMARRA | E2: JOLBER VARGAS ENRIQUEZ
A3: 8 | B3: SANDRA MARLENE LOPEZ CHAHUA | D3: RAÚL CHÁVEZ INCHE | E3: JOSE MANUEL SURCO CORIMAYA
A4: 8 | B4: ANAMELVA QUIÑONES BELTRÁN | D4: TANIA AURORA SaNCHEZ CASTRO | E4: LUCAS ALBERTO SANCHEZ SILVA
A5: 6 | B5: RAÚL CHÁVEZ INCHE | D5: BRIAN STEVE SANGAY SALVATIERRA | E5: LUZ ELVIRA RAMiREZ
A6: 5 | B6: RHANIA SHADEN UNTIVEROS REQUEJO | D6: CRISTIAN ARONE | E6: MARiA ELENA ALVINO LoPEZ
A7: 7 | B7: CRISTIAN ARONE | D7: GIULIANA EDITH BUENDIA MUÑOZ | E7: KARIN PORTOCARRERO PEREA
A8: 4 | B8: SEBASTIÁN JOSÉ ALVARADO CABRERA | C8: OK | D8: JOSE GUILLERMO CURI SALVADOR | E8: MARIA OLARTE BARRIENTOS
A9: 5 | B9: LUZ MABEL CHIPANA VEGA | C9: OK | D9: LIZ CAROL TRUJILLO MALLQUI | E9: SEBASTIÁN JOSÉ ALVARADO CABRERA | G9: =37/2 -> 18.5
A10: 7 | B10: JOSE GUILLERMO CURI SALVADOR | C10: OK | D10: MARIA DEL CARMEN MENDOZA PILCO | E10: CARMEN ROSA MORAN CRUZ
A11: 5 | B11: DARNER ISZAT DIAZ ZAPANA | C11: OK | D11: VICTORIA DEL MILAGRO VALDIVIA VILLEGAS | E11: CÉSAR AUGUSTO NIEBUHR PRADO
A12: 3 | B12: LUCAS ALBERTO SANCHEZ SILVA | C12: OK | D12: YULI INeS MACHADO QUInONES | E12: DARNER ISZAT DIAZ ZAPANA
A13: 6 | B13: FABIO ALESSANDRO CANQUY LLOYD | C13: OK | D13: ANAMELVA QUIÑONES BELTRÁN | E13: LUZ MABEL CHIPANA VEGA
A14: 6 | B14: ANITA ESPERANZA FLORES TIPISMANA | D14: CAMILA ALEGRIA VERASTEGUI DURAN | E14: RHANIA SHADEN UNTIVEROS REQUEJO
A15: 8 | B15: CAMILA ALEGRIA VERASTEGUI DURAN | D15: ROXANA MURILLO BONETT | E15: YENI BAÑEZ LAURANTE
A16: 3 | B16: LUZ ELVIRA RAMiREZ | D16: SANDRA MARLENE LOPEZ CHAHUA | E16: AARON MIGUEL SURCO CORIMAYA
A17: 6 | B17: AARON MIGUEL SURCO CORIMAYA | D17: ARIANA XIMENA SOSAYA JIMeNEZ | E17: ANITA ESPERANZA FLORES TIPISMANA
A18: 9 | B18: HIPOLITA SaNCHEZ MEDINA | C18: OK | D18: HIPOLITA SaNCHEZ MEDINA | E18: FABIO ALESSANDRO CANQUY LLOYD
A19: 7 | B19: MARIA DEL CARMEN MENDOZA PILCO | D19: GREZIA MARÍA JOLLY VERA | E19: JENNIFER ALYSSON CASTANEDA PONCE DE LEON
A20: 3 | B20: MARiA ELENA ALVINO LoPEZ | D20: PIERO
A21: 8 | B21: ROXANA MURILLO BONETT
A22: 6 | B22: JENNIFER ALYSSON CASTANEDA PONCE DE LEON | C22: OK
A23: 4 | B23: KARIN PORTOCARRERO PEREA
A24: 7 | B24: VICTORIA DEL MILAGRO VALDIVIA VILLEGAS
A25: 9 | B25: ARIANA XIMENA SOSAYA JIMeNEZ | C25: OK
A26: 5 | B26: CARMEN ROSA MORAN CRUZ
A27: 7 | B27: GIULIANA EDITH BUENDIA MUÑOZ
A28: 3 | B28: JOSE MANUEL SURCO CORIMAYA | C28: OK
A29: 4 | B29: MARIA OLARTE BARRIENTOS
A30: 7 | B30: BRIAN STEVE SANGAY SALVATIERRA
A31: 2 | B31: JOLBER VARGAS ENRIQUEZ
A32: 5 | B32: YENI BAÑEZ LAURANTE
A33: 7 | B33: YULI INeS MACHADO QUInONES
A34: 6 | B34: PAUL GAMARRA
A35: 6 | B35: TANIA AURORA SaNCHEZ CASTRO
A36: 7 | B36: LIZ CAROL TRUJILLO MALLQUI
A37: 5 | B37: CÉSAR AUGUSTO NIEBUHR PRADO | C37: OK
A38: 9 | B38: GREZIA MARÍA JOLLY VERA

Sheet APOYOS CAP 1 E25 (2)
B1: CODIGO DE VESTIMENTA PARA LOS APOYOS SIEMPRE NEGRO FORMAL | J1: OBS
A2: N° | B2: RESP | C2: APOYOS | D2: EQUIPO | E2: VIERNES 8 AM - 1PM | F2: SÁBADO 830 AM - 12PM | G2: SÁBADO 5 PM - 8 PM | H2: DOMINGO 8:30 AM - 11 AM | I2: DOMINGO 6PM - 8 PM
A3: 1 | B3: NA | C3: CARMEN PEREZ CHINCHAY | D3: 9
A4: 2 | B4: NA | C4: MILAGROS CASTAÑEDA ORBE | D4: 10
A5: 3 | C5: ELIZABETH MORALES CARCELEN | D5: =+VLOOKUP(C5,'GRADUADOS '!$A$2:$B$230,2,0) -> 11 | E5: XC
A6: 4 | B6: NA | C6: LIZ CAROL TRUJILLO MALLQUI | D6: 11 | J6: ALIADO
A7: 5 | C7: ANAMELVA QUIÑONES BELTRÁN | D7: 11 | I7: OK
C8: MARIA CELLI HUAYANCA DIAZ | D8: 11
A9: 6 | C9: SHIRLEY RIVERA HUAMAN | D9: =+VLOOKUP(C9,'GRADUADOS '!$A$2:$B$230,2,0) -> 12 | I9: OK
A10: 7 | B10: NA | C10: D'YANIRA ALLYZON LEON SUAREZ | D10: =+VLOOKUP(C10,'GRADUADOS '!$A$2:$B$230,2,0) -> 12
A11: 8 | C11: PAMELA MORALES VEGA | D11: 12
A12: 9 | C12: LEYDY PEÑA CHAVARRIA | D12: =+VLOOKUP(C12,'GRADUADOS '!$A$2:$B$230,2,0) -> 13
C13: RAQUEL RIVEROS RAMOS | D13: 13 | E13: NP | F13: OK | H13: NP | I13: NP
A14: 10 | C14: PILAR DE LA CRUZ | D14: =+VLOOKUP(C14,'GRADUADOS '!$A$2:$B$230,2,0) -> 13
A15: 11 | B15: NA | C15: PIERO ALESSANDRO PORTAL PASQUEL | D15: =+VLOOKUP(C15,'GRADUADOS '!$A$2:$B$230,2,0) -> 14
A16: 12 | C16: ANTONY LEO ALTAMIRANO LLACCHUAS | D16: =+VLOOKUP(C16,'GRADUADOS '!$A$2:$B$230,2,0) -> 15
A17: 13 | C17: GIULIANA CRISTINA BECERRA CANTELLA | D17: =+VLOOKUP(C17,'GRADUADOS '!$A$2:$B$230,2,0) -> 15
A18: 14 | C18: SHEILA DE LA CRUZ HUAYTALLA | D18: =+VLOOKUP(C18,'GRADUADOS '!$A$2:$B$230,2,0) -> 15
A19: 15 | C19: ODALIS RIVERA OSORES | D19: =+VLOOKUP(C19,'GRADUADOS '!$A$2:$B$230,2,0) -> 16
A20: 16 | C20: KATIA MELVA DE PAZ FIGUEROA | D20: =+VLOOKUP(C20,'GRADUADOS '!$A$2:$B$230,2,0) -> 16
A21: 17 | B21: NA | C21: RUMI MONTANO RAMOS | D21: =+VLOOKUP(C21,'GRADUADOS '!$A$2:$B$230,2,0) -> 16
A22: 18 | C22: JORGE EDUARDO CHALCO CCASA | D22: =+VLOOKUP(C22,'GRADUADOS '!$A$2:$B$230,2,0) -> 16 | E22: NP | F22: NP | G22: NP | H22: NP | I22: NP
A23: 19 | C23: JIMENA PLASENCIA | D23: 16 | F23: NP
A24: 20 | C24: NADIA ZEGARRA TOLENTINO | D24: =+VLOOKUP(C24,'GRADUADOS '!$A$2:$B$230,2,0) -> 18 | E24: OK
A25: 21 | C25: ROXANA ELIZABETH AYVAR VEGA | D25: =+VLOOKUP(C25,'GRADUADOS '!$A$2:$B$230,2,0) -> 18
C26: ANA CARINA CáRDENAS TERREROS | D26: 18 | E26: OK
A27: 22 | C27: RONALD HENRY CARITA CANSAYA | D27: 18
A28: 23 | C28: JESSICA GUISELLE MORALES VEGA | D28: 18
A29: 24 | B29: NA | C29: CAMILA ALEGRIA VERASTEGUI DURAN | D29: =+VLOOKUP(C29,'GRADUADOS '!$A$2:$B$230,2,0) -> 19
A30: 25 | C30: LILIANA JACKELINE CHU COELLO | D30: =+VLOOKUP(C30,'GRADUADOS '!$A$2:$B$230,2,0) -> 19
A31: 26 | B31: NA | C31: DIANA REYNA RAMOS OROSCO | D31: =+VLOOKUP(C31,'GRADUADOS '!$A$2:$B$230,2,0) -> 19
A32: 27 | C32: LEISI MEDINA | D32: 19
A33: 28 | C33: VIOLETA LIS BELLO GASPAR | D33: =+VLOOKUP(C33,'GRADUADOS '!$A$2:$B$230,2,0) -> 19
A34: 29 | C34: AARON MIGUEL SURCO CORIMAYA | D34: 20 | E34: NP | F34: NP | G34: NP | H34: NP | I34: NP
A35: 30 | C35: ANGEL ENRIQUE YONG LAU | D35: 20 | E35: NP | F35: NP | G35: NP | H35: NP | I35: NP
A36: 31 | B36: NA | C36: CAROLINA VICTORIA MANRIQUE HUARANCA | D36: 20
A37: 32 | C37: ELIZABETH HUAMANI PALOMINO | D37: 20
A38: 33 | B38: NA | C38: FELIPE ALEJANDRO MALLQUI TRUJILLO | D38: 20
A39: 34 | C39: GINA CaRDENAS LOPEZ | D39: 20
A40: 35 | C40: GUIDO RUSVEL FALCON ROJAS | D40: 20
...

Sheet APOYOS CAP 1 E27
B1: CODIGO DE VESTIMENTA PARA LOS APOYOS SIEMPRE NEGRO FORMAL | J1: OBS
A2: N° | B2: RESP | C2: APOYOS | D2: EQUIPO | E2: VIERNES 8 AM - 1PM | F2: SÁBADO 830 AM - 12PM | G2: SÁBADO 5 PM - 8 PM | H2: DOMINGO 8:30 AM - 11 AM | I2: DOMINGO 6PM - 8 PM
B3: A | C3: AARON ALBERTO URIARTE CACHAY | D3: 21
B4: A | C4: AARON MIGUEL SURCO CORIMAYA | D4: 20
B5: JOY | C5: ABANTO RIOS LUZ ISABEL | D5: 25
B6: LEY | C6: ALBORNOZ LEON BARMER FERNANDO | D6: 24
B7: LUIS | C7: ALTAMIRANO LLANTOY LELY MELUSA | D7: 24
B8: LEY | C8: ANA CARINA CáRDENAS TERREROS | D8: 18 | J8: AFUERA DE MESA
B9: LUIS | C9: Ana Gabriela Ramos Ramos | D9: 24
B10: A | C10: ANAMELVA QUIÑONES BELTRÁN | D10: 11
B11: ZU | C11: ANDRADE TANG ANITA BELEN | D11: 24
B12: LEY | C12: ANGEL ENRIQUE YONG LAU | D12: 20
B13: DM | C13: ANTONY LEO ALTAMIRANO LLACCHUAS | D13: =+VLOOKUP(C13,'GRADUADOS '!$A$2:$B$230,2,0) -> 15
B14: LUIS | C14: APONTE PEREZ CHARO YANETH | D14: 22
B15: LEY | C15: ARAUJO TANGOA BERTHA LUZ | D15: 22
B16: JOY | C16: ARIANA JANICE DE LA CRUZ GARCIA | D16: 23
B17: ZU | C17: ARRIETA BERMUDO IDA | D17: 24
B18: JOY | C18: BANEZ LAURANTE YENI | D18: 22
B19: ZU | C19: BUENDIA MUNOZ GIULIANA EDITH | D19: 22
B20: LEY | C20: CALLE GUIZADO NAYSHA ESCARLETH | D20: 24
B21: A | C21: CAMILA ALEGRIA VERASTEGUI DURAN | D21: =+VLOOKUP(C21,'GRADUADOS '!$A$2:$B$230,2,0) -> 19
B22: DM | C22: CáRDENAS TERREROS ANA CARINA | D22: 24
B23: DM | C23: CARMEN PEREZ CHINCHAY | D23: 9
B24: JOY | C24: CAROLINA VICTORIA MANRIQUE HUARANCA | D24: 20
B25: ZU | C25: CARRASCO CHAFLOQUE ERIKA | D25: 25
B26: JOY | C26: CASTANEDA PONCE DE LEON JENNIFER ALYSSON | D26: 22
B27: LEY | C27: CASTILLO GONZALES HOLLY STEPHANY | D27: 24
B28: LEY | C28: CASTILLO PAREDEZ ViCTOR VICENTE | D28: 25
B29: DM | C29: CASTILLO RIOS PAMELA CYNTHIA | D29: 22
B30: JOY | C30: CCARHUAS CHIPANA MARIBEL | D30: 25
B31: DM | C31: CELEDONIO RIOS MARJORIE ZULAY | D31: 24
B32: DM | C32: CESAR ADINO MANRIQUE ESCOBAR | D32: 23
B33: DM | C33: CHIPANA LLACCHUA ROSA | D33: 24
... B41: ZU | C41: DAVID EMERSON CONTRERAS LUCHINE | D41: 23
B42: JOY | C42: DIANA REYNA RAMOS OROSCO | D42: =+VLOOKUP(C42,'GRADUADOS '!$A$2:$B$230,2,0) -> 19
B43: JOY | C43: Diego Wladimith Romero | D43: 24
B44: DM | C44: DUQUE MAYO YENITSE DEL VALLE | D44: 25
B45: DM | C45: D'YANIRA ALLYZON LEON SUAREZ | D45: =+VLOOKUP(C45,'GRADUADOS '!$A$2:$B$230,2,0) -> 12
B46: ZU | C46: EDITH SILVIA ESPINOZA SURICHAQUI | D46: 23
B47: LUIS | C47: ELIZABETH HUAMANI PALOMINO | D47: 20
...

Sheet APOYOS CAP 1 E26
B1: CODIGO DE VESTIMENTA PARA LOS APOYOS SIEMPRE NEGRO FORMAL | J1: OBS
A2: N° | B2: RESP | C2: APOYOS | D2: EQUIPO | E2: VIERNES 8 AM - 1PM | F2: SÁBADO 830 AM - 12PM | G2: SÁBADO 5 PM - 8 PM | H2: DOMINGO 8:30 AM - 11 AM | I2: DOMINGO 6PM - 8 PM
B3: A | C3: AARON ALBERTO URIARTE CACHAY | D3: 21
B4: A | C4: AARON MIGUEL SURCO CORIMAYA | D4: 20
B5: JOY | C5: ABANTO RIOS LUZ ISABEL | D5: 25 | F5: NA | H5: NA | I5: NA
B6: LEY | C6: ALBORNOZ LEON BARMER FERNANDO | D6: 24 | E6: OK
B7: LUIS | C7: ALTAMIRANO LLANTOY LELY MELUSA | D7: 24 | E7: OK
B8: LEY | C8: ANA CARINA CáRDENAS TERREROS | D8: 18 | E8: OK | F8: OK | J8: AFUERA DE MESA
B9: LUIS | C9: Ana Gabriela Ramos Ramos | D9: 24 | E9: OK
B10: A | C10: ANAMELVA QUIÑONES BELTRÁN | D10: 11
B11: ZU | C11: ANDRADE TANG ANITA BELEN | D11: 24
B12: LEY | C12: ANGEL ENRIQUE YONG LAU | D12: 20 | E12: OK | F12: OK
B13: DM | C13: ANTONY LEO ALTAMIRANO LLACCHUAS | D13: =+VLOOKUP(C13,'GRADUADOS '!$A$2:$B$230,2,0) -> 15
B14: LUIS | C14: APONTE PEREZ CHARO YANETH | D14: 22 | E14: OK
B15: LEY | C15: ARAUJO TANGOA BERTHA LUZ | D15: 22 | E15: NP
B16: JOY | C16: ARIANA JANICE DE LA CRUZ GARCIA | D16: 23 | E16: NA | F16: NA | H16: NA | I16: NA
B17: ZU | C17: ARRIETA BERMUDO IDA | D17: 24
B18: JOY | C18: BANEZ LAURANTE YENI | D18: 22 | E18: NA | F18: NA | H18: NA | I18: NA
B19: ZU | C19: BUENDIA MUNOZ GIULIANA EDITH | D19: 22
B20: LEY | C20: CALLE GUIZADO NAYSHA ESCARLETH | D20: 24 | E20: NC
B21: A | C21: CAMILA ALEGRIA VERASTEGUI DURAN | D21: =+VLOOKUP(C21,'GRADUADOS '!$A$2:$B$230,2,0) -> 19
B22: DM | C22: CáRDENAS TERREROS ANA CARINA | D22: 24
B23: DM | C23: CARMEN PEREZ CHINCHAY | D23: 9 | E23: OK | H23: OK | I23: OK
B24: JOY | C24: CAROLINA VICTORIA MANRIQUE HUARANCA | D24: 20 | E24: NC | F24: NC | H24: NC | I24: NC
B25: ZU | C25: CARRASCO CHAFLOQUE ERIKA | D25: 25 | F25: NA | H25: NA | I25: NA
B26: JOY | C26: CASTANEDA PONCE DE LEON JENNIFER ALYSSON | D26: 22 | E26: NA | F26: NA | H26: NA | I26: NA
B27: LEY | C27: CASTILLO GONZALES HOLLY STEPHANY | D27: 24 | E27: NP | F27: NA | H27: NA | I27: NA
B28: LEY | C28: CASTILLO PAREDEZ ViCTOR VICENTE | D28: 25 | F28: NA | H28: NA | I28: NA
B29: DM | C29: CASTILLO RIOS PAMELA CYNTHIA | D29: 22
B30: JOY | C30: CCARHUAS CHIPANA MARIBEL | D30: 25 | E30: NP | F30: NA | H30: NA | I30: NA
B31: DM | C31: CELEDONIO RIOS MARJORIE ZULAY | D31: 24
B32: DM | C32: CESAR ADINO MANRIQUE ESCOBAR | D32: 23
B33: DM | C33: CHIPANA LLACCHUA ROSA | D33: 24 | E33: OK | F33: NP | H33: NP | I33: NP
B34: DM | C34: CHIPANA LLACCHUA SIXTO | D34: 25 | E34: OK | F34: NA | H34: NA | I34: NA
B35: LEY | C35: CLAUDIA ALEJANDRA BERNAL VILLAR | D35: 23 | E35: NC
B36: ZU | C36: CORAL TULUMBA YSIDORA | D36: 25 | F36: NA | H36: NA | I36: NA
B37: ZU | C37: CORNELIO NOLASCO ESTELA | D37: 23
B38: LEY | C38: CORREA OLAYA EUFEMIA ISABEL | D38: 24 | E38: NC
B39: LEY | C39: CRISTIAN MIJAIL CASTILLO GONZALES | D39: 23 | E39: NP
B40: A | C40: DARNER ISZAT DIAZ ZAPANA | D40: 18
...

Sheet APOYOS CAP 1 E24
B1: CODIGO DE VESTIMENTA PARA LOS APOYOS SIEMPRE NEGRO FORMAL | J1: OBS
A2: N° | B2: RESPONSABLE | C2: APOYOS | D2: EQUIPO | E2: VIERNES 8 AM - 1PM | F2: SÁBADO 830 AM - 12PM | G2: SÁBADO 5 PM - 8 PM | H2: DOMINGO 8:30 AM - 11 AM | I2: DOMINGO 430 PM - 8 PM
A3: 1 | B3: GARETH | C3: SANDRA MARLENE LOPEZ CHAHUA | D3: =+VLOOKUP(C3,'GRADUADOS '!$A$2:$B$230,2,0) -> 9 | E3: NP | F3: NP | G3: NP | H3: NP | I3: NP
A4: 2 | B4: JOYCE | C4: CARMEN PEREZ CHINCHAY | D4: 9 | E4: NP | F4: OK | G4: OK | H4: OK | I4: OK | J4: CONFIRMO PARA EL VIERNES 16 - GARETH - SE VA A CAP2
A5: 3 | B5: JOYCE | C5: MILAGROS CASTAÑEDA ORBE | D5: 10
A6: 4 | B6: KRISCIA | C6: ELIZABETH MORALES CARCELEN | D6: =+VLOOKUP(C6,'GRADUADOS '!$A$2:$B$230,2,0) -> 11 | E6: NP | F6: NA | G6: NA | H6: NA | I6: NA
A7: 5 | B7: GARETH | C7: LIZ CAROL TRUJILLO MALLQUI | D7: 11 | E7: NP | F7: NP | G7: NP | H7: NP | I7: NP | J7: MESA DE ENROLLAMIENTO CAP2 SABADO
A8: 6 | B8: GARETH | C8: SHIRLEY RIVERA HUAMAN | D8: =+VLOOKUP(C8,'GRADUADOS '!$A$2:$B$230,2,0) -> 12 | E8: NP
A9: 7 | B9: KRISCIA | C9: D'YANIRA ALLYZON LEON SUAREZ | D9: =+VLOOKUP(C9,'GRADUADOS '!$A$2:$B$230,2,0) -> 12 | E9: NP | F9: NA | G9: NA | H9: NA | I9: NA
A10: 8 | B10: JOYCE | C10: PAMELA MORALES VEGA | D10: 12 | E10: NP | F10: NP | G10: NP | H10: NP | I10: NP
A11: 9 | B11: GARETH | C11: LEYDY PEÑA CHAVARRIA | D11: =+VLOOKUP(C11,'GRADUADOS '!$A$2:$B$230,2,0) -> 13 | E11: NP | F11: NP | G11: NP | H11: NP | I11: NP
A12: 10 | B12: GARETH | C12: PILAR DE LA CRUZ | D12: =+VLOOKUP(C12,'GRADUADOS '!$A$2:$B$230,2,0) -> 13 | F12: NP | G12: NP | H12: NP | I12: NP
A13: 11 | B13: KRISCIA | C13: MARÍA ELENA ROMERO RAMIREZ | D13: =+VLOOKUP(C13,'GRADUADOS '!$A$2:$B$230,2,0) -> 13 | F13: NA | G13: NA | H13: NA | I13: OK
A14: 12 | B14: JOYCE | C14: MARIA VERONICA JIMENEZ VASQUEZ | D14: =+VLOOKUP(C14,'GRADUADOS '!$A$2:$B$230,2,0) -> 13 | E14: NP | F14: NP | G14: NP | H14: NP | I14: NP
A15: 13 | B15: GARETH | C15: JESUS JULIO ANTAURCO PEREZ | D15: =+VLOOKUP(C15,'GRADUADOS '!$A$2:$B$230,2,0) -> 14 | E15: NA
A16: 14 | B16: GARETH | C16: PILAR CUADRAO CARRUITERO | D16: =+VLOOKUP(C16,'GRADUADOS '!$A$2:$B$230,2,0) -> 14 | E16: NA
