Workbook

Sheet Hoja1
A1: COORDINADOR MAESTRIA DEL JUEGO | B1: MAESTRIA DEL JUEGO | E1: CAPITULO UNO | J1: C2 A CREACION | Y1: CREACION A RELACION | AJ1: RELACIÓN A GRATITUD | AU1: GRATITUD AL VIAJE | AY1: PERDIDOS | BD1: STATUS DEL EQUIPO
I2: CAPITULO DOS | P2: CREACIÓN | Y2: RELACIÓN | AJ2: GRATITUD | AU2: EL VIAJE
A3: CMJ | B3: SEDE | C3: E.# | D3: ENROLAMIENTO | E3: INICIAN C1 | F3: TERMINAN CAP 1 | G3: PAGAN C2 | H3: PASE | I3: INICIAN C2 | J3: TERMINAN C2 | K3: PAGOS MJ | L3: PASE | M3: MANGERS DECLARADOS | N3: C2 | O3: REZAGADOS | P3: PX INICIO | Q3: MANAGERS INICIO | R3: PX FINAL | S3: MANGERS FINAL | T3: DESERTORES PX | U3: DESERTORES MG | V3: ENROLAMIENTO PX | W3: ENROLAMIENTO MANAGERS | X3: ENROLAMIENTO TOTAL | Y3: PX INICIO | Z3: MANAGERS INICIO | AA3: DESERTORES PX | AB3: DESERTORES MANAGERS | AC3: PX FINAL | AD3: MANGERS FINAL | AE3: DESERTORES PX | AF3: DESERTORES MG | AG3: ENROLAMIENTO PX | AH3: ENROLAMIENTO MANAGERS | AI3: ENROLAMIENTO TOTAL | AJ3: PX INICIO | AK3: MANAGERS INICIO | AL3: DESERTORES PX | AM3: DESERORES MANAGERS | AN3: PX FINAL | AO3: MANGERS FINAL | AP3: DESERTORES PX | AQ3: DESERTORES MG | AR3: ENROLAMIENTO PX | AS3: ENROLAMIENTO MANAGERS | AT3: ENROLAMIENTO TOTAL | AU3: PX INICIO | AV3: MANAGERS INICIO | AW3: NO GRADUADO PX | AX3: NO GRADUADO MANAGERS | AY3: PX PERDIDOS EN MJ | AZ3: MANAGER PERDIDOS EN MJ | BA3: % DESERCIÓN | BB3: IMPACTO C1-VIAJE | BC3: IMPACTO | BD3: STATUS DEL EQUIPO
A4: MIGUEL TORRES | B4: CUENCA | C4: 1 | D4: =54+32+34 -> 120 | E4: 61 | F4: 61 | G4: 23 | H4: =+G4/F4 -> 0.37704918 | I4: 30 | J4: 30 | K4: 28 | L4: =+K4/J4 -> 0.93333333 | M4: 5 | N4: 21 | O4: 0 | P4: =+O4+N4 -> 21 | Q4: 5 | R4: 18 | S4: 5 | T4: =+P4-R4 -> 3 | U4: =+Q4-S4 -> 0 | V4: 22 | W4: 15 | X4: =+W4+V4 -> 37 | Y4: 16 | Z4: 5 | AA4: =+R4-Y4 -> 2 | AB4: =+S4-Z4 -> 0 | AC4: 16 | AD4: 5 | AE4: =+Y4-AC4 -> 0 | AF4: =+Z4-AD4 -> 0 | AG4: 16 | AH4: 16 | AI4: =+AH4+AG4 -> 32 | AJ4: 16 | AK4: 5 | AL4: =+AC4-AJ4 -> 0 | AM4: =+AD4-AK4 -> 0 | AN4: 14 | AO4: 4 | AP4: =+AJ4-AN4 -> 2 | AQ4: =+AK4-AO4 -> 1 | AR4: 23 | AS4: 11 | AT4: =+AS4+AR4 -> 34 | AU4: 14 | AV4: 4 | AW4: =+AN4-AU4 -> 0 | AX4: =+AO4-AV4 -> 0 | AY4: =+P4-AU4 -> 7 | AZ4: =+Q4-AV4 -> 1 | BA4: =+(AY4+AZ4)/(P4+Q4) -> 0.30769231 | BB4: =+(AU4+AV4)/E4 -> 0.29508197 | BC4: =+AU4/D4 -> 0.11666667 | BD4: =IF(AU4>0,"Graduado","En Proceso") -> Graduado
A5: MAURICIO RAMIREZ | B5: MEDELLIN | C5: 1 | D5: 46 | E5: 40 | F5: 38 | G5: 24 | H5: =+G5/F5 -> 0.63157895 | I5: 19 | J5: 19 | K5: 19 | L5: =+K5/J5 -> 1 | M5: 3 | N5: 18 | O5: 1 | P5: =+O5+N5 -> 19 | Q5: 3 | R5: 18 | S5: 3 | T5: =+P5-R5 -> 1 | U5: =+Q5-S5 -> 0 | V5: 31 | W5: 15 | X5: =+W5+V5 -> 46 | Y5: 16 | Z5: 3 | AA5: =+R5-Y5 -> 2 | AB5: =+S5-Z5 -> 0 | AC5: 14 | AD5: 2 | AE5: =+Y5-AC5 -> 2 | AF5: =+Z5-AD5 -> 1 | AG5: 13 | AH5: 10 | AI5: =+AH5+AG5 -> 23 | AJ5: 14 | AK5: 2 | AL5: =+AC5-AJ5 -> 0 | AM5: =+AD5-AK5 -> 0 | AN5: 12 | AO5: 2 | AP5: =+AJ5-AN5 -> 2 | AQ5: =+AK5-AO5 -> 0 | AR5: 14 | AS5: 9 | AT5: =+AS5+AR5 -> 23 | AU5: 7 | AV5: 2 | AW5: =+AN5-AU5 -> 5 | AX5: =+AO5-AV5 -> 0 | AY5: =+P5-AU5 -> 12 | AZ5: =+Q5-AV5 -> 1 | BA5: =+(AY5+AZ5)/(P5+Q5) -> 0.59090909 | BB5: =+(AU5+AV5)/E5 -> 0.225 | BC5: =+AU5/D5 -> 0.15217391 | BD5: =IF(AU5>0,"Graduado","En Proceso") -> Graduado
A6: MIGUEL TORRES | B6: CUENCA | C6: 2 | D6: 39 | E6: 32 | F6: 31 | G6: 21 | H6: =+G6/F6 -> 0.67741935 | I6: 21 | J6: 19 | K6: 17 | L6: =+K6/J6 -> 0.89473684 | M6: 5 | N6: 17 | O6: 1 | P6: =+O6+N6 -> 18 | Q6: 3 | R6: 18 | S6: 3 | T6: =+P6-R6 -> 0 | U6: =+Q6-S6 -> 0 | V6: 41 | W6: 16 | X6: =+W6+V6 -> 57 | Y6: 18 | Z6: 3 | AA6: =+R6-Y6 -> 0 | AB6: =+S6-Z6 -> 0 | AC6: 18 | AD6: 2 | AE6: =+Y6-AC6 -> 0 | AF6: =+Z6-AD6 -> 1 | AG6: 24 | AH6: 8 | AI6: =+AH6+AG6 -> 32 | AJ6: 16 | AK6: 2 | AL6: =+AC6-AJ6 -> 2 | AM6: =+AD6-AK6 -> 0 | AN6: 15 | AO6: 2 | AP6: =+AJ6-AN6 -> 1 | AQ6: =+AK6-AO6 -> 0 | AR6: 39 | AS6: 11 | AT6: =+AS6+AR6 -> 50 | AU6: 14 | AV6: 2 | AW6: =+AN6-AU6 -> 1 | AX6: =+AO6-AV6 -> 0 | AY6: =+P6-AU6 -> 4 | AZ6: =+Q6-AV6 -> 1 | BA6: =+(AY6+AZ6)/(P6+Q6) -> 0.23809524 | BB6: =+(AU6+AV6)/E6 -> 0.5 | BC6: =+AU6/D6 -> 0.35897436 | BD6: =IF(AU6>0,"Graduado","En Proceso") -> Graduado
A7: MAURICIO RAMIREZ | B7: MEDELLIN | C7: 2 | D7: 47 | E7: 42 | F7: 40 | G7: 31 | H7: =+G7/F7 -> 0.775 | I7: 28 | J7: 28 | K7: 24 | L7: =+K7/J7 -> 0.85714286 | M7: 6 | N7: 15 | O7: 0 | P7: =+O7+N7 -> 15 | Q7: 6 | R7: 13 | S7: 6 | T7: =+P7-R7 -> 2 | U7: =+Q7-S7 -> 0 | V7: 21 | W7: 26 | X7: =+W7+V7 -> 47 | Y7: 12 | Z7: 6 | AA7: =+R7-Y7 -> 1 | AB7: =+S7-Z7 -> 0 | AC7: 12 | AD7: 6 | AE7: =+Y7-AC7 -> 0 | AF7: =+Z7-AD7 -> 0 | AG7: 30 | AH7: 27 | AI7: =+AH7+AG7 -> 57 | AJ7: 11 | AK7: 5 | AL7: =+AC7-AJ7 -> 1 | AM7: =+AD7-AK7 -> 1 | AN7: 8 | AO7: 5 | AP7: =+AJ7-AN7 -> 3 | AQ7: =+AK7-AO7 -> 0 | AR7: 26 | AS7: 30 | AT7: =+AS7+AR7 -> 56 | AU7: 8 | AV7: 5 | AW7: =+AN7-AU7 -> 0 | AX7: =+AO7-AV7 -> 0 | AY7: =+P7-AU7 -> 7 | AZ7: =+Q7-AV7 -> 1 | BA7: =+(AY7+AZ7)/(P7+Q7) -> 0.38095238 | BB7: =+(AU7+AV7)/E7 -> 0.30952381 | BC7: =+AU7/D7 -> 0.17021277 | BD7: =IF(AU7>0,"Graduado","En Proceso") -> Graduado
A8: MIGUEL TORRES | B8: CUENCA | C8: 3 | D8: =33+24 -> 57 | E8: 16 | F8: 16 | G8: 2 | H8: =+G8/F8 -> 0.125 | I8: 22 | J8: 18 | K8: 18 | L8: =+K8/J8 -> 1 | M8: 5 | N8: 15 | O8: 0 | P8: =+O8+N8 -> 15 | Q8: 4 | R8: 15 | S8: 4 | T8: =+P8-R8 -> 0 | U8: =+Q8-S8 -> 0 | V8: 23 | W8: 10 | X8: =+W8+V8 -> 33 | Y8: 13 | Z8: 4 | AA8: =+R8-Y8 -> 2 | AB8: =+S8-Z8 -> 0 | AC8: 12 | AD8: 2 | AE8: =+Y8-AC8 -> 1 | AF8: =+Z8-AD8 -> 2 | AG8: 17 | AH8: 7 | AI8: =+AH8+AG8 -> 24 | AJ8: 10 | AK8: 2 | AL8: =+AC8-AJ8 -> 2 | AM8: =+AD8-AK8 -> 0 | AN8: 8 | AO8: 2 | AP8: =+AJ8-AN8 -> 2 | AQ8: =+AK8-AO8 -> 0 | AR8: 22 | AS8: 5 | AT8: =+AS8+AR8 -> 27 | AU8: 7 | AV8: 2 | AW8: =+AN8-AU8 -> 1 | AX8: =+AO8-AV8 -> 0 | AY8: =+P8-AU8 -> 8 | AZ8: =+Q8-AV8 -> 2 | BA8: =+(AY8+AZ8)/(P8+Q8) -> 0.52631579 | BB8: =+(AU8+AV8)/E8 -> 0.5625 | BC8: =+AU8/D8 -> 0.12280702 | BD8: =IF(AU8>0,"Graduado","En Proceso") -> Graduado
A9: MAURICIO RAMIREZ | B9: MEDELLIN | C9: 3 | D9: 70 | E9: 49 | F9: 41 | G9: 21 | H9: =+G9/F9 -> 0.51219512 | I9: 17 | J9: 16 | K9: 16 | L9: =+K9/J9 -> 1 | M9: 1 | N9: 14 | O9: 2 | P9: =+O9+N9 -> 16 | Q9: 1 | R9: 14 | S9: 1 | T9: =+P9-R9 -> 2 | U9: =+Q9-S9 -> 0 | V9: 25 | W9: 3 | X9: =+W9+V9 -> 28 | Y9: 13 | Z9: 1 | AA9: =+R9-Y9 -> 1 | AB9: =+S9-Z9 -> 0 | AC9: 12 | AD9: 1 | AE9: =+Y9-AC9 -> 1 | AF9: =+Z9-AD9 -> 0 | AG9: 22 | AH9: 5 | AI9: =+AH9+AG9 -> 27 | AJ9: 0 | AK9: 0 | AL9: =+AC9-AJ9 -> 12 | AM9: =+AD9-AK9 -> 1 | AN9: 0 | AO9: 0 | AP9: =+AJ9-AN9 -> 0 | AQ9: =+AK9-AO9 -> 0 | AR9: 0 | AS9: 0 | AT9: =+AS9+AR9 -> 0 | AU9: 0 | AV9: 0 | AW9: =+AN9-AU9 -> 0 | AX9: =+AO9-AV9 -> 0 | AY9: =+P9-AU9 -> 16 | AZ9: =+Q9-AV9 -> 1 | BA9: =+(AY9+AZ9)/(P9+Q9) -> 1 | BB9: =+(AU9+AV9)/E9 -> 0 | BC9: =+AU9/D9 -> 0 | BD9: =IF(AU9>0,"Graduado","En Proceso") -> En Proceso
A10: JOSUE VERA | B10: CUENCA | C10: 4 | D10: 99 | E10: 74 | F10: 59 | G10: 16 | H10: =+G10/F10 -> 0.27118644 | I10: 13 | J10: 13 | K10: 12 | L10: =+K10/J10 -> 0.92307692 | M10: 0 | N10: 12 | O10: 0 | P10: =+O10+N10 -> 12 | Q10: 1 | R10: 10 | S10: 2 | T10: =+P10-R10 -> 2 | U10: =+Q10-S10 -> -1 | V10: 15 | W10: 6 | X10: =+W10+V10 -> 21 | Y10: 8 | Z10: 2 | AA10: =+R10-Y10 -> 2 | AB10: =+S10-Z10 -> 0 | AC10: 8 | AD10: 2 | AE10: =+Y10-AC10 -> 0 | AF10: =+Z10-AD10 -> 0 | AG10: 18 | AH10: 5 | AI10: =+AH10+AG10 -> 23 | AJ10: 8 | AK10: 2 | AL10: =+AC10-AJ10 -> 0 | AM10: =+AD10-AK10 -> 0 | AN10: 8 | AO10: 1 | AP10: =+AJ10-AN10 -> 0 | AQ10: =+AK10-AO10 -> 1 | AR10: 14 | AS10: 6 | AT10: =+AS10+AR10 -> 20 | AU10: 8 | AV10: 1 | AW10: =+AN10-AU10 -> 0 | AX10: =+AO10-AV10 -> 0 | AY10: =+P10-AU10 -> 4 | AZ10: =+Q10-AV10 -> 0 | BA10: =+(AY10+AZ10)/(P10+Q10) -> 0.30769231 | BB10: =+(AU10+AV10)/E10 -> 0.12162162 | BC10: =+AU10/D10 -> 0.080808081 | BD10: =IF(AU10>0,"Graduado","En Proceso") -> Graduado
A11: MAURICIO RAMIREZ | B11: MEDELLIN | C11: 4 | D11: 108 | E11: 59 | F11: 51 | G11: 37 | H11: =+G11/F11 -> 0.7254902 | I11: 28 | J11: 25 | K11: 25 | L11: =+K11/J11 -> 1 | M11: 2 | N11: 18 | O11: 0 | P11: =+O11+N11 -> 18 | Q11: 2 | R11: 16 | S11: 2 | T11: =+P11-R11 -> 2 | U11: =+Q11-S11 -> 0 | V11: 31 | W11: 10 | X11: =+W11+V11 -> 41 | Y11: 0 | Z11: 0 | AA11: =+R11-Y11 -> 16 | AB11: =+S11-Z11 -> 2 | AC11: 0 | AD11: 0 | AE11: =+Y11-AC11 -> 0 | AF11: =+Z11-AD11 -> 0 | AG11: 0 | AH11: 0 | AI11: =+AH11+AG11 -> 0 | AJ11: 0 | AK11: 0 | AL11: =+AC11-AJ11 -> 0 | AM11: =+AD11-AK11 -> 0 | AN11: 0 | AO11: 0 | AP11: =+AJ11-AN11 -> 0 | AQ11: =+AK11-AO11 -> 0 | AR11: 0 | AS11: 0 | AT11: =+AS11+AR11 -> 0 | AU11: 0 | AV11: 0 | AW11: =+AN11-AU11 -> 0 | AX11: =+AO11-AV11 -> 0 | AY11: =+P11-AU11 -> 18 | AZ11: =+Q11-AV11 -> 2 | BA11: =+(AY11+AZ11)/(P11+Q11) -> 1 | BB11: =+(AU11+AV11)/E11 -> 0 | BC11: =+AU11/D11 -> 0 | BD11: =IF(AU11>0,"Graduado","En Proceso") -> En Proceso
A12: JOSUE VERA | B12: CUENCA | C12: 5 | D12: 95 | E12: 74 | F12: 74 | G12: 28 | H12: =+G12/F12 -> 0.37837838 | I12: 26 | J12: 26 | K12: 24 | L12: =+K12/J12 -> 0.92307692 | M12: 2 | N12: 23 | O12: 1 | P12: =+O12+N12 -> 24 | Q12: 3 | R12: 23 | S12: 3 | T12: =+P12-R12 -> 1 | U12: =+Q12-S12 -> 0 | V12: 31 | W12: 9 | X12: =+W12+V12 -> 40 | Y12: 19 | Z12: 3 | AA12: =+R12-Y12 -> 4 | AB12: =+S12-Z12 -> 0 | AC12: 17 | AD12: 3 | AE12: =+Y12-AC12 -> 2 | AF12: =+Z12-AD12 -> 0 | AG12: 45 | AH12: 9 | AI12: =+AH12+AG12 -> 54 | AJ12: 15 | AK12: 3 | AL12: =+AC12-AJ12 -> 2 | AM12: =+AD12-AK12 -> 0 | AN12: 15 | AO12: 3 | AP12: =+AJ12-AN12 -> 0 | AQ12: =+AK12-AO12 -> 0 | AR12: 45 | AS12: 12 | AT12: =+AS12+AR12 -> 57 | AU12: 14 | AV12: 3 | AW12: =+AN12-AU12 -> 1 | AX12: =+AO12-AV12 -> 0 | AY12: =+P12-AU12 -> 10 | AZ12: =+Q12-AV12 -> 0 | BA12: =+(AY12+AZ12)/(P12+Q12) -> 0.37037037 | BB12: =+(AU12+AV12)/E12 -> 0.22972973 | BC12: =+AU12/D12 -> 0.14736842 | BD12: =IF(AU12>0,"Graduado","En Proceso") -> Graduado
A13: MAURICIO RAMIREZ | B13: MEDELLIN | C13: 5 | D13: 126 | E13: 81 | F13: 70 | G13: 39 | H13: =+G13/F13 -> 0.55714286 | I13: 0 | J13: 0 | K13: 0 | L13: =+K13/J13 -> #DIV/0! | M13: 0 | N13: 0 | O13: 0 | P13: =+O13+N13 -> 0 | Q13: 0 | R13: 0 | S13: 0 | T13: =+P13-R13 -> 0 | U13: =+Q13-S13 -> 0 | V13: 0 | W13: 0 | X13: =+W13+V13 -> 0 | Y13: 0 | Z13: 0 | AA13: =+R13-Y13 -> 0 | AB13: =+S13-Z13 -> 0 | AC13: 0 | AD13: 0 | AE13: =+Y13-AC13 -> 0 | AF13: =+Z13-AD13 -> 0 | AG13: 0 | AH13: 0 | AI13: =+AH13+AG13 -> 0 | AJ13: 0 | AK13: 0 | AL13: =+AC13-AJ13 -> 0 | AM13: =+AD13-AK13 -> 0 | AN13: 0 | AO13: 0 | AP13: =+AJ13-AN13 -> 0 | AQ13: =+AK13-AO13 -> 0 | AR13: 0 | AS13: 0 | AT13: =+AS13+AR13 -> 0 | AU13: 0 | AV13: 0 | AW13: =+AN13-AU13 -> 0 | AX13: =+AO13-AV13 -> 0 | AY13: =+P13-AU13 -> 0 | AZ13: =+Q13-AV13 -> 0 | BA13: =+(AY13+AZ13)/(P13+Q13) -> #DIV/0! | BB13: =+(AU13+AV13)/E13 -> 0 | BC13: =+AU13/D13 -> 0 | BD13: =IF(AU13>0,"Graduado","En Proceso") -> En Proceso
A14: JOSUE VERA | B14: CUENCA | C14: 6 | D14: 99 | E14: 90 | F14: 74 | G14: 32 | H14: =+G14/F14 -> 0.43243243 | I14: 30 | J14: 23 | K14: 23 | L14: =+K14/J14 -> 1 | M14: 2 | N14: 23 | O14: 1 | P14: =+O14+N14 -> 24 | Q14: 2 | R14: 23 | S14: 2 | T14: =+P14-R14 -> 1 | U14: =+Q14-S14 -> 0 | V14: 52 | W14: 6 | X14: =+W14+V14 -> 58 | Y14: 22 | Z14: 2 | AA14: =+R14-Y14 -> 1 | AB14: =+S14-Z14 -> 0 | AC14: 22 | AD14: 1 | AE14: =+Y14-AC14 -> 0 | AF14: =+Z14-AD14 -> 1 | AG14: 38 | AH14: 3 | AI14: =+AH14+AG14 -> 41 | AJ14: 20 | AK14: 1 | AL14: =+AC14-AJ14 -> 2 | AM14: =+AD14-AK14 -> 0 | AN14: 19 | AO14: 1 | AP14: =+AJ14-AN14 -> 1 | AQ14: =+AK14-AO14 -> 0 | AR14: 36 | AS14: 6 | AT14: =+AS14+AR14 -> 42 | AU14: 19 | AV14: 1 | AW14: =+AN14-AU14 -> 0 | AX14: =+AO14-AV14 -> 0 | AY14: =+P14-AU14 -> 5 | AZ14: =+Q14-AV14 -> 1 | BA14: =+(AY14+AZ14)/(P14+Q14) -> 0.23076923 | BB14: =+(AU14+AV14)/E14 -> 0.22222222 | BC14: =+AU14/D14 -> 0.19191919 | BD14: =IF(AU14>0,"Graduado","En Proceso") -> Graduado
A15: JOSE SANCHEZ | B15: LIMA | C15: 6 | D15: 58 | E15: 36 | F15: 35 | G15: 11 | H15: =+G15/F15 -> 0.31428571 | I15: 10 | J15: 10 | K15: 9 | L15: =+K15/J15 -> 0.9 | M15: 3 | N15: 7 | P15: =+O15+N15 -> 7 | Q15: 3 | R15: 5 | S15: 3 | T15: =+P15-R15 -> 2 | U15: =+Q15-S15 -> 0 | V15: 5 | W15: 17 | X15: =+W15+V15 -> 22 | Y15: 3 | Z15: 3 | AA15: =+R15-Y15 -> 2 | AB15: =+S15-Z15 -> 0 | AC15: 3 | AD15: 3 | AE15: =+Y15-AC15 -> 0 | AF15: =+Z15-AD15 -> 0 | AG15: 5 | AH15: 16 | AI15: =+AH15+AG15 -> 21 | AJ15: 0 | AK15: 2 | AL15: =+AC15-AJ15 -> 3 | AM15: =+AD15-AK15 -> 1 | AN15: 0 | AO15: 2 | AP15: =+AJ15-AN15 -> 0 | AQ15: =+AK15-AO15 -> 0 | AR15: 0 | AS15: 12 | AT15: =+AS15+AR15 -> 12 | AU15: 0 | AV15: 2 | AW15: =+AN15-AU15 -> 0 | AX15: =+AO15-AV15 -> 0 | AY15: =+P15-AU15 -> 7 | AZ15: =+Q15-AV15 -> 1 | BA15: =+(AY15+AZ15)/(P15+Q15) -> 0.8 | BB15: =+(AU15+AV15)/E15 -> 0.055555556 | BC15: =+AU15/D15 -> 0 | BD15: Graduado
A16: JOSUE VERA | B16: CUENCA | C16: 7 | D16: 122 | E16: 114 | F16: 105 | G16: 54 | H16: =+G16/F16 -> 0.51428571 | I16: 48 | J16: 44 | K16: 44 | L16: =+K16/J16 -> 1 | M16: 3 | N16: 43 | O16: 1 | P16: =+O16+N16 -> 44 | Q16: 2 | R16: 44 | S16: 2 | T16: =+P16-R16 -> 0 | U16: =+Q16-S16 -> 0 | V16: 87 | W16: 8 | X16: =+W16+V16 -> 95 | Y16: 36 | Z16: 2 | AA16: =+R16-Y16 -> 8 | AB16: =+S16-Z16 -> 0 | AC16: 33 | AD16: 2 | AE16: =+Y16-AC16 -> 3 | AF16: =+Z16-AD16 -> 0 | AG16: 48 | AH16: 10 | AI16: =+AH16+AG16 -> 58 | AJ16: 33 | AK16: 2 | AL16: =+AC16-AJ16 -> 0 | AM16: =+AD16-AK16 -> 0 | AN16: 29 | AO16: 2 | AP16: =+AJ16-AN16 -> 4 | AQ16: =+AK16-AO16 -> 0 | AR16: 54 | AS16: 7 | AT16: =+AS16+AR16 -> 61 | AU16: 33 | AV16: 2 | AW16: =+AN16-AU16 -> -4 | AX16: =+AO16-AV16 -> 0 | AY16: =+P16-AU16 -> 11 | AZ16: =+Q16-AV16 -> 0 | BA16: =+(AY16+AZ16)/(P16+Q16) -> 0.23913043 | BB16: =+(AU16+AV16)/E16 -> 0.30701754 | BC16: =+AU16/D16 -> 0.2704918 | BD16: =IF(AU16>0,"Graduado","En Proceso") -> Graduado
A17: JOSE SANCHEZ | B17: LIMA | C17: 7 | D17: 79 | E17: 58 | F17: 45 | G17: 25 | H17: =+G17/F17 -> 0.55555556 | I17: 22 | J17: 20 | K17: 20 | L17: =+K17/J17 -> 1 | M17: 3 | N17: 17 | P17: =+O17+N17 -> 17 | Q17: 3 | R17: 16 | S17: 3 | T17: =+P17-R17 -> 1 | U17: =+Q17-S17 -> 0 | V17: 26 | W17: 8 | X17: =+W17+V17 -> 34 | Y17: 14 | Z17: 2 | AA17: =+R17-Y17 -> 2 | AB17: =+S17-Z17 -> 1 | AC17: 14 | AD17: 2 | AE17: =+Y17-AC17 -> 0 | AF17: =+Z17-AD17 -> 0 | AG17: 16 | AH17: 4 | AI17: =+AH17+AG17 -> 20 | AJ17: 9 | AK17: 3 | AL17: =+AC17-AJ17 -> 5 | AM17: =+AD17-AK17 -> -1 | AN17: 9 | AO17: 3 | AP17: =+AJ17-AN17 -> 0 | AQ17: =+AK17-AO17 -> 0 | AR17: 16 | AS17: 17 | AT17: =+AS17+AR17 -> 33 | AU17: 8 | AV17: 3 | AW17: =+AN17-AU17 -> 1 | AX17: =+AO17-AV17 -> 0 | AY17: =+P17-AU17 -> 9 | AZ17: =+Q17-AV17 -> 0 | BA17: =+(AY17+AZ17)/(P17+Q17) -> 0.45 | BB17: =+(AU17+AV17)/E17 -> 0.18965517 | BC17: =+AU17/D17 -> 0.10126582 | BD17: =IF(AU17>0,"Graduado","En Proceso") -> Graduado
A18: JOSUE VERA - KERLY CARRILLO | B18: CUENCA | C18: 8 | D18: 190 | E18: 150 | F18: 130 | G18: 55 | H18: =+G18/F18 -> 0.42307692 | I18: 55 | J18: 47 | K18: 44 | L18: =+K18/J18 -> 0.93617021 | M18: 3 | N18: 37 | O18: 0 | P18: =+O18+N18 -> 37 | Q18: 3 | R18: 37 | S18: 3 | T18: =+P18-R18 -> 0 | U18: =+Q18-S18 -> 0 | V18: 37 | W18: 10 | X18: =+W18+V18 -> 47 | Y18: 31 | Z18: 2 | AA18: =+R18-Y18 -> 6 | AB18: =+S18-Z18 -> 1 | AC18: 30 | AD18: 2 | AE18: =+Y18-AC18 -> 1 | AF18: =+Z18-AD18 -> 0 | AG18: 34 | AH18: 10 | AI18: =+AH18+AG18 -> 44 | AJ18: 27 | AK18: 2 | AL18: =+AC18-AJ18 -> 3 | AM18: =+AD18-AK18 -> 0 | AP18: =+AJ18-AN18 -> 27 | AQ18: =+AK18-AO18 -> 2 | AR18: 41 | AS18: 10 | AT18: =+AS18+AR18 -> 51 | AU18: 23 | AV18: 2 | AW18: =+AN18-AU18 -> -23 | AX18: =+AO18-AV18 -> -2 | AY18: =+P18-AU18 -> 14 | AZ18: =+Q18-AV18 -> 1 | BA18: =+(AY18+AZ18)/(P18+Q18) -> 0.375 | BB18: =+(AU18+AV18)/E18 -> 0.16666667 | BC18: =+AU18/D18 -> 0.12105263 | BD18: =IF(AU18>0,"Graduado","En Proceso") -> Graduado
A19: JOSE SANCHEZ | B19: LIMA | C19: 8 | D19: 79 | E19: 50 | F19: 45 | G19: 32 | H19: =+G19/F19 -> 0.71111111 | I19: 28 | J19: 21 | K19: 21 | L19: =+K19/J19 -> 1 | M19: 10 | N19: 17 | P19: =+O19+N19 -> 17 | Q19: 8 | R19: 14 | S19: 8 | T19: =+P19-R19 -> 3 | U19: =+Q19-S19 -> 0 | V19: 25 | W19: 29 | X19: =+W19+V19 -> 54 | Y19: 10 | Z19: 8 | AA19: =+R19-Y19 -> 4 | AB19: =+S19-Z19 -> 0 | AC19: 10 | AD19: 7 | AE19: =+Y19-AC19 -> 0 | AF19: =+Z19-AD19 -> 1 | AG19: 21 | AH19: 22 | AI19: =+AH19+AG19 -> 43 | AJ19: 9 | AK19: 5 | AL19: =+AC19-AJ19 -> 1 | AM19: =+AD19-AK19 -> 2 | AN19: 7 | AO19: 5 | AP19: =+AJ19-AN19 -> 2 | AQ19: =+AK19-AO19 -> 0 | AR19: 19 | AS19: 11 | AT19: =+AS19+AR19 -> 30 | AU19: 7 | AV19: 5 | AW19: =+AN19-AU19 -> 0 | AX19: =+AO19-AV19 -> 0 | AY19: =+P19-AU19 -> 10 | AZ19: =+Q19-AV19 -> 3 | BA19: =+(AY19+AZ19)/(P19+Q19) -> 0.52 | BB19: =+(AU19+AV19)/E19 -> 0.24 | BC19: =+AU19/D19 -> 0.088607595 | BD19: =IF(AU19>0,"Graduado","En Proceso") -> Graduado
A20: KERLY CARRILLO | B20: CUENCA | C20: 9 | D20: 148 | E20: 127 | F20: 115 | G20: 56 | H20: =+G20/F20 -> 0.48695652 | I20: 57 | J20: 56 | K20: 52 | L20: =+K20/J20 -> 0.92857143 | M20: 2 | N20: 47 | O20: 0 | P20: =+O20+N20 -> 47 | Q20: 2 | R20: 38 | S20: 2 | T20: =+P20-R20 -> 9 | U20: =+Q20-S20 -> 0 | V20: 38 | W20: 10 | X20: =+W20+V20 -> 48 | Y20: 35 | Z20: 2 | AA20: =+R20-Y20 -> 3 | AB20: =+S20-Z20 -> 0 | AC20: 32 | AD20: 2 | AE20: =+Y20-AC20 -> 3 | AF20: =+Z20-AD20 -> 0 | AG20: 39 | AH20: 7 | AI20: =+AH20+AG20 -> 46 | AL20: =+AC20-AJ20 -> 32 | AM20: =+AD20-AK20 -> 2 | AP20: =+AJ20-AN20 -> 0 | AQ20: =+AK20-AO20 -> 0 | AT20: =+AS20+AR20 -> 0 | AW20: =+AN20-AU20 -> 0 | AX20: =+AO20-AV20 -> 0 | AY20: =+P20-AU20 -> 47 | AZ20: =+Q20-AV20 -> 2 | BA20: =+(AY20+AZ20)/(P20+Q20) -> 1 | BB20: =+(AU20+AV20)/E20 -> 0 | BC20: =+AU20/D20 -> 0 | BD20: =IF(AU20>0,"Graduado","En Proceso") -> En Proceso
A21: JOSE SANCHEZ | B21: LIMA | C21: 9 | D21: 74 | E21: 67 | F21: 60 | G21: 24 | H21: =+G21/F21 -> 0.4 | I21: 22 | J21: 17 | K21: 17 | L21: =+K21/J21 -> 1 | M21: 5 | N21: 15 | P21: =+O21+N21 -> 15 | Q21: 4 | R21: 12 | S21: 3 | T21: =+P21-R21 -> 3 | U21: =+Q21-S21 -> 1 | V21: 21 | W21: 15 | X21: =+W21+V21 -> 36 | Y21: 6 | Z21: 3 | AA21: =+R21-Y21 -> 6 | AB21: =+S21-Z21 -> 0 | AC21: 6 | AD21: 3 | AE21: =+Y21-AC21 -> 0 | AF21: =+Z21-AD21 -> 0 | AG21: 19 | AH21: 14 | AI21: =+AH21+AG21 -> 33 | AJ21: 6 | AK21: 3 | AL21: =+AC21-AJ21 -> 0 | AM21: =+AD21-AK21 -> 0 | AN21: 5 | AO21: 3 | AP21: =+AJ21-AN21 -> 1 | AQ21: =+AK21-AO21 -> 0 | AR21: 19 | AS21: 20 | AT21: =+AS21+AR21 -> 39 | AU21: 4 | AV21: 3 | AW21: =+AN21-AU21 -> 1 | AX21: =+AO21-AV21 -> 0 | AY21: =+P21-AU21 -> 11 | AZ21: =+Q21-AV21 -> 1 | BA21: =+(AY21+AZ21)/(P21+Q21) -> 0.63157895 | BB21: =+(AU21+AV21)/E21 -> 0.10447761 | BC21: =+AU21/D21 -> 0.054054054 | BD21: =IF(AU21>0,"Graduado","En Proceso") -> Graduado
A22: KERLY CARRILLO | B22: CUENCA | C22: 10 | D22: 154 | E22: 138 | F22: 127 | G22: 59 | H22: =+G22/F22 -> 0.46456693 | I22: 63 | J22: 55 | K22: 49 | L22: =+K22/J22 -> 0.89090909 | M22: 4 | N22: 34 | O22: 2 | P22: =+O22+N22 -> 36 | Q22: 2 | R22: 36 | S22: 2 | T22: =+P22-R22 -> 0 | U22: =+Q22-S22 -> 0 | V22: 51 | W22: 10 | X22: =+W22+V22 -> 61 | AA22: =+R22-Y22 -> 36 | AB22: =+S22-Z22 -> 2 | AE22: =+Y22-AC22 -> 0 | AF22: =+Z22-AD22 -> 0 | AI22: =+AH22+AG22 -> 0 | AL22: =+AC22-AJ22 -> 0 | AM22: =+AD22-AK22 -> 0 | AP22: =+AJ22-AN22 -> 0 | AQ22: =+AK22-AO22 -> 0 | AT22: =+AS22+AR22 -> 0 | AW22: =+AN22-AU22 -> 0 | AX22: =+AO22-AV22 -> 0 | AY22: =+P22-AU22 -> 36 | AZ22: =+Q22-AV22 -> 2 | BA22: =+(AY22+AZ22)/(P22+Q22) -> 1 | BB22: =+(AU22+AV22)/E22 -> 0 | BC22: =+AU22/D22 -> 0 | BD22: =IF(AU22>0,"Graduado","En Proceso") -> En Proceso
A23: JOSE SANCHEZ | B23: LIMA | C23: 10 | D23: 112 | E23: 82 | F23: 65 | G23: 36 | H23: =+G23/F23 -> 0.55384615 | I23: 34 | J23: 26 | K23: 26 | L23: =+K23/J23 -> 1 | M23: 1 | N23: 24 | P23: =+O23+N23 -> 24 | Q23: 1 | R23: 23 | S23: 1 | T23: =+P23-R23 -> 1 | U23: =+Q23-S23 -> 0 | V23: 22 | W23: 5 | X23: =+W23+V23 -> 27 | Y23: 20 | Z23: 1 | AA23: =+R23-Y23 -> 3 | AB23: =+S23-Z23 -> 0 | AC23: 16 | AD23: 0 | AE23: =+Y23-AC23 -> 4 | AF23: =+Z23-AD23 -> 1 | AG23: 22 | AH23: 1 | AI23: =+AH23+AG23 -> 23 | AJ23: 16 | AK23: 1 | AL23: =+AC23-AJ23 -> 0 | AM23: =+AD23-AK23 -> -1 | AN23: 15 | AO23: 1 | AP23: =+AJ23-AN23 -> 1 | AQ23: =+AK23-AO23 -> 0 | AR23: 33 | AS23: 5 | AT23: =+AS23+AR23 -> 38 | AU23: 12 | AV23: 1 | AW23: =+AN23-AU23 -> 3 | AX23: =+AO23-AV23 -> 0 | AY23: =+P23-AU23 -> 12 | AZ23: =+Q23-AV23 -> 0 | BA23: =+(AY23+AZ23)/(P23+Q23) -> 0.48 | BB23: =+(AU23+AV23)/E23 -> 0.15853659 | BC23: =+AU23/D23 -> 0.10714286 | BD23: =IF(AU23>0,"Graduado","En Proceso") -> Graduado
A24: KERLY CARRILLO | B24: CUENCA | C24: 11 | D24: 158 | E24: 124 | F24: 114 | G24: 49 | H24: =+G24/F24 -> 0.42982456 | L24: =+K24/J24 -> #DIV/0! | P24: =+O24+N24 -> 0 | T24: =+P24-R24 -> 0 | U24: =+Q24-S24 -> 0 | X24: =+W24+V24 -> 0 | AA24: =+R24-Y24 -> 0 | AB24: =+S24-Z24 -> 0 | AE24: =+Y24-AC24 -> 0 | AF24: =+Z24-AD24 -> 0 | AI24: =+AH24+AG24 -> 0 | AL24: =+AC24-AJ24 -> 0 | AM24: =+AD24-AK24 -> 0 | AP24: =+AJ24-AN24 -> 0 | AQ24: =+AK24-AO24 -> 0 | AT24: =+AS24+AR24 -> 0 | AW24: =+AN24-AU24 -> 0 | AX24: =+AO24-AV24 -> 0 | AY24: =+P24-AU24 -> 0 | AZ24: =+Q24-AV24 -> 0 | BA24: =+(AY24+AZ24)/(P24+Q24) -> #DIV/0! | BB24: =+(AU24+AV24)/E24 -> 0 | BC24: =+AU24/D24 -> 0 | BD24: =IF(AU24>0,"Graduado","En Proceso") -> En Proceso
A25: JOSE SANCHEZ | B25: LIMA | C25: 11 | D25: 90 | E25: 65 | F25: 56 | G25: 31 | H25: =+G25/F25 -> 0.55357143 | I25: 24 | J25: 20 | K25: 20 | L25: =+K25/J25 -> 1 | M25: 3 | N25: 19 | O25: 2 | P25: =+O25+N25 -> 21 | Q25: 3 | R25: 19 | S25: 3 | T25: =+P25-R25 -> 2 | U25: =+Q25-S25 -> 0 | V25: 36 | W25: 15 | X25: =+W25+V25 -> 51 | Y25: 18 | Z25: 3 | AA25: =+R25-Y25 -> 1 | AB25: =+S25-Z25 -> 0 | AC25: 17 | AD25: 3 | AE25: =+Y25-AC25 -> 1 | AF25: =+Z25-AD25 -> 0 | AG25: 30 | AH25: 10 | AI25: =+AH25+AG25 -> 40 | AJ25: 16 | AK25: 3 | AL25: =+AC25-AJ25 -> 1 | AM25: =+AD25-AK25 -> 0 | AN25: 15 | AO25: 3 | AP25: =+AJ25-AN25 -> 1 | AQ25: =+AK25-AO25 -> 0 | AR25: 35 | AS25: 12 | AT25: =+AS25+AR25 -> 47 | AU25: 14 | AV25: 3 | AW25: =+AN25-AU25 -> 1 | AX25: =+AO25-AV25 -> 0 | AY25: =+P25-AU25 -> 7 | AZ25: =+Q25-AV25 -> 0 | BA25: =+(AY25+AZ25)/(P25+Q25) -> 0.29166667 | BB25: =+(AU25+AV25)/E25 -> 0.26153846 | BC25: =+AU25/D25 -> 0.15555556 | BD25: =IF(AU25>0,"Graduado","En Proceso") -> Graduado
A26: JOSE SANCHEZ | B26: LIMA | C26: 12 | D26: 113 | E26: 69 | F26: 58 | G26: 29 | H26: =+G26/F26 -> 0.5 | I26: 30 | J26: 29 | K26: 29 | L26: =+K26/J26 -> 1 | M26: 7 | N26: 26 | O26: 1 | P26: =+O26+N26 -> 27 | Q26: 6 | R26: 26 | S26: 5 | T26: =+P26-R26 -> 1 | U26: =+Q26-S26 -> 1 | V26: 37 | W26: 20 | X26: =+W26+V26 -> 57 | Y26: 24 | Z26: 5 | AA26: =+R26-Y26 -> 2 | AB26: =+S26-Z26 -> 0 | AC26: 23 | AD26: 5 | AE26: =+Y26-AC26 -> 1 | AF26: =+Z26-AD26 -> 0 | AG26: 54 | AH26: 15 | AI26: =+AH26+AG26 -> 69 | AJ26: 21 | AK26: 5 | AL26: =+AC26-AJ26 -> 2 | AM26: =+AD26-AK26 -> 0 | AN26: 21 | AO26: 5 | AP26: =+AJ26-AN26 -> 0 | AQ26: =+AK26-AO26 -> 0 | AR26: 57 | AS26: 23 | AT26: =+AS26+AR26 -> 80 | AU26: 18 | AV26: 5 | AW26: =+AN26-AU26 -> 3 | AX26: =+AO26-AV26 -> 0 | AY26: =+P26-AU26 -> 9 | AZ26: =+Q26-AV26 -> 1 | BA26: =+(AY26+AZ26)/(P26+Q26) -> 0.3030303 | BB26: =+(AU26+AV26)/E26 -> 0.33333333 | BC26: =+AU26/D26 -> 0.15929204 | BD26: =IF(AU26>0,"Graduado","En Proceso") -> Graduado
A27: ALEJANDRO DIAZ | B27: GUAYAQUIL | C27: 13 | D27: 185 | E27: 131 | F27: 87 | G27: 39 | H27: =+G27/F27 -> 0.44827586 | I27: 44 | J27: 40 | K27: 32 | L27: =+K27/J27 -> 0.8 | M27: 7 | N27: 31 | P27: =+O27+N27 -> 31 | Q27: 2 | R27: 31 | S27: 1 | T27: =+P27-R27 -> 0 | U27: =+Q27-S27 -> 1 | V27: 25 | W27: 5 | X27: =+W27+V27 -> 30 | Y27: 20 | Z27: 2 | AA27: =+R27-Y27 -> 11 | AB27: =+S27-Z27 -> -1 | AC27: 20 | AD27: 1 | AE27: =+Y27-AC27 -> 0 | AF27: =+Z27-AD27 -> 1 | AG27: 25 | AH27: 5 | AI27: =+AH27+AG27 -> 30 | AJ27: 18 | AK27: 1 | AL27: =+AC27-AJ27 -> 2 | AM27: =+AD27-AK27 -> 0 | AN27: 17 | AO27: 1 | AP27: =+AJ27-AN27 -> 1 | AQ27: =+AK27-AO27 -> 0 | AR27: 44 | AS27: 3 | AT27: =+AS27+AR27 -> 47 | AU27: 13 | AV27: 1 | AW27: =+AN27-AU27 -> 4 | AX27: =+AO27-AV27 -> 0 | AY27: =+P27-AU27 -> 18 | AZ27: =+Q27-AV27 -> 1 | BA27: =+(AY27+AZ27)/(P27+Q27) -> 0.57575758 | BB27: =+(AU27+AV27)/E27 -> 0.10687023 | BC27: =+AU27/D27 -> 0.07027027 | BD27: =IF(AU27>0,"Graduado","En Proceso") -> Graduado
A28: JOSE SANCHEZ | B28: LIMA | C28: 13 | D28: 130 | E28: 102 | F28: 90 | G28: 43 | H28: =+G28/F28 -> 0.47777778 | I28: 40 | J28: 36 | K28: 36 | L28: =+K28/J28 -> 1 | M28: 22 | N28: 35 | O28: 2 | P28: =+O28+N28 -> 37 | Q28: 2 | R28: 36 | S28: 2 | T28: =+P28-R28 -> 1 | U28: =+Q28-S28 -> 0 | V28: 48 | W28: 11 | X28: =+W28+V28 -> 59 | Y28: 27 | Z28: 3 | AA28: =+R28-Y28 -> 9 | AB28: =+S28-Z28 -> -1 | AC28: 26 | AD28: 3 | AE28: =+Y28-AC28 -> 1 | AF28: =+Z28-AD28 -> 0 | AG28: 45 | AH28: 13 | AI28: =+AH28+AG28 -> 58 | AJ28: 24 | AK28: 3 | AL28: =+AC28-AJ28 -> 2 | AM28: =+AD28-AK28 -> 0 | AN28: 22 | AO28: 3 | AP28: =+AJ28-AN28 -> 2 | AQ28: =+AK28-AO28 -> 0 | AR28: 53 | AS28: 14 | AT28: =+AS28+AR28 -> 67 | AU28: 21 | AV28: 3 | AW28: =+AN28-AU28 -> 1 | AX28: =+AO28-AV28 -> 0 | AY28: =+P28-AU28 -> 16 | AZ28: =+Q28-AV28 -> -1 | BA28: =+(AY28+AZ28)/(P28+Q28) -> 0.38461538 | BB28: =+(AU28+AV28)/E28 -> 0.23529412 | BC28: =+AU28/D28 -> 0.16153846 | BD28: =IF(AU28>0,"Graduado","En Proceso") -> Graduado
A29: ALEJANDRO DIAZ | B29: GUAYAQUIL | C29: 14 | D29: 158 | E29: 142 | F29: 108 | G29: 32 | H29: =+G29/F29 -> 0.2962963 | I29: 38 | J29: 38 | K29: 29 | L29: =+K29/J29 -> 0.76315789 | M29: 9 | N29: 29 | O29: 1 | P29: =+O29+N29 -> 30 | Q29: 7 | R29: 28 | S29: 7 | T29: =+P29-R29 -> 2 | U29: =+Q29-S29 -> 0 | V29: 50 | W29: 24 | X29: =+W29+V29 -> 74 | Y29: 22 | Z29: 7 | AA29: =+R29-Y29 -> 6 | AB29: =+S29-Z29 -> 0 | AC29: 22 | AD29: 5 | AE29: =+Y29-AC29 -> 0 | AF29: =+Z29-AD29 -> 2 | AG29: 38 | AH29: 17 | AI29: =+AH29+AG29 -> 55 | AJ29: 19 | AK29: 4 | AL29: =+AC29-AJ29 -> 3 | AM29: =+AD29-AK29 -> 1 | AN29: 17 | AO29: 4 | AP29: =+AJ29-AN29 -> 2 | AQ29: =+AK29-AO29 -> 0 | AR29: 53 | AS29: 18 | AT29: =+AS29+AR29 -> 71 | AU29: 16 | AV29: 4 | AW29: =+AN29-AU29 -> 1 | AX29: =+AO29-AV29 -> 0 | AY29: =+P29-AU29 -> 14 | AZ29: =+Q29-AV29 -> 3 | BA29: =+(AY29+AZ29)/(P29+Q29) -> 0.45945946 | BB29: =+(AU29+AV29)/E29 -> 0.14084507 | BC29: =+AU29/D29 -> 0.10126582 | BD29: =IF(AU29>0,"Graduado","En Proceso") -> Graduado
A30: LINID VALENCIA | B30: LIMA | C30: 14 | D30: 176 | E30: 129 | F30: 105 | G30: 39 | H30: =+G30/F30 -> 0.37142857 | I30: 31 | J30: 30 | K30: 27 | L30: =+K30/J30 -> 0.9 | M30: 12 | N30: 21 | O30: 2 | P30: =+O30+N30 -> 23 | Q30: 9 | R30: 23 | S30: 8 | T30: =+P30-R30 -> 0 | U30: =+Q30-S30 -> 1 | V30: 43 | W30: 34 | X30: =+W30+V30 -> 77 | Y30: 22 | Z30: 8 | AA30: =+R30-Y30 -> 1 | AB30: =+S30-Z30 -> 0 | AC30: 22 | AD30: 7 | AE30: =+Y30-AC30 -> 0 | AF30: =+Z30-AD30 -> 1 | AG30: 43 | AH30: 20 | AI30: =+AH30+AG30 -> 63 | AJ30: 21 | AK30: 7 | AL30: =+AC30-AJ30 -> 1 | AM30: =+AD30-AK30 -> 0 | AN30: 18 | AO30: 7 | AP30: =+AJ30-AN30 -> 3 | AQ30: =+AK30-AO30 -> 0 | AR30: 43 | AS30: 28 | AT30: =+AS30+AR30 -> 71 | AU30: 16 | AV30: 7 | AW30: =+AN30-AU30 -> 2 | AX30: =+AO30-AV30 -> 0 | AY30: =+P30-AU30 -> 7 | AZ30: =+Q30-AV30 -> 2 | BA30: =+(AY30+AZ30)/(P30+Q30) -> 0.28125 | BB30: =+(AU30+AV30)/E30 -> 0.17829457 | BC30: =+AU30/D30 -> 0.090909091 | BD30: =IF(AU30>0,"Graduado","En Proceso") -> Graduado
A31: BENDA RODRIGUEZ | B31: GUAYAQUIL | C31: 15 | D31: 165 | E31: 145 | F31: 130 | G31: 63 | H31: =+G31/F31 -> 0.48461538 | I31: 58 | J31: 54 | K31: 47 | L31: =+K31/J31 -> 0.87037037 | M31: 13 | N31: 44 | O31: 1 | P31: =+O31+N31 -> 45 | Q31: 4 | R31: 44 | S31: 4 | T31: =+P31-R31 -> 1 | U31: =+Q31-S31 -> 0 | V31: 55 | W31: 14 | X31: =+W31+V31 -> 69 | Y31: 39 | Z31: 4 | AA31: =+R31-Y31 -> 5 | AB31: =+S31-Z31 -> 0 | AC31: 38 | AD31: 4 | AE31: =+Y31-AC31 -> 1 | AF31: =+Z31-AD31 -> 0 | AG31: 70 | AH31: 9 | AI31: =+AH31+AG31 -> 79 | AJ31: 32 | AK31: 4 | AL31: =+AC31-AJ31 -> 6 | AM31: =+AD31-AK31 -> 0 | AN31: 32 | AO31: 4 | AP31: =+AJ31-AN31 -> 0 | AQ31: =+AK31-AO31 -> 0 | AR31: 105 | AS31: 20 | AT31: =+AS31+AR31 -> 125 | AU31: 32 | AV31: 4 | AW31: =+AN31-AU31 -> 0 | AX31: =+AO31-AV31 -> 0 | AY31: =+P31-AU31 -> 13 | AZ31: =+Q31-AV31 -> 0 | BA31: =+(AY31+AZ31)/(P31+Q31) -> 0.26530612 | BB31: =+(AU31+AV31)/E31 -> 0.24827586 | BC31: =+AU31/D31 -> 0.19393939 | BD31: =IF(AU31>0,"Graduado","En Proceso") -> Graduado
A32: LINID VALENCIA | B32: LIMA | C32: 15 | D32: 215 | E32: 143 | F32: 124 | G32: 56 | H32: =+G32/F32 -> 0.4516129 | I32: 56 | J32: 54 | K32: 52 | L32: =+K32/J32 -> 0.96296296 | M32: 13 | N32: 47 | O32: 2 | P32: =+O32+N32 -> 49 | Q32: 11 | R32: 42 | S32: 8 | T32: =+P32-R32 -> 7 | U32: =+Q32-S32 -> 3 | V32: 131 | W32: 49 | X32: =+W32+V32 -> 180 | Y32: 34 | Z32: 8 | AA32: =+R32-Y32 -> 8 | AB32: =+S32-Z32 -> 0 | AC32: 34 | AD32: 8 | AE32: =+Y32-AC32 -> 0 | AF32: =+Z32-AD32 -> 0 | AG32: 85 | AH32: 24 | AI32: =+AH32+AG32 -> 109 | AJ32: 30 | AK32: 7 | AL32: =+AC32-AJ32 -> 4 | AM32: =+AD32-AK32 -> 1 | AN32: 29 | AO32: 7 | AP32: =+AJ32-AN32 -> 1 | AQ32: =+AK32-AO32 -> 0 | AR32: 57 | AS32: 23 | AT32: =+AS32+AR32 -> 80 | AU32: 29 | AV32: 7 | AW32: =+AN32-AU32 -> 0 | AX32: =+AO32-AV32 -> 0 | AY32: =+P32-AU32 -> 20 | AZ32: =+Q32-AV32 -> 4 | BA32: =+(AY32+AZ32)/(P32+Q32) -> 0.4 | BB32: =+(AU32+AV32)/E32 -> 0.25174825 | BC32: =+AU32/D32 -> 0.13488372 | BD32: =IF(AU32>0,"Graduado","En Proceso") -> Graduado
A33: BRENDA RODRIGUEZ | B33: GUAYAQUIL | C33: 16 | D33: 171 | E33: 123 | F33: 114 | G33: 35 | H33: =+G33/F33 -> 0.30701754 | I33: 36 | J33: 33 | K33: 31 | L33: =+K33/J33 -> 0.93939394 | M33: 7 | N33: 24 | O33: 2 | P33: =+O33+N33 -> 26 | Q33: 3 | R33: 22 | S33: 3 | T33: =+P33-R33 -> 4 | U33: =+Q33-S33 -> 0 | V33: 24 | W33: 12 | X33: =+W33+V33 -> 36 | Y33: 19 | Z33: 2 | AA33: =+R33-Y33 -> 3 | AB33: =+S33-Z33 -> 1 | AC33: 19 | AD33: 1 | AE33: =+Y33-AC33 -> 0 | AF33: =+Z33-AD33 -> 1 | AG33: 25 | AH33: 10 | AI33: =+AH33+AG33 -> 35 | AJ33: 14 | AK33: 2 | AL33: =+AC33-AJ33 -> 5 | AM33: =+AD33-AK33 -> -1 | AN33: 14 | AO33: 2 | AP33: =+AJ33-AN33 -> 0 | AQ33: =+AK33-AO33 -> 0 | AR33: 20 | AS33: 9 | AT33: =+AS33+AR33 -> 29 | AU33: 10 | AV33: 2 | AW33: =+AN33-AU33 -> 4 | AX33: =+AO33-AV33 -> 0 | AY33: =+P33-AU33 -> 16 | AZ33: =+Q33-AV33 -> 1 | BA33: =+(AY33+AZ33)/(P33+Q33) -> 0.5862069 | BB33: =+(AU33+AV33)/E33 -> 0.097560976 | BC33: =+AU33/D33 -> 0.058479532 | BD33: =IF(AU33>0,"Graduado","En Proceso") -> Graduado
A34: LINID VALENCIA | B34: LIMA | C34: 16 | D34: 180 | E34: 138 | F34: 110 | G34: 33 | H34: =+G34/F34 -> 0.3 | I34: 33 | J34: 32 | K34: 32 | L34: =+K34/J34 -> 1 | M34: 4 | N34: 30 | O34: 3 | P34: =+O34+N34 -> 33 | Q34: 3 | R34: 33 | S34: 3 | T34: =+P34-R34 -> 0 | U34: =+Q34-S34 -> 0 | V34: 37 | W34: 8 | X34: =+W34+V34 -> 45 | Y34: 31 | Z34: 3 | AA34: =+R34-Y34 -> 2 | AB34: =+S34-Z34 -> 0 | AC34: 28 | AD34: 3 | AE34: =+Y34-AC34 -> 3 | AF34: =+Z34-AD34 -> 0 | AG34: 39 | AH34: 9 | AI34: =+AH34+AG34 -> 48 | AL34: =+AC34-AJ34 -> 28 | AM34: =+AD34-AK34 -> 3 | AP34: =+AJ34-AN34 -> 0 | AQ34: =+AK34-AO34 -> 0 | AT34: =+AS34+AR34 -> 0 | AU34: 24 | AV34: 3 | AW34: =+AN34-AU34 -> -24 | AX34: =+AO34-AV34 -> -3 | AY34: =+P34-AU34 -> 9 | AZ34: =+Q34-AV34 -> 0 | BA34: =+(AY34+AZ34)/(P34+Q34) -> 0.25 | BB34: =+(AU34+AV34)/E34 -> 0.19565217 | BC34: =+AU34/D34 -> 0.13333333 | BD34: =IF(AU34>0,"Graduado","En Proceso") -> Graduado
A35: BRENDA RODRIGUEZ | B35: GUAYAQUIL | C35: 17 | D35: 186 | E35: 171 | F35: 143 | G35: 45 | H35: =+G35/F35 -> 0.31468531 | I35: 41 | J35: 38 | K35: 27 | L35: =+K35/J35 -> 0.71052632 | M35: 10 | N35: 23 | O35: 5 | P35: =+O35+N35 -> 28 | Q35: 4 | R35: 22 | S35: 4 | T35: =+P35-R35 -> 6 | U35: =+Q35-S35 -> 0 | V35: 38 | W35: 15 | X35: =+W35+V35 -> 53 | Y35: 18 | Z35: 4 | AA35: =+R35-Y35 -> 4 | AB35: =+S35-Z35 -> 0 | AC35: 17 | AD35: 3 | AE35: =+Y35-AC35 -> 1 | AF35: =+Z35-AD35 -> 1 | AG35: 29 | AH35: 12 | AI35: =+AH35+AG35 -> 41 | AL35: =+AC35-AJ35 -> 17 | AM35: =+AD35-AK35 -> 3 | AP35: =+AJ35-AN35 -> 0 | AQ35: =+AK35-AO35 -> 0 | AT35: =+AS35+AR35 -> 0 | AW35: =+AN35-AU35 -> 0 | AX35: =+AO35-AV35 -> 0 | AY35: =+P35-AU35 -> 28 | AZ35: =+Q35-AV35 -> 4 | BA35: =+(AY35+AZ35)/(P35+Q35) -> 1 | BB35: =+(AU35+AV35)/E35 -> 0 | BC35: =+AU35/D35 -> 0 | BD35: =IF(AU35>0,"Graduado","En Proceso") -> En Proceso
A36: LINID VALENCIA | B36: LIMA | C36: 17 | D36: 228 | E36: 153 | F36: 120 | G36: 52 | H36: =+G36/F36 -> 0.43333333 | I36: 45 | J36: 39 | K36: 39 | L36: =+K36/J36 -> 1 | M36: 16 | N36: 33 | O36: 2 | P36: =+O36+N36 -> 35 | Q36: 15 | R36: 33 | S36: 12 | T36: =+P36-R36 -> 2 | U36: =+Q36-S36 -> 3 | V36: 61 | W36: 58 | X36: =+W36+V36 -> 119 | Y36: 29 | Z36: 12 | AA36: =+R36-Y36 -> 4 | AB36: =+S36-Z36 -> 0 | AC36: 27 | AD36: 11 | AE36: =+Y36-AC36 -> 2 | AF36: =+Z36-AD36 -> 1 | AG36: 67 | AH36: 34 | AI36: =+AH36+AG36 -> 101 | AJ36: 27 | AK36: 11 | AL36: =+AC36-AJ36 -> 0 | AM36: =+AD36-AK36 -> 0 | AN36: 26 | AO36: 10 | AP36: =+AJ36-AN36 -> 1 | AQ36: =+AK36-AO36 -> 1 | AR36: 70 | AS36: 41 | AT36: =+AS36+AR36 -> 111 | AU36: 26 | AV36: 10 | AW36: 1 | AX36: =+AO36-AV36 -> 0 | AY36: =+P36-AU36 -> 9 | AZ36: =+Q36-AV36 -> 5 | BA36: =+(AY36+AZ36)/(P36+Q36) -> 0.28 | BB36: =+(AU36+AV36)/E36 -> 0.23529412 | BC36: =+AU36/D36 -> 0.11403509 | BD36: =IF(AU36>0,"Graduado","En Proceso") -> Graduado
A37: BRENDA RODRIGUEZ | B37: GUAYAQUIL | C37: 18 | D37: 213 | E37: 201 | F37: 163 | G37: 63 | H37: =+G37/F37 -> 0.38650307 | I37: 54 | J37: 50 | K37: 41 | L37: =+K37/J37 -> 0.82 | M37: 9 | N37: 34 | O37: 3 | P37: =+O37+N37 -> 37 | Q37: 7 | R37: 35 | S37: 5 | T37: =+P37-R37 -> 2 | U37: =+Q37-S37 -> 2 | V37: 58 | W37: 12 | X37: =+W37+V37 -> 70 | Y37: 30 | Z37: 5 | AA37: =+R37-Y37 -> 5 | AB37: =+S37-Z37 -> 0 | AC37: 30 | AD37: 5 | AE37: =+Y37-AC37 -> 0 | AF37: =+Z37-AD37 -> 0 | AG37: 57 | AH37: 13 | AI37: =+AH37+AG37 -> 70 | AL37: =+AC37-AJ37 -> 30 | AM37: =+AD37-AK37 -> 5 | AP37: =+AJ37-AN37 -> 0 | AQ37: =+AK37-AO37 -> 0 | AT37: =+AS37+AR37 -> 0 | AW37: =+AN37-AU37 -> 0 | AX37: =+AO37-AV37 -> 0 | AY37: =+P37-AU37 -> 37 | AZ37: =+Q37-AV37 -> 7 | BA37: =+(AY37+AZ37)/(P37+Q37) -> 1 | BB37: =+(AU37+AV37)/E37 -> 0 | BC37: =+AU37/D37 -> 0 | BD37: =IF(AU37>0,"Graduado","En Proceso") -> En Proceso
A38: LINID VALENCIA | B38: LIMA | C38: 18 | D38: 251 | E38: 180 | F38: 133 | G38: 48 | H38: =+G38/F38 -> 0.36090226 | I38: 34 | J38: 30 | K38: 28 | L38: =+K38/J38 -> 0.93333333 | M38: 12 | N38: 28 | O38: 0 | P38: =+O38+N38 -> 28 | Q38: 7 | R38: 20 | S38: 7 | T38: =+P38-R38 -> 8 | U38: =+Q38-S38 -> 0 | V38: 20 | W38: 18 | X38: =+W38+V38 -> 38 | Y38: 20 | Z38: 6 | AA38: =+R38-Y38 -> 0 | AB38: =+S38-Z38 -> 1 | AC38: 18 | AD38: 6 | AE38: =+Y38-AC38 -> 2 | AF38: =+Z38-AD38 -> 0 | AG38: 25 | AH38: 12 | AI38: =+AH38+AG38 -> 37 | AJ38: 14 | AK38: 6 | AL38: =+AC38-AJ38 -> 4 | AM38: =+AD38-AK38 -> 0 | AN38: 12 | AO38: 6 | AP38: =+AJ38-AN38 -> 2 | AQ38: =+AK38-AO38 -> 0 | AR38: 36 | AS38: 20 | AT38: =+AS38+AR38 -> 56 | AU38: 12 | AV38: 6 | AW38: 1 | AX38: =+AO38-AV38 -> 0 | AY38: =+V38-AU38 -> 8 | AZ38: =+Q38-AV38 -> 1 | BA38: =+(AY38+AZ38)/(P38+Q38) -> 0.25714286 | BB38: =+(AU38+AV38)/E38 -> 0.1 | BC38: =+AU38/D38 -> 0.047808765 | BD38: =IF(AU38>0,"Graduado","En Proceso") -> Graduado
A39: BRENDA RODRIGUEZ | B39: GUAYAQUIL | C39: 19 | D39: 140 | E39: 124 | F39: 110 | G39: 30 | H39: =+G39/F39 -> 0.27272727 | I39: 31 | J39: 30 | K39: 30 | L39: =+K39/J39 -> 1 | M39: 10 | N39: 30 | O39: 4 | P39: =+O39+N39 -> 34 | Q39: 10 | R39: 28 | S39: 10 | T39: =+P39-R39 -> 6 | U39: =+Q39-S39 -> 0 | V39: 60 | W39: 43 | X39: =+W39+V39 -> 103 | AA39: =+R39-Y39 -> 28 | AB39: =+S39-Z39 -> 10 | AE39: =+Y39-AC39 -> 0 | AF39: =+Z39-AD39 -> 0 | AI39: =+AH39+AG39 -> 0 | AL39: =+AC39-AJ39 -> 0 | AM39: =+AD39-AK39 -> 0 | AP39: =+AJ39-AN39 -> 0 | AQ39: =+AK39-AO39 -> 0 | AT39: =+AS39+AR39 -> 0 | AW39: =+AN39-AU39 -> 0 | AX39: =+AO39-AV39 -> 0 | AY39: =+P39-AU39 -> 34 | AZ39: =+Q39-AV39 -> 10 | BA39: =+(AY39+AZ39)/(P39+Q39) -> 1 | BB39: =+(AU39+AV39)/E39 -> 0 | BC39: =+AU39/D39 -> 0 | BD39: =IF(AU39>0,"Graduado","En Proceso") -> En Proceso
A40: LINID VALENCIA | B40: LIMA | C40: 19 | D40: 217 | E40: 160 | F40: 133 | G40: 64 | H40: =+G40/F40 -> 0.48120301 | I40: 61 | J40: 60 | K40: 58 | L40: =+K40/J40 -> 0.96666667 | M40: 12 | N40: 53 | O40: 3 | P40: =+O40+N40 -> 56 | Q40: 9 | R40: 48 | S40: 9 | T40: =+P40-R40 -> 8 | U40: =+Q40-S40 -> 0 | V40: 61 | W40: 27 | X40: =+W40+V40 -> 88 | Y40: 43 | Z40: 6 | AA40: =+R40-Y40 -> 5 | AB40: =+S40-Z40 -> 3 | AC40: 36 | AD40: 5 | AE40: =+Y40-AC40 -> 7 | AF40: =+Z40-AD40 -> 1 | AG40: 44 | AH40: 23 | AI40: =+AH40+AG40 -> 67 | AJ40: 30 | AK40: 4 | AL40: =+AC40-AJ40 -> 6 | AM40: =+AD40-AK40 -> 1 | AN40: 27 | AO40: 3 | AP40: =+AJ40-AN40 -> 3 | AQ40: =+AK40-AO40 -> 1 | AR40: 50 | AS40: 18 | AT40: =+AS40+AR40 -> 68 | AW40: =+AN40-AU40 -> 27 | AX40: =+AO40-AV40 -> 3 | AY40: =+P40-AU40 -> 56 | AZ40: =+Q40-AV40 -> 9 | BA40: =+(AY40+AZ40)/(P40+Q40) -> 1 | BB40: =+(AU40+AV40)/E40 -> 0 | BC40: =+AU40/D40 -> 0 | BD40: =IF(AU40>0,"Graduado","En Proceso") -> En Proceso
...

Sheet Hoja2
C1: CREACION | E1: C A R | G1: RELACION | I1: R A G | K1: GRATITUD | M1: G A V
A2: SEDE | B2: E.# | C2: DESERTORES PX | D2: DESERTORES MG | E2: DESERTORES PX | F2: DESERTORES MG | G2: DESERTORES PX | H2: DESERTORES MG | I2: DESERTORES PX | J2: DESERTORES MG | K2: DESERTORES PX | L2: DESERTORES MG | M2: DESERTORES PX | N2: DESERTORES MG
A3: =+Hoja1!B12 -> CUENCA | B3: =+Hoja1!C12 -> 5 | C3: =+Hoja1!T12 -> 1 | D3: =+Hoja1!U12 -> 0 | E3: =+Hoja1!AA12 -> 4 | F3: =+Hoja1!AB12 -> 0 | G3: =+Hoja1!AE12 -> 2 | H3: =+Hoja1!AF12 -> 0 | I3: =+Hoja1!AL12 -> 2 | J3: =+Hoja1!AM12 -> 0 | K3: =+Hoja1!AP12 -> 0 | L3: =+Hoja1!AQ12 -> 0 | M3: =+Hoja1!AW12 -> 1 | N3: =+Hoja1!AX12 -> 0
A4: =+Hoja1!B13 -> MEDELLIN | B4: =+Hoja1!C13 -> 5 | C4: =+Hoja1!T13 -> 0 | D4: =+Hoja1!U13 -> 0 | E4: =+Hoja1!AA13 -> 0 | F4: =+Hoja1!AB13 -> 0 | G4: =+Hoja1!AE13 -> 0 | H4: =+Hoja1!AF13 -> 0 | I4: =+Hoja1!AL13 -> 0 | J4: =+Hoja1!AM13 -> 0 | K4: =+Hoja1!AP13 -> 0 | L4: =+Hoja1!AQ13 -> 0 | M4: =+Hoja1!AW13 -> 0 | N4: =+Hoja1!AX13 -> 0
A5: =+Hoja1!B14 -> CUENCA | B5: =+Hoja1!C14 -> 6 | C5: =+Hoja1!T14 -> 1 | D5: =+Hoja1!U14 -> 0 | E5: =+Hoja1!AA14 -> 1 | F5: =+Hoja1!AB14 -> 0 | G5: =+Hoja1!AE14 -> 0 | H5: =+Hoja1!AF14 -> 1 | I5: =+Hoja1!AL14 -> 2 | J5: =+Hoja1!AM14 -> 0 | K5: =+Hoja1!AP14 -> 1 | L5: =+Hoja1!AQ14 -> 0 | M5: =+Hoja1!AW14 -> 0 | N5: =+Hoja1!AX14 -> 0
A6: =+Hoja1!B15 -> LIMA | B6: =+Hoja1!C15 -> 6 | C6: =+Hoja1!T15 -> 2 | D6: =+Hoja1!U15 -> 0 | E6: =+Hoja1!AA15 -> 2 | F6: =+Hoja1!AB15 -> 0 | G6: =+Hoja1!AE15 -> 0 | H6: =+Hoja1!AF15 -> 0 | I6: =+Hoja1!AL15 -> 3 | J6: =+Hoja1!AM15 -> 1 | K6: =+Hoja1!AP15 -> 0 | L6: =+Hoja1!AQ15 -> 0 | M6: =+Hoja1!AW15 -> 0 | N6: =+Hoja1!AX15 -> 0
A7: =+Hoja1!B16 -> CUENCA | B7: =+Hoja1!C16 -> 7 | C7: =+Hoja1!T16 -> 0 | D7: =+Hoja1!U16 -> 0 | E7: =+Hoja1!AA16 -> 8 | F7: =+Hoja1!AB16 -> 0 | G7: =+Hoja1!AE16 -> 3 | H7: =+Hoja1!AF16 -> 0 | I7: =+Hoja1!AL16 -> 0 | J7: =+Hoja1!AM16 -> 0 | K7: =+Hoja1!AP16 -> 4 | L7: =+Hoja1!AQ16 -> 0 | M7: =+Hoja1!AW16 -> -4 | N7: =+Hoja1!AX16 -> 0
A8: =+Hoja1!B17 -> LIMA | B8: =+Hoja1!C17 -> 7 | C8: =+Hoja1!T17 -> 1 | D8: =+Hoja1!U17 -> 0 | E8: =+Hoja1!AA17 -> 2 | F8: =+Hoja1!AB17 -> 1 | G8: =+Hoja1!AE17 -> 0 | H8: =+Hoja1!AF17 -> 0 | I8: =+Hoja1!AL17 -> 5 | J8: =+Hoja1!AM17 -> -1 | K8: =+Hoja1!AP17 -> 0 | L8: =+Hoja1!AQ17 -> 0 | M8: =+Hoja1!AW17 -> 1 | N8: =+Hoja1!AX17 -> 0
A9: =+Hoja1!B18 -> CUENCA | B9: =+Hoja1!C18 -> 8 | C9: =+Hoja1!T18 -> 0 | D9: =+Hoja1!U18 -> 0 | E9: =+Hoja1!AA18 -> 6 | F9: =+Hoja1!AB18 -> 1 | G9: =+Hoja1!AE18 -> 1 | H9: =+Hoja1!AF18 -> 0 | I9: =+Hoja1!AL18 -> 3 | J9: =+Hoja1!AM18 -> 0 | K9: =+Hoja1!AP18 -> 27 | L9: =+Hoja1!AQ18 -> 2 | M9: =+Hoja1!AW18 -> -23 | N9: =+Hoja1!AX18 -> -2
A10: =+Hoja1!B19 -> LIMA | B10: =+Hoja1!C19 -> 8 | C10: =+Hoja1!T19 -> 3 | D10: =+Hoja1!U19 -> 0 | E10: =+Hoja1!AA19 -> 4 | F10: =+Hoja1!AB19 -> 0 | G10: =+Hoja1!AE19 -> 0 | H10: =+Hoja1!AF19 -> 1 | I10: =+Hoja1!AL19 -> 1 | J10: =+Hoja1!AM19 -> 2 | K10: =+Hoja1!AP19 -> 2 | L10: =+Hoja1!AQ19 -> 0 | M10: =+Hoja1!AW19 -> 0 | N10: =+Hoja1!AX19 -> 0
A11: =+Hoja1!B20 -> CUENCA | B11: =+Hoja1!C20 -> 9 | C11: =+Hoja1!T20 -> 9 | D11: =+Hoja1!U20 -> 0 | E11: =+Hoja1!AA20 -> 3 | F11: =+Hoja1!AB20 -> 0 | G11: =+Hoja1!AE20 -> 3 | H11: =+Hoja1!AF20 -> 0 | I11: =+Hoja1!AL20 -> 32 | J11: =+Hoja1!AM20 -> 2 | K11: =+Hoja1!AP20 -> 0 | L11: =+Hoja1!AQ20 -> 0 | M11: =+Hoja1!AW20 -> 0 | N11: =+Hoja1!AX20 -> 0
A12: =+Hoja1!B21 -> LIMA | B12: =+Hoja1!C21 -> 9 | C12: =+Hoja1!T21 -> 3 | D12: =+Hoja1!U21 -> 1 | E12: =+Hoja1!AA21 -> 6 | F12: =+Hoja1!AB21 -> 0 | G12: =+Hoja1!AE21 -> 0 | H12: =+Hoja1!AF21 -> 0 | I12: =+Hoja1!AL21 -> 0 | J12: =+Hoja1!AM21 -> 0 | K12: =+Hoja1!AP21 -> 1 | L12: =+Hoja1!AQ21 -> 0 | M12: =+Hoja1!AW21 -> 1 | N12: =+Hoja1!AX21 -> 0
